Workbook

Sheet Start Here
A1: MDS decision workbook — Beyond the Bottleneck (Group WGB3)
A2: Enabling smarter lunch flow by optimising queue management and capacity utilisation across Chefs Touch centres (Central CT and Munch Mess, 11:30–14:30).
A4: How to use
A5: 1. Change only BLUE cells, and almost all of them live on the Inputs tab. Black cells are formulas; GREEN cells pull values from another tab.
A6: 2. YELLOW cells are not measured yet (assumed or group estimate). Replace them with measurements (Data Collection tab).
A7: 3. Green-filled cells are the key results. The Checks tab must say ALL OK: | C7: =Checks!$C$27 -> ALL OK
A9: How the parts fit together
A10: Inputs → S15 Queuing (the analytic model) → LP Student Flow (the primary decision: students per mess per slot) → LP Food Allocation (food supports the flow)
A11: Inputs → the simulator (python -m messq.scenarios) → Scenarios, S7 Payoff Matrix, Reconciliation (why the two models differ)
A12: Decision Rule = how the screens turn estimates into advice: when Central, when Munch, when no advice
A14: Status tags
A15: Tag | B15: Meaning | C15: Example
A16: Measured | B16: From field work, CT or the group | C16: 2,960 students; seats 900 / 492; 2 stations + 1 scanner per mess
A17: Group estimate | B17: The group's figure, not yet timed | C17: Eating 14–18 min; disposal ≤ 2 min; food ready 70% of the time
A18: Assumed | B18: A placeholder until measured | C18: 10 students/min per station; MIT lab share; DLHS/MILHS size
A19: Calibrated | B19: Not measured: chosen so the model reproduces what was observed | C19: Lag from the start of a lunch break to the mess door
A20: Simulated | B20: Output of the simulator, 20 lunches per row | C20: Average wait 4.3 → 0.8 min on a busy day
A21: Policy | B21: Our design choice | C21: Minimum saving 2 min before suggesting a switch
A22: Tabs
A23: Tab | B23: Session(s) | C23: What it does
A24: Inputs | B24: — | C24: One assumptions table: value, unit, status, source, date, where it is used
A25: S2-3 Problem & Root Cause | B25: 2–3 | C25: Problem and decision; 5 Whys backtracked from the Phase 1 symptom; fishbone; issue tree
A26: S4 Biases & Ethics | B26: 4 | C26: Status quo, herding, loss aversion, missing information (hypotheses vs findings); DPDP ethics
A27: S5-6 Priority Matrix | B27: 5–6 | C27: ABC/XYZ menu matrix; tray weights; impact–effort matrix; decision dilemmas
A28: Arrival Curve | B28: 15 | C28: Department lunch breaks added up: when students arrive, and the 13:10–13:30 overlap
A29: S15 Queuing | B29: 15 | C29: M/M/1 check, utilisation curve, M/M/c + fluid queue by 10-min slot, four-stage throughput
A30: LP Student Flow | B30: 10–11 | C30: PRIMARY model: students to direct to each mess per slot; food as a constraint; shadow price
A31: LP Food Allocation | B31: 10–11 | C31: SECONDARY model: the star dish split that supports the flow; graphical method
A32: S7 Payoff Matrix | B32: 7 | C32: Five alternatives × three kinds of day, every cell simulated: maximax, maximin, Hurwicz, Laplace, EMV, regret, EVPI
A33: S18 Heuristics | B33: 18 | C33: Door-screen rule, reorder point, heuristic vs full model vs LP bound, metaheuristics
A34: Decision Rule | B34: — | C34: When the screen recommends Munch, Central, or gives no advice; worked situations
... A39: Checks | B39: — | C39: Validation: no errors, balances, constraints, calibration, response to inputs

Sheet Inputs
A1: Inputs: every assumption the workbook and the simulator use
A2: Change BLUE cells only. Yellow = not measured yet (assumed or group estimate): replace with measured data. The simulator reads the same values from config/default.toml.
A4: Parameter | B4: Value | C4: Unit | D4: Status | E4: Source / how to measure | F4: Date | G4: Used in
A5: MEASURED (Phase 1 field work, CT, the group)
A6: Students per lunch at Central CT + Munch (= plates served) | B6: 2960 | C6: students | D6: Measured | E6: Phase 1 deck: ~2,960 plates; one plate per student. Daily counts 2,810–3,465 | F6: Sep 2026 | G6: S15, LP Student Flow, all scenarios
A7: Lunch opens | B7: 11:30 | C7: time | D7: Measured | E7: Mess timings 11:30–14:30 | F7: Oct 2026 | G7: S15, LP Student Flow
A8: Lunch window length | B8: 180 | C8: minutes | D8: Measured | E8: 11:30–14:30 | F8: Oct 2026 | G8: S15
A9: Seats: Central CT | B9: 900 | C9: seats | D9: Measured | E9: Group measurement | F9: Oct 2026 | G9: S15, simulator
A10: Seats: Munch Mess | B10: 492 | C10: seats | D10: Measured | E10: Group measurement | F10: Oct 2026 | G10: S15, simulator
A11: Serving stations: Central CT | B11: 2 | C11: stations | D11: Measured | E11: Group observation | F11: Oct 2026 | G11: S15, LP, Decision Rule
A12: Serving stations: Munch Mess | B12: 2 | C12: stations | D12: Measured | E12: Group observation | F12: Oct 2026 | G12: S15, LP, Decision Rule
A13: Face scanners at the entrance: Central CT | B13: 1 | C13: scanners | D13: Measured | E13: Group observation | F13: Oct 2026 | G13: S15
A14: Face scanners at the entrance: Munch Mess | B14: 1 | C14: scanners | D14: Measured | E14: Group observation | F14: Oct 2026 | G14: S15
A15: Normal visit, scan to leaving (quiet times) | B15: 20 | C15: minutes | D15: Group estimate | E15: Group: about 20 min on a normal day | F15: Oct 2026 | G15: Checks (calibration)
A16: Throughput time range: low (quiet) | B16: 17 | C16: minutes | D16: Group estimate | E16: Group: door to leaving takes 17–35 min depending on the rush | F16: Oct 2026 | G16: Checks (calibration)
A17: Throughput time range: high (surge) | B17: 35 | C17: minutes | D17: Group estimate | E17: As above | F17: Oct 2026 | G17: Checks (calibration)
A18: Refill after the 'running low' call if the food must be made (make + send) | B18: 30 | C18: minutes | D18: Measured | E18: Group: the 30 min starts when the mess calls the kitchen | F18: Oct 2026 | G18: Decision Rule, S18, simulator
A19: Refill if the food is already made: sending only (low) | B19: 10 | C19: minutes | D19: Measured | E19: Group: 10–14 min | F19: Oct 2026 | G19: Decision Rule, simulator
... A21: Delay faced by students at the peak (observed) | B21: 15 | C21: minutes | D21: Measured | E21: Phase 1 deck: ~15 min | F21: Sep 2026 | G21: Checks (calibration)
A22: THE FOUR STAGES OF A VISIT (group estimates where given, else assumed)
A23: Stage 1: one face scan | B23: 2 | C23: seconds | D23: Assumed | E23: Stopwatch at the scanner, or gaps between scans in the logs | F23: — | G23: S15, simulator
A24: Stage 1: collect a plate after the scan (low) | B24: 28 | C24: seconds | D24: Group estimate | E24: Group: scan + plate takes 30–45 s | F24: — | G24: S15, simulator
A25: Stage 1: collect a plate after the scan (high) | B25: 43 | C25: seconds | D25: Group estimate | E25: As above | F25: — | G25: S15, simulator
A26: Stage 2: service rate per serving station | B26: 10 | C26: students/min | D26: Assumed | E26: ≈6 s per student. Must be about this fast for 2 stations to serve ~2,360 Central students, mostly within two hours. Stopwatch 20–30 students | F26: — | G26: S15, LP, Decision Rule, simulator
A27: Stage 2: rest of food collection after the station (low) | B27: 54 | C27: seconds | D27: Group estimate | E27: Group: collecting food takes 1–2 min without a queue, incl. ~6 s at the station | F27: — | G27: S15, simulator
A28: Stage 2: rest of food collection (high) | B28: 114 | C28: seconds | D28: Group estimate | E28: As above | F28: — | G28: S15, simulator
A29: Stage 3: eating at a table (low) | B29: 14 | C29: minutes | D29: Group estimate | E29: Group: 14–18 min | F29: Oct 2026 | G29: S15, simulator
A30: Stage 3: eating at a table (high) | B30: 18 | C30: minutes | D30: Group estimate | E30: As above | F30: Oct 2026 | G30: S15, simulator
A31: Stage 3: staying at the table after eating (the seat stays taken) | B31: 9 | C31: minutes | D31: Group estimate | E31: Chatting, waiting for friends: a seat is held ~25 min, which is why the hall looks full | F31: Oct 2026 | G31: S15, simulator
A32: Stage 4: dispose of leftovers and the plate (low) | B32: 1 | C32: minutes | D32: Group estimate | E32: Group: 2 min at most | F32: Oct 2026 | G32: S15, simulator
A33: Stage 4: dispose of leftovers and the plate (high) | B33: 2 | C33: minutes | D33: Group estimate | E33: As above | F33: Oct 2026 | G33: S15, simulator
A34: BEHAVIOUR AND DEMAND
A35: Share who go to Central CT by habit (no screens) | B35: 0.797 | C35: share | D35: Measured | E35: Group: ~2,360 eat at Central and ~600 at Munch of ~2,960. A day of biometric logs confirms it (Data Collection tab) | F35: Oct 2026 | G35: S15, LP, scenarios
A36: Share of students who follow the screen | B36: 0.6 | C36: share | D36: Assumed | E36: The pilot measures it; stress-tested at 30% and 100% | F36: — | G36: S15, LP, scenarios
A37: Walk between the two mess doors | B37: 0.5 | C37: minutes | D37: Assumed | E37: 30 s; walk it with a stopwatch | F37: — | G37: LP, Decision Rule, simulator
A38: Minutes from the start of a department's lunch break to the mess door: mean | B38: 20 | C38: minutes | D38: Calibrated | E38: Chosen so the no-screen simulation fits the 17–35 min visit and ~15 min peak delay. Logs + timetable measure it | F38: — | G38: Arrival Curve, simulator
A39: Same lag: spread (standard deviation); cut off at the end of the break | B39: 20 | C39: minutes | D39: Calibrated | E39: Stress-tested at 15 ± 10 min (everyone rushes at the bell) | F39: — | G39: Arrival Curve, simulator
A40: DEPARTMENT LUNCH BREAKS (sizes are rough counts, used as shares and scaled to the plates served)
A41: MIT: students (rough) | B41: 1100 | C41: students | D41: Group estimate | E41: Group: ~1,100 (rough) | F41: Oct 2026 | G41: Arrival Curve, simulator
A42: MIT: lunch break starts | B42: 0.5 | C42: time | D42: Measured | E42: Department timetable | F42: Oct 2026 | G42: Arrival Curve, simulator
...

Sheet S2-3 Problem & Root Cause
A1: Problem definition, decision context and root causes
A2: Sessions 2–3: Nature of business decisions · Problem identification, structuring, root cause analysis
A4: Problem statement (Phase 2: Beyond the Bottleneck)
A5: During the 11:30–14:30 lunch window, Chefs Touch serves about 2,960 students at Central CT and Munch Mess, which serve the same menu 30 seconds apart. Total serving capacity is enough on average but is used unevenly: one mess saturates while the other has spare capacity, so students wait (~15 min observed), and star-dish run-outs at the busy mess make it worse.
A6: Primary decision (LP Student Flow): how many students should be directed to each mess in each 10-minute slot, so that waiting falls without adding staff or space? Constraints: serving capacity, food availability, walking time, compliance, demand uncertainty. Secondary decision (LP Food Allocation): how should the star dish be allocated and replenished to support that flow?
A8: Session 2: nature of the decision
A9: Dimension | B9: Classification | C9: Why
A10: Level | B10: Operational | C10: Made every lunch, minute by minute, at the mess door and in the kitchen
A11: Structure | B11: Structured / programmable | C11: The same choice repeats daily; inputs can be measured (scans, stock, stations)
A12: Certainty | B12: Under risk / uncertainty | C12: Daily demand varies; probabilities come from the biometric logs
A13: Frequency | B13: Recurring (daily) | C13: Justifies a model and a decision rule instead of ad-hoc judgement
A14: Decision makers | B14: Mess manager (food status), students (which mess) | C14: Students' choice of mess is itself a decision we can inform
A16: Session 3: 5 Whys, backtracked. Phase 1 stopped at a symptom; Phase 2 follows the chain to the root cause
A17: Why? | B17: Phase 1 answer (symptom) | C17: Phase 2 answer (after backtracking) | D17: Evidence | E17: Status
A18: 1. Why do students wait ~15 min? | B18: Food runs out at peak | C18: Central's serving stations are overloaded at peak | D18: Line was at the stations; trays and seats free (field visit) | E18: Observed
A19: 2. Why are they overloaded? | B19: — | C19: ~30 arrive/min against 20/min capacity at the 13:10 overlap, while Munch gets ~8 | D19: S15 Queuing, Scenarios (simulated) | E19: Simulated; logs will confirm
A20: 3. Why so uneven? | B20: — | C20: About 80% go to Central by habit (~2,360 of ~2,960) | D20: Inputs: habit share | E20: Measured (group)
A21: 4. Why habit? | B21: — | C21: At the moment of choosing, nobody can see how busy either mess is | D21: S4 Biases | E21: Hypothesis (survey)
A22: 5. Why not? | B22: — | C22: Every entry is already scanned, but the data is never used live | D22: Biometric system exists (COSEC) | E22: Observed
A24: Food chain: star dishes run out mid-peak → refills start only at a 'running low' call → 30 min if not already made → no forecast from live arrivals. Both chains end at the same gap: live demand data exists but nobody acts on it.
A26: Session 3: fishbone (cause-and-effect) for 'long wait at lunch'
A27: People | B27: Process | C27: Policy | D27: Information | E27: Logistics / place
A28: Students arrive together at peak | B28: 2 serving stations and 1 face scanner per mess | C28: Replenishment is reactive | D28: No live view of demand | E28: Delivery shares the student walkway
A29: Habit: same mess every day | B29: Refilling at the counter stops the line | C29: Base foods under-buffered | D29: Published menu ≠ served menu | E29: Return station not measured
A30: Herding: a long line looks better | B30: Serving rate not measured | C30: No reorder point | D30: No per-mess forecast | E30: One kitchen supplies five centres
A32: Issue tree (problem structuring)
A33: Branch | B33: Sub-question | C33: Tool in this workbook
A34: Demand | B34: When and where do students arrive? Is Central really busier? | C34: Data Collection, S15 Queuing
A35: Capacity | B35: How many stations, how fast, how much spare at Munch? | C35: S15 Queuing, Scenarios (stress tests)
A36: Allocation of students | B36: How many to send to each mess, when? | C36: LP Student Flow (primary model), Decision Rule
A37: Allocation of food | B37: How much of the star dish to each mess, and when to refill? | C37: LP Food Allocation, Decision Rule (refill clock), S18
A38: Choice of intervention | B38: Which option is best on normal, busy and surge days? | C38: S7 Payoff Matrix, Scenarios
A39: Model trust | B39: Do the spreadsheet and the simulator agree? | C39: Reconciliation, Simulation Method, Checks

Sheet S4 Biases & Ethics
A1: Decision biases and ethical decision making
A2: Session 4: Decision-making frameworks, decision biases, ethical decision making
A4: Bias | B4: Where it shows up in the mess problem | C4: How the project counters it | D4: Status
A5: Status quo / habit | B5: Students go to the same mess daily even when the other is faster | C5: Door screens show the faster option at the moment of choice | D5: Hypothesis: survey + logs
A6: Herding | B6: A long line reads as a sign the food is better; if everyone follows one signal, the 'empty' mess becomes the busy one | C6: Equal-wait split + 2-minute minimum saving (Decision Rule) | D6: Shown in simulation (Scenarios: naive vs proposal)
A7: Loss aversion | B7: The 30-second walk feels like a cost; minutes in line don't | C7: Show the saving in minutes ('save ~8 min') | D7: Hypothesis: survey
A8: No information (bounded rationality) | B8: From the door you can't see the other mess's queue | C8: Live estimates on screens and phones | D8: Observed
A9: Anchoring (planning) | B9: Kitchen plans from the published menu; the served menu differed | C9: Record the actual menu; forecast from observed arrivals | D9: Observed (field visit)
A10: Confirmation (our team) | B10: We want the screens to look good | C10: Report observed / assumed / simulated separately; if the logs show Munch is not underused, revise the diagnosis | D10: Built into this workbook
A12: Ethics checklist
A13: Principle | B13: What we do | C13: Status
A14: Data minimisation (DPDP Act 2023) | B14: Request only scan time + mess + pseudonymous ID; no face data or templates | C14: Built into data request
A15: Pseudonymisation | B15: IDs hashed on reading; names hidden by default | C15: Built into prototype
A16: Purpose limitation & retention | B16: Use for this project only; delete at semester end | C16: Committed in email
A17: Honesty to students | B17: Suggest switching only if it saves ≥ 2 min; no advice when data is stale | C17: Built into prototype
A18: Consent / approval | B18: Written approval from college and vendor before any live connection | C18: Pending
A19: Fairness | B19: Advice is the same for everyone; no priority for any group | C19: Built into prototype

Sheet S5-6 Priority Matrix
A1: Decision dilemma and priority matrices
A2: Sessions 5–6: Decision dilemma and project priority matrix
A4: 1. Menu criticality × predictability (ABC/XYZ), MDS_dataset.xlsx 'Priority Matrix', menu week 31 Aug–6 Sep
A5: Policy | B5: Class | C5: Menu entries | D5: Share | E5: What to do
A6: Tight Control | B6: AZ | C6: 28 | D6: =C6/$C$10 -> 0.27184466 | E6: Measure and model: star dishes, chapattis, curd/raitha | F6: The dataset's field notes label curd AX while its menu ratings give AZ; we follow the ratings.
A7: Calculated Issue | B7: AX | C7: 9 | D7: =C7/$C$10 -> 0.087378641 | E7: Derive from plate count: one-per-plate sweets
A8: Buffered Issue | B8: CZ | C8: 40 | D8: =C8/$C$10 -> 0.38834951 | E8: Issue with a safety margin: rice, dal, sambar, rasam, dry veg
A9: Free Issue | B9: CX | C9: 26 | D9: =C9/$C$10 -> 0.25242718 | E9: Issue without control: pickle, salt, sugar, fryums
A10: Total | C10: =SUM(C6:C9) -> 103 | D10: =SUM(D6:D9) -> 1
A12: 2. Tray weights used by the live system (config/default.toml [[tray]]): how much a tray running low or out changes the advice
A13: Tray | B13: Item type (matrix) | C13: Class | D13: Weight | E13: When OUT | F13: Why this weight
A14: Gravy sabji, Special rice | B14: Star dish | C14: AZ | D14: ★ 1.0 | E14: Outage: that mess serves nobody until the refill | F14: 'The one item everyone notices when it is gone'
A15: Roti | B15: Made fresh in batches | C15: AZ | D15: 0.5 | E15: Adds 0.5 × expected refill time | F15: Running out is a speed problem; another tawa fixes it
A16: Dessert | B16: One per plate | C16: AX | D16: 0.3 | E16: Adds 0.3 × expected refill time | F16: Demand = plate count; errors are headcount errors
A17: Curd / raita | B17: Fresh side | C17: AZ | D17: 0.3 | E17: Adds 0.3 × expected refill time | F17: Risk is surplus more than shortage
A18: Dry sabji, Dal, Rice, Sambar / rasam | B18: Base food | C18: CZ | D18: 0.1 | E18: Adds 0.1 × expected refill time | F18: Interchangeable: 'quietly absorbed by another'
A19: Salt, pickle, fryums | B19: Table item | C19: CX | D19: 0 | E19: Not tracked | F19: Free issue
A20: Running low: a tray costs a student time only if they reach the counter after it empties and before its refill (Decision Rule). Weights are the group's reading of the matrix; confirm them with the CT manager.
A22: 3. Intervention priority matrix (impact vs effort). Impact from the Scenarios tab; effort scores are the group's judgement.
A23: Quadrant threshold (score above this = high) | C23: 3
A25: Intervention | B25: Impact (1–5) | C25: Effort (1–5) | D25: Quadrant | E25: Reason (impact) | F25: Reason (effort)
A26: A2 Door screens, queue information only | B26: 4 | C26: 3 | D26: =IF(B26>$C$23,IF(C26>$C$23,"Major project","Quick win"),IF(C26>$C$23,"Thankless task","Fill-in")) -> Quick win | E26: Busy day: wait 4.3 → 1.2 min (simulated) | F26: Two screens + a laptop; needs data access
A27: A3 Screens + food status (proposal) | B27: 5 | C27: 3 | D27: =IF(B27>$C$23,IF(C27>$C$23,"Major project","Quick win"),IF(C27>$C$23,"Thankless task","Fill-in")) -> Quick win | E27: Busy day: wait 4.3 → 0.8 min (simulated) | F27: Same as A2 + manager taps food status
A28: A4 3rd serving station at Central | B28: 4 | C28: 4 | D28: =IF(B28>$C$23,IF(C28>$C$23,"Major project","Quick win"),IF(C28>$C$23,"Thankless task","Fill-in")) -> Major project | E28: Busy day: 4.3 → 0.6 min; best on normal days | F28: Staff cost every day; space at counter
A29: A6 Larger buffers for base foods (CZ) | B29: 2 | C29: 1 | D29: =IF(B29>$C$23,IF(C29>$C$23,"Major project","Quick win"),IF(C29>$C$23,"Thankless task","Fill-in")) -> Fill-in | E29: Base foods ran dry in the field visit | F29: Just send more rice/dal/sambar
A30: A7 Stagger class end times | B30: 4 | C30: 5 | D30: =IF(B30>$C$23,IF(C30>$C$23,"Major project","Quick win"),IF(C30>$C$23,"Thankless task","Fill-in")) -> Major project | E30: SMI 15 min earlier: today's wait 4.3 → 3.3 min; TAPMI 15 min later: → 1.7 (simulated) | F30: Needs academic administration
A32: 4. Decision dilemmas
A33: Dilemma | B33: Option 1 | C33: Option 2 | E33: Trade-off | F33: How we resolve it
A34: Send students to the other mess? | B34: Strong advice (risk herding) | C34: No advice (uneven load) | E34: Balance vs trust | F34: Equal-wait split + 2-min threshold (Decision Rule, S18)
A35: React to 'running low'? | B35: Redirect early (needless walks) | C35: Wait for 'out' (late) | E35: Walks vs waits | F35: Delay only for students who would reach an empty tray (Decision Rule)
A36: Add a serving station? | B36: Yes (staff every day) | C36: No (long peak waits) | E36: Staff cost vs waiting | F36: S7 Payoff Matrix (A4, A5) and Scenarios

Sheet Arrival Curve
A1: When students arrive: department lunch breaks added up
A2: Feeds S15 Queuing and the LP. The simulator uses the same curve (config/default.toml)
A3: Scale: plates served ÷ sum of the rough department sizes | E3: =Inputs!$B$6/(Inputs!$B$41+Inputs!$B$47+Inputs!$B$50+Inputs!$B$53+Inputs!$B$56+Inputs!$B$59+Inputs!$B$62) -> 0.93968254
A5: Cohort | B5: Students (scaled) | C5: Break starts (min after opening) | D5: Break ends (min) | E5: Mean arrival (min) | F5: Share of the curve inside the break
A6: MIT | B6: =Inputs!$B$41*(1-Inputs!$B$44)*$E$3 -> 568.50794 | C6: =ROUND((Inputs!$B$42-TIMEVALUE(Inputs!$B$7))*1440,0) -> 30 | D6: =ROUND((Inputs!$B$43-TIMEVALUE(Inputs!$B$7))*1440,0) -> 90 | E6: =C6+Inputs!$B$38 -> 50 | F6: =NORMDIST(D6,E6,Inputs!$B$39,TRUE())-NORMDIST(C6,E6,Inputs!$B$39,TRUE()) -> 0.81859461
A7: MIT (lab day) | B7: =Inputs!$B$41*Inputs!$B$44*$E$3 -> 465.14286 | C7: =ROUND((Inputs!$B$45-TIMEVALUE(Inputs!$B$7))*1440,0) -> 90 | D7: =ROUND((Inputs!$B$46-TIMEVALUE(Inputs!$B$7))*1440,0) -> 150 | E7: =C7+Inputs!$B$38 -> 110 | F7: =NORMDIST(D7,E7,Inputs!$B$39,TRUE())-NORMDIST(C7,E7,Inputs!$B$39,TRUE()) -> 0.81859461
A8: TAPMI | B8: =Inputs!$B$47*$E$3 -> 798.73016 | C8: =ROUND((Inputs!$B$48-TIMEVALUE(Inputs!$B$7))*1440,0) -> 95 | D8: =ROUND((Inputs!$B$49-TIMEVALUE(Inputs!$B$7))*1440,0) -> 150 | E8: =C8+Inputs!$B$38 -> 115 | F8: =NORMDIST(D8,E8,Inputs!$B$39,TRUE())-NORMDIST(C8,E8,Inputs!$B$39,TRUE()) -> 0.80128559
A9: DOC/MICFE | B9: =Inputs!$B$50*$E$3 -> 516.8254 | C9: =ROUND((Inputs!$B$51-TIMEVALUE(Inputs!$B$7))*1440,0) -> 60 | D9: =ROUND((Inputs!$B$52-TIMEVALUE(Inputs!$B$7))*1440,0) -> 120 | E9: =C9+Inputs!$B$38 -> 80 | F9: =NORMDIST(D9,E9,Inputs!$B$39,TRUE())-NORMDIST(C9,E9,Inputs!$B$39,TRUE()) -> 0.81859461
A10: SMI | B10: =Inputs!$B$53*$E$3 -> 422.85714 | C10: =ROUND((Inputs!$B$54-TIMEVALUE(Inputs!$B$7))*1440,0) -> 30 | D10: =ROUND((Inputs!$B$55-TIMEVALUE(Inputs!$B$7))*1440,0) -> 90 | E10: =C10+Inputs!$B$38 -> 50 | F10: =NORMDIST(D10,E10,Inputs!$B$39,TRUE())-NORMDIST(C10,E10,Inputs!$B$39,TRUE()) -> 0.81859461
A11: DLHS/MILHS | B11: =Inputs!$B$56*$E$3 -> 93.968254 | C11: =ROUND((Inputs!$B$57-TIMEVALUE(Inputs!$B$7))*1440,0) -> 70 | D11: =ROUND((Inputs!$B$58-TIMEVALUE(Inputs!$B$7))*1440,0) -> 130 | E11: =C11+Inputs!$B$38 -> 90 | F11: =NORMDIST(D11,E11,Inputs!$B$39,TRUE())-NORMDIST(C11,E11,Inputs!$B$39,TRUE()) -> 0.81859461
A12: MLS | B12: =Inputs!$B$59*$E$3 -> 46.984127 | C12: =ROUND((Inputs!$B$60-TIMEVALUE(Inputs!$B$7))*1440,0) -> 80 | D12: =ROUND((Inputs!$B$61-TIMEVALUE(Inputs!$B$7))*1440,0) -> 140 | E12: =C12+Inputs!$B$38 -> 100 | F12: =NORMDIST(D12,E12,Inputs!$B$39,TRUE())-NORMDIST(C12,E12,Inputs!$B$39,TRUE()) -> 0.81859461
A13: MIRM | B13: =Inputs!$B$62*$E$3 -> 46.984127 | C13: =ROUND((Inputs!$B$63-TIMEVALUE(Inputs!$B$7))*1440,0) -> 60 | D13: =ROUND((Inputs!$B$64-TIMEVALUE(Inputs!$B$7))*1440,0) -> 120 | E13: =C13+Inputs!$B$38 -> 80 | F13: =NORMDIST(D13,E13,Inputs!$B$39,TRUE())-NORMDIST(C13,E13,Inputs!$B$39,TRUE()) -> 0.81859461
A14: Total | B14: =SUM(B6:B13) -> 2960
A15: Each department starts arriving when its lunch break starts. A student's lag after the break starts is Normal(mean, spread) from the Inputs tab, cut off at the end of the break, so each cohort's arrivals add up to its size. MIT eats 13:00–14:00 on lab days. The sizes are rough and add up to more than the plates served, so they are used as shares. The biometric logs replace this whole tab once available.
A17: Arrivals per 10-minute slot
A18: Slot | B18: Minute | C18: MIT | D18: MIT (lab day) | E18: TAPMI | F18: DOC/MICFE | G18: SMI | H18: DLHS/MILHS | I18: MLS | J18: MIRM | K18: Total | L18: Share
A19: 11:30 | B19: 0 | C19: =$B$6*(NORMDIST(MIN($D$6,MAX($C$6,$B19+10)),$E$6,Inputs!$B$39,TRUE())-NORMDIST(MIN($D$6,MAX($C$6,$B19)),$E$6,Inputs!$B$39,TRUE()))/$F$6 -> 0 | D19: =$B$7*(NORMDIST(MIN($D$7,MAX($C$7,$B19+10)),$E$7,Inputs!$B$39,TRUE())-NORMDIST(MIN($D$7,MAX($C$7,$B19)),$E$7,Inputs!$B$39,TRUE()))/$F$7 -> 0 | E19: =$B$8*(NORMDIST(MIN($D$8,MAX($C$8,$B19+10)),$E$8,Inputs!$B$39,TRUE())-NORMDIST(MIN($D$8,MAX($C$8,$B19)),$E$8,Inputs!$B$39,TRUE()))/$F$8 -> 0 | F19: =$B$9*(NORMDIST(MIN($D$9,MAX($C$9,$B19+10)),$E$9,Inputs!$B$39,TRUE())-NORMDIST(MIN($D$9,MAX($C$9,$B19)),$E$9,Inputs!$B$39,TRUE()))/$F$9 -> 0 | G19: =$B$10*(NORMDIST(MIN($D$10,MAX($C$10,$B19+10)),$E$10,Inputs!$B$39,TRUE())-NORMDIST(MIN($D$10,MAX($C$10,$B19)),$E$10,Inputs!$B$39,TRUE()))/$F$10 -> 0 | H19: =$B$11*(NORMDIST(MIN($D$11,MAX($C$11,$B19+10)),$E$11,Inputs!$B$39,TRUE())-NORMDIST(MIN($D$11,MAX($C$11,$B19)),$E$11,Inputs!$B$39,TRUE()))/$F$11 -> 0 | I19: =$B$12*(NORMDIST(MIN($D$12,MAX($C$12,$B19+10)),$E$12,Inputs!$B$39,TRUE())-NORMDIST(MIN($D$12,MAX($C$12,$B19)),$E$12,Inputs!$B$39,TRUE()))/$F$12 -> 0 | J19: =$B$13*(NORMDIST(MIN($D$13,MAX($C$13,$B19+10)),$E$13,Inputs!$B$39,TRUE())-NORMDIST(MIN($D$13,MAX($C$13,$B19)),$E$13,Inputs!$B$39,TRUE()))/$F$13 -> 0 | K19: =SUM(C19:J19) -> 0 | L19: =K19/SUM($K$19:$K$36) -> 0
A20: 11:40 | B20: 10 | C20: =$B$6*(NORMDIST(MIN($D$6,MAX($C$6,$B20+10)),$E$6,Inputs!$B$39,TRUE())-NORMDIST(MIN($D$6,MAX($C$6,$B20)),$E$6,Inputs!$B$39,TRUE()))/$F$6 -> 0 | D20: =$B$7*(NORMDIST(MIN($D$7,MAX($C$7,$B20+10)),$E$7,Inputs!$B$39,TRUE())-NORMDIST(MIN($D$7,MAX($C$7,$B20)),$E$7,Inputs!$B$39,TRUE()))/$F$7 -> 0 | E20: =$B$8*(NORMDIST(MIN($D$8,MAX($C$8,$B20+10)),$E$8,Inputs!$B$39,TRUE())-NORMDIST(MIN($D$8,MAX($C$8,$B20)),$E$8,Inputs!$B$39,TRUE()))/$F$8 -> 0 | F20: =$B$9*(NORMDIST(MIN($D$9,MAX($C$9,$B20+10)),$E$9,Inputs!$B$39,TRUE())-NORMDIST(MIN($D$9,MAX($C$9,$B20)),$E$9,Inputs!$B$39,TRUE()))/$F$9 -> 0 | G20: =$B$10*(NORMDIST(MIN($D$10,MAX($C$10,$B20+10)),$E$10,Inputs!$B$39,TRUE())-NORMDIST(MIN($D$10,MAX($C$10,$B20)),$E$10,Inputs!$B$39,TRUE()))/$F$10 -> 0 | H20: =$B$11*(NORMDIST(MIN($D$11,MAX($C$11,$B20+10)),$E$11,Inputs!$B$39,TRUE())-NORMDIST(MIN($D$11,MAX($C$11,$B20)),$E$11,Inputs!$B$39,TRUE()))/$F$11 -> 0 | I20: =$B$12*(NORMDIST(MIN($D$12,MAX($C$12,$B20+10)),$E$12,Inputs!$B$39,TRUE())-NORMDIST(MIN($D$12,MAX($C$12,$B20)),$E$12,Inputs!$B$39,TRUE()))/$F$12 -> 0 | J20: =$B$13*(NORMDIST(MIN($D$13,MAX($C$13,$B20+10)),$E$13,Inputs!$B$39,TRUE())-NORMDIST(MIN($D$13,MAX($C$13,$B20)),$E$13,Inputs!$B$39,TRUE()))/$F$13 -> 0 | K20: =SUM(C20:J20) -> 0 | L20: =K20/SUM($K$19:$K$36) -> 0
A21: 11:50 | B21: 20 | C21: =$B$6*(NORMDIST(MIN($D$6,MAX($C$6,$B21+10)),$E$6,Inputs!$B$39,TRUE())-NORMDIST(MIN($D$6,MAX($C$6,$B21)),$E$6,Inputs!$B$39,TRUE()))/$F$6 -> 0 | D21: =$B$7*(NORMDIST(MIN($D$7,MAX($C$7,$B21+10)),$E$7,Inputs!$B$39,TRUE())-NORMDIST(MIN($D$7,MAX($C$7,$B21)),$E$7,Inputs!$B$39,TRUE()))/$F$7 -> 0 | E21: =$B$8*(NORMDIST(MIN($D$8,MAX($C$8,$B21+10)),$E$8,Inputs!$B$39,TRUE())-NORMDIST(MIN($D$8,MAX($C$8,$B21)),$E$8,Inputs!$B$39,TRUE()))/$F$8 -> 0 | F21: =$B$9*(NORMDIST(MIN($D$9,MAX($C$9,$B21+10)),$E$9,Inputs!$B$39,TRUE())-NORMDIST(MIN($D$9,MAX($C$9,$B21)),$E$9,Inputs!$B$39,TRUE()))/$F$9 -> 0 | G21: =$B$10*(NORMDIST(MIN($D$10,MAX($C$10,$B21+10)),$E$10,Inputs!$B$39,TRUE())-NORMDIST(MIN($D$10,MAX($C$10,$B21)),$E$10,Inputs!$B$39,TRUE()))/$F$10 -> 0 | H21: =$B$11*(NORMDIST(MIN($D$11,MAX($C$11,$B21+10)),$E$11,Inputs!$B$39,TRUE())-NORMDIST(MIN($D$11,MAX($C$11,$B21)),$E$11,Inputs!$B$39,TRUE()))/$F$11 -> 0 | I21: =$B$12*(NORMDIST(MIN($D$12,MAX($C$12,$B21+10)),$E$12,Inputs!$B$39,TRUE())-NORMDIST(MIN($D$12,MAX($C$12,$B21)),$E$12,Inputs!$B$39,TRUE()))/$F$12 -> 0 | J21: =$B$13*(NORMDIST(MIN($D$13,MAX($C$13,$B21+10)),$E$13,Inputs!$B$39,TRUE())-NORMDIST(MIN($D$13,MAX($C$13,$B21)),$E$13,Inputs!$B$39,TRUE()))/$F$13 -> 0 | K21: =SUM(C21:J21) -> 0 | L21: =K21/SUM($K$19:$K$36) -> 0
A22: 12:00 | B22: 30 | C22: =$B$6*(NORMDIST(MIN($D$6,MAX($C$6,$B22+10)),$E$6,Inputs!$B$39,TRUE())-NORMDIST(MIN($D$6,MAX($C$6,$B22)),$E$6,Inputs!$B$39,TRUE()))/$F$6 -> 104.09214 | D22: =$B$7*(NORMDIST(MIN($D$7,MAX($C$7,$B22+10)),$E$7,Inputs!$B$39,TRUE())-NORMDIST(MIN($D$7,MAX($C$7,$B22)),$E$7,Inputs!$B$39,TRUE()))/$F$7 -> 0 | E22: =$B$8*(NORMDIST(MIN($D$8,MAX($C$8,$B22+10)),$E$8,Inputs!$B$39,TRUE())-NORMDIST(MIN($D$8,MAX($C$8,$B22)),$E$8,Inputs!$B$39,TRUE()))/$F$8 -> 0 | F22: =$B$9*(NORMDIST(MIN($D$9,MAX($C$9,$B22+10)),$E$9,Inputs!$B$39,TRUE())-NORMDIST(MIN($D$9,MAX($C$9,$B22)),$E$9,Inputs!$B$39,TRUE()))/$F$9 -> 0 | G22: =$B$10*(NORMDIST(MIN($D$10,MAX($C$10,$B22+10)),$E$10,Inputs!$B$39,TRUE())-NORMDIST(MIN($D$10,MAX($C$10,$B22)),$E$10,Inputs!$B$39,TRUE()))/$F$10 -> 77.423909 | H22: =$B$11*(NORMDIST(MIN($D$11,MAX($C$11,$B22+10)),$E$11,Inputs!$B$39,TRUE())-NORMDIST(MIN($D$11,MAX($C$11,$B22)),$E$11,Inputs!$B$39,TRUE()))/$F$11 -> 0 | I22: =$B$12*(NORMDIST(MIN($D$12,MAX($C$12,$B22+10)),$E$12,Inputs!$B$39,TRUE())-NORMDIST(MIN($D$12,MAX($C$12,$B22)),$E$12,Inputs!$B$39,TRUE()))/$F$12 -> 0 | J22: =$B$13*(NORMDIST(MIN($D$13,MAX($C$13,$B22+10)),$E$13,Inputs!$B$39,TRUE())-NORMDIST(MIN($D$13,MAX($C$13,$B22)),$E$13,Inputs!$B$39,TRUE()))/$F$13 -> 0 | K22: =SUM(C22:J22) -> 181.51605 | L22: =K22/SUM($K$19:$K$36) -> 0.061322991
A23: 12:10 | B23: 40 | C23: =$B$6*(NORMDIST(MIN($D$6,MAX($C$6,$B23+10)),$E$6,Inputs!$B$39,TRUE())-NORMDIST(MIN($D$6,MAX($C$6,$B23)),$E$6,Inputs!$B$39,TRUE()))/$F$6 -> 132.96927 | D23: =$B$7*(NORMDIST(MIN($D$7,MAX($C$7,$B23+10)),$E$7,Inputs!$B$39,TRUE())-NORMDIST(MIN($D$7,MAX($C$7,$B23)),$E$7,Inputs!$B$39,TRUE()))/$F$7 -> 0 | E23: =$B$8*(NORMDIST(MIN($D$8,MAX($C$8,$B23+10)),$E$8,Inputs!$B$39,TRUE())-NORMDIST(MIN($D$8,MAX($C$8,$B23)),$E$8,Inputs!$B$39,TRUE()))/$F$8 -> 0 | F23: =$B$9*(NORMDIST(MIN($D$9,MAX($C$9,$B23+10)),$E$9,Inputs!$B$39,TRUE())-NORMDIST(MIN($D$9,MAX($C$9,$B23)),$E$9,Inputs!$B$39,TRUE()))/$F$9 -> 0 | G23: =$B$10*(NORMDIST(MIN($D$10,MAX($C$10,$B23+10)),$E$10,Inputs!$B$39,TRUE())-NORMDIST(MIN($D$10,MAX($C$10,$B23)),$E$10,Inputs!$B$39,TRUE()))/$F$10 -> 98.902763 | H23: =$B$11*(NORMDIST(MIN($D$11,MAX($C$11,$B23+10)),$E$11,Inputs!$B$39,TRUE())-NORMDIST(MIN($D$11,MAX($C$11,$B23)),$E$11,Inputs!$B$39,TRUE()))/$F$11 -> 0 | I23: =$B$12*(NORMDIST(MIN($D$12,MAX($C$12,$B23+10)),$E$12,Inputs!$B$39,TRUE())-NORMDIST(MIN($D$12,MAX($C$12,$B23)),$E$12,Inputs!$B$39,TRUE()))/$F$12 -> 0 | J23: =$B$13*(NORMDIST(MIN($D$13,MAX($C$13,$B23+10)),$E$13,Inputs!$B$39,TRUE())-NORMDIST(MIN($D$13,MAX($C$13,$B23)),$E$13,Inputs!$B$39,TRUE()))/$F$13 -> 0 | K23: =SUM(C23:J23) -> 231.87203 | L23: =K23/SUM($K$19:$K$36) -> 0.078335147
A24: 12:20 | B24: 50 | C24: =$B$6*(NORMDIST(MIN($D$6,MAX($C$6,$B24+10)),$E$6,Inputs!$B$39,TRUE())-NORMDIST(MIN($D$6,MAX($C$6,$B24)),$E$6,Inputs!$B$39,TRUE()))/$F$6 -> 132.96927 | D24: =$B$7*(NORMDIST(MIN($D$7,MAX($C$7,$B24+10)),$E$7,Inputs!$B$39,TRUE())-NORMDIST(MIN($D$7,MAX($C$7,$B24)),$E$7,Inputs!$B$39,TRUE()))/$F$7 -> 0 | E24: =$B$8*(NORMDIST(MIN($D$8,MAX($C$8,$B24+10)),$E$8,Inputs!$B$39,TRUE())-NORMDIST(MIN($D$8,MAX($C$8,$B24)),$E$8,Inputs!$B$39,TRUE()))/$F$8 -> 0 | F24: =$B$9*(NORMDIST(MIN($D$9,MAX($C$9,$B24+10)),$E$9,Inputs!$B$39,TRUE())-NORMDIST(MIN($D$9,MAX($C$9,$B24)),$E$9,Inputs!$B$39,TRUE()))/$F$9 -> 0 | G24: =$B$10*(NORMDIST(MIN($D$10,MAX($C$10,$B24+10)),$E$10,Inputs!$B$39,TRUE())-NORMDIST(MIN($D$10,MAX($C$10,$B24)),$E$10,Inputs!$B$39,TRUE()))/$F$10 -> 98.902763 | H24: =$B$11*(NORMDIST(MIN($D$11,MAX($C$11,$B24+10)),$E$11,Inputs!$B$39,TRUE())-NORMDIST(MIN($D$11,MAX($C$11,$B24)),$E$11,Inputs!$B$39,TRUE()))/$F$11 -> 0 | I24: =$B$12*(NORMDIST(MIN($D$12,MAX($C$12,$B24+10)),$E$12,Inputs!$B$39,TRUE())-NORMDIST(MIN($D$12,MAX($C$12,$B24)),$E$12,Inputs!$B$39,TRUE()))/$F$12 -> 0 | J24: =$B$13*(NORMDIST(MIN($D$13,MAX($C$13,$B24+10)),$E$13,Inputs!$B$39,TRUE())-NORMDIST(MIN($D$13,MAX($C$13,$B24)),$E$13,Inputs!$B$39,TRUE()))/$F$13 -> 0 | K24: =SUM(C24:J24) -> 231.87203 | L24: =K24/SUM($K$19:$K$36) -> 0.078335147
A25: 12:30 | B25: 60 | C25: =$B$6*(NORMDIST(MIN($D$6,MAX($C$6,$B25+10)),$E$6,Inputs!$B$39,TRUE())-NORMDIST(MIN($D$6,MAX($C$6,$B25)),$E$6,Inputs!$B$39,TRUE()))/$F$6 -> 104.09214 | D25: =$B$7*(NORMDIST(MIN($D$7,MAX($C$7,$B25+10)),$E$7,Inputs!$B$39,TRUE())-NORMDIST(MIN($D$7,MAX($C$7,$B25)),$E$7,Inputs!$B$39,TRUE()))/$F$7 -> 0 | E25: =$B$8*(NORMDIST(MIN($D$8,MAX($C$8,$B25+10)),$E$8,Inputs!$B$39,TRUE())-NORMDIST(MIN($D$8,MAX($C$8,$B25)),$E$8,Inputs!$B$39,TRUE()))/$F$8 -> 0 | F25: =$B$9*(NORMDIST(MIN($D$9,MAX($C$9,$B25+10)),$E$9,Inputs!$B$39,TRUE())-NORMDIST(MIN($D$9,MAX($C$9,$B25)),$E$9,Inputs!$B$39,TRUE()))/$F$9 -> 94.629222 | G25: =$B$10*(NORMDIST(MIN($D$10,MAX($C$10,$B25+10)),$E$10,Inputs!$B$39,TRUE())-NORMDIST(MIN($D$10,MAX($C$10,$B25)),$E$10,Inputs!$B$39,TRUE()))/$F$10 -> 77.423909 | H25: =$B$11*(NORMDIST(MIN($D$11,MAX($C$11,$B25+10)),$E$11,Inputs!$B$39,TRUE())-NORMDIST(MIN($D$11,MAX($C$11,$B25)),$E$11,Inputs!$B$39,TRUE()))/$F$11 -> 0 | I25: =$B$12*(NORMDIST(MIN($D$12,MAX($C$12,$B25+10)),$E$12,Inputs!$B$39,TRUE())-NORMDIST(MIN($D$12,MAX($C$12,$B25)),$E$12,Inputs!$B$39,TRUE()))/$F$12 -> 0 | J25: =$B$13*(NORMDIST(MIN($D$13,MAX($C$13,$B25+10)),$E$13,Inputs!$B$39,TRUE())-NORMDIST(MIN($D$13,MAX($C$13,$B25)),$E$13,Inputs!$B$39,TRUE()))/$F$13 -> 8.6026565 | K25: =SUM(C25:J25) -> 284.74793 | L25: =K25/SUM($K$19:$K$36) -> 0.096198625
A26: 12:40 | B26: 70 | C26: =$B$6*(NORMDIST(MIN($D$6,MAX($C$6,$B26+10)),$E$6,Inputs!$B$39,TRUE())-NORMDIST(MIN($D$6,MAX($C$6,$B26)),$E$6,Inputs!$B$39,TRUE()))/$F$6 -> 63.787797 | D26: =$B$7*(NORMDIST(MIN($D$7,MAX($C$7,$B26+10)),$E$7,Inputs!$B$39,TRUE())-NORMDIST(MIN($D$7,MAX($C$7,$B26)),$E$7,Inputs!$B$39,TRUE()))/$F$7 -> 0 | E26: =$B$8*(NORMDIST(MIN($D$8,MAX($C$8,$B26+10)),$E$8,Inputs!$B$39,TRUE())-NORMDIST(MIN($D$8,MAX($C$8,$B26)),$E$8,Inputs!$B$39,TRUE()))/$F$8 -> 0 | F26: =$B$9*(NORMDIST(MIN($D$9,MAX($C$9,$B26+10)),$E$9,Inputs!$B$39,TRUE())-NORMDIST(MIN($D$9,MAX($C$9,$B26)),$E$9,Inputs!$B$39,TRUE()))/$F$9 -> 120.88116 | G26: =$B$10*(NORMDIST(MIN($D$10,MAX($C$10,$B26+10)),$E$10,Inputs!$B$39,TRUE())-NORMDIST(MIN($D$10,MAX($C$10,$B26)),$E$10,Inputs!$B$39,TRUE()))/$F$10 -> 47.445469 | H26: =$B$11*(NORMDIST(MIN($D$11,MAX($C$11,$B26+10)),$E$11,Inputs!$B$39,TRUE())-NORMDIST(MIN($D$11,MAX($C$11,$B26)),$E$11,Inputs!$B$39,TRUE()))/$F$11 -> 17.205313 | I26: =$B$12*(NORMDIST(MIN($D$12,MAX($C$12,$B26+10)),$E$12,Inputs!$B$39,TRUE())-NORMDIST(MIN($D$12,MAX($C$12,$B26)),$E$12,Inputs!$B$39,TRUE()))/$F$12 -> 0 | J26: =$B$13*(NORMDIST(MIN($D$13,MAX($C$13,$B26+10)),$E$13,Inputs!$B$39,TRUE())-NORMDIST(MIN($D$13,MAX($C$13,$B26)),$E$13,Inputs!$B$39,TRUE()))/$F$13 -> 10.989196 | K26: =SUM(C26:J26) -> 260.30893 | L26: =K26/SUM($K$19:$K$36) -> 0.087942206
A27: 12:50 | B27: 80 | C27: =$B$6*(NORMDIST(MIN($D$6,MAX($C$6,$B27+10)),$E$6,Inputs!$B$39,TRUE())-NORMDIST(MIN($D$6,MAX($C$6,$B27)),$E$6,Inputs!$B$39,TRUE()))/$F$6 -> 30.59731 | D27: =$B$7*(NORMDIST(MIN($D$7,MAX($C$7,$B27+10)),$E$7,Inputs!$B$39,TRUE())-NORMDIST(MIN($D$7,MAX($C$7,$B27)),$E$7,Inputs!$B$39,TRUE()))/$F$7 -> 0 | E27: =$B$8*(NORMDIST(MIN($D$8,MAX($C$8,$B27+10)),$E$8,Inputs!$B$39,TRUE())-NORMDIST(MIN($D$8,MAX($C$8,$B27)),$E$8,Inputs!$B$39,TRUE()))/$F$8 -> 0 | F27: =$B$9*(NORMDIST(MIN($D$9,MAX($C$9,$B27+10)),$E$9,Inputs!$B$39,TRUE())-NORMDIST(MIN($D$9,MAX($C$9,$B27)),$E$9,Inputs!$B$39,TRUE()))/$F$9 -> 120.88116 | G27: =$B$10*(NORMDIST(MIN($D$10,MAX($C$10,$B27+10)),$E$10,Inputs!$B$39,TRUE())-NORMDIST(MIN($D$10,MAX($C$10,$B27)),$E$10,Inputs!$B$39,TRUE()))/$F$10 -> 22.75833 | H27: =$B$11*(NORMDIST(MIN($D$11,MAX($C$11,$B27+10)),$E$11,Inputs!$B$39,TRUE())-NORMDIST(MIN($D$11,MAX($C$11,$B27)),$E$11,Inputs!$B$39,TRUE()))/$F$11 -> 21.978392 | I27: =$B$12*(NORMDIST(MIN($D$12,MAX($C$12,$B27+10)),$E$12,Inputs!$B$39,TRUE())-NORMDIST(MIN($D$12,MAX($C$12,$B27)),$E$12,Inputs!$B$39,TRUE()))/$F$12 -> 8.6026565 | J27: =$B$13*(NORMDIST(MIN($D$13,MAX($C$13,$B27+10)),$E$13,Inputs!$B$39,TRUE())-NORMDIST(MIN($D$13,MAX($C$13,$B27)),$E$13,Inputs!$B$39,TRUE()))/$F$13 -> 10.989196 | K27: =SUM(C27:J27) -> 215.80704 | L27: =K27/SUM($K$19:$K$36) -> 0.072907784
A28: 13:00 | B28: 90 | C28: =$B$6*(NORMDIST(MIN($D$6,MAX($C$6,$B28+10)),$E$6,Inputs!$B$39,TRUE())-NORMDIST(MIN($D$6,MAX($C$6,$B28)),$E$6,Inputs!$B$39,TRUE()))/$F$6 -> 0 | D28: =$B$7*(NORMDIST(MIN($D$7,MAX($C$7,$B28+10)),$E$7,Inputs!$B$39,TRUE())-NORMDIST(MIN($D$7,MAX($C$7,$B28)),$E$7,Inputs!$B$39,TRUE()))/$F$7 -> 85.1663 | E28: =$B$8*(NORMDIST(MIN($D$8,MAX($C$8,$B28+10)),$E$8,Inputs!$B$39,TRUE())-NORMDIST(MIN($D$8,MAX($C$8,$B28)),$E$8,Inputs!$B$39,TRUE()))/$F$8 -> 67.755324 | F28: =$B$9*(NORMDIST(MIN($D$9,MAX($C$9,$B28+10)),$E$9,Inputs!$B$39,TRUE())-NORMDIST(MIN($D$9,MAX($C$9,$B28)),$E$9,Inputs!$B$39,TRUE()))/$F$9 -> 94.629222 | G28: =$B$10*(NORMDIST(MIN($D$10,MAX($C$10,$B28+10)),$E$10,Inputs!$B$39,TRUE())-NORMDIST(MIN($D$10,MAX($C$10,$B28)),$E$10,Inputs!$B$39,TRUE()))/$F$10 -> 0 | H28: =$B$11*(NORMDIST(MIN($D$11,MAX($C$11,$B28+10)),$E$11,Inputs!$B$39,TRUE())-NORMDIST(MIN($D$11,MAX($C$11,$B28)),$E$11,Inputs!$B$39,TRUE()))/$F$11 -> 21.978392 | I28: =$B$12*(NORMDIST(MIN($D$12,MAX($C$12,$B28+10)),$E$12,Inputs!$B$39,TRUE())-NORMDIST(MIN($D$12,MAX($C$12,$B28)),$E$12,Inputs!$B$39,TRUE()))/$F$12 -> 10.989196 | J28: =$B$13*(NORMDIST(MIN($D$13,MAX($C$13,$B28+10)),$E$13,Inputs!$B$39,TRUE())-NORMDIST(MIN($D$13,MAX($C$13,$B28)),$E$13,Inputs!$B$39,TRUE()))/$F$13 -> 8.6026565 | K28: =SUM(C28:J28) -> 289.12109 | L28: =K28/SUM($K$19:$K$36) -> 0.097676044
A29: 13:10 | B29: 100 | C29: =$B$6*(NORMDIST(MIN($D$6,MAX($C$6,$B29+10)),$E$6,Inputs!$B$39,TRUE())-NORMDIST(MIN($D$6,MAX($C$6,$B29)),$E$6,Inputs!$B$39,TRUE()))/$F$6 -> 0 | D29: =$B$7*(NORMDIST(MIN($D$7,MAX($C$7,$B29+10)),$E$7,Inputs!$B$39,TRUE())-NORMDIST(MIN($D$7,MAX($C$7,$B29)),$E$7,Inputs!$B$39,TRUE()))/$F$7 -> 108.79304 | E29: =$B$8*(NORMDIST(MIN($D$8,MAX($C$8,$B29+10)),$E$8,Inputs!$B$39,TRUE())-NORMDIST(MIN($D$8,MAX($C$8,$B29)),$E$8,Inputs!$B$39,TRUE()))/$F$8 -> 174.10928 | F29: =$B$9*(NORMDIST(MIN($D$9,MAX($C$9,$B29+10)),$E$9,Inputs!$B$39,TRUE())-NORMDIST(MIN($D$9,MAX($C$9,$B29)),$E$9,Inputs!$B$39,TRUE()))/$F$9 -> 57.988906 | G29: =$B$10*(NORMDIST(MIN($D$10,MAX($C$10,$B29+10)),$E$10,Inputs!$B$39,TRUE())-NORMDIST(MIN($D$10,MAX($C$10,$B29)),$E$10,Inputs!$B$39,TRUE()))/$F$10 -> 0 | H29: =$B$11*(NORMDIST(MIN($D$11,MAX($C$11,$B29+10)),$E$11,Inputs!$B$39,TRUE())-NORMDIST(MIN($D$11,MAX($C$11,$B29)),$E$11,Inputs!$B$39,TRUE()))/$F$11 -> 17.205313 | I29: =$B$12*(NORMDIST(MIN($D$12,MAX($C$12,$B29+10)),$E$12,Inputs!$B$39,TRUE())-NORMDIST(MIN($D$12,MAX($C$12,$B29)),$E$12,Inputs!$B$39,TRUE()))/$F$12 -> 10.989196 | J29: =$B$13*(NORMDIST(MIN($D$13,MAX($C$13,$B29+10)),$E$13,Inputs!$B$39,TRUE())-NORMDIST(MIN($D$13,MAX($C$13,$B29)),$E$13,Inputs!$B$39,TRUE()))/$F$13 -> 5.2717187 | K29: =SUM(C29:J29) -> 374.35746 | L29: =K29/SUM($K$19:$K$36) -> 0.12647211
A30: 13:20 | B30: 110 | C30: =$B$6*(NORMDIST(MIN($D$6,MAX($C$6,$B30+10)),$E$6,Inputs!$B$39,TRUE())-NORMDIST(MIN($D$6,MAX($C$6,$B30)),$E$6,Inputs!$B$39,TRUE()))/$F$6 -> 0 | D30: =$B$7*(NORMDIST(MIN($D$7,MAX($C$7,$B30+10)),$E$7,Inputs!$B$39,TRUE())-NORMDIST(MIN($D$7,MAX($C$7,$B30)),$E$7,Inputs!$B$39,TRUE()))/$F$7 -> 108.79304 | E30: =$B$8*(NORMDIST(MIN($D$8,MAX($C$8,$B30+10)),$E$8,Inputs!$B$39,TRUE())-NORMDIST(MIN($D$8,MAX($C$8,$B30)),$E$8,Inputs!$B$39,TRUE()))/$F$8 -> 196.78307 | F30: =$B$9*(NORMDIST(MIN($D$9,MAX($C$9,$B30+10)),$E$9,Inputs!$B$39,TRUE())-NORMDIST(MIN($D$9,MAX($C$9,$B30)),$E$9,Inputs!$B$39,TRUE()))/$F$9 -> 27.815737 | G30: =$B$10*(NORMDIST(MIN($D$10,MAX($C$10,$B30+10)),$E$10,Inputs!$B$39,TRUE())-NORMDIST(MIN($D$10,MAX($C$10,$B30)),$E$10,Inputs!$B$39,TRUE()))/$F$10 -> 0 | H30: =$B$11*(NORMDIST(MIN($D$11,MAX($C$11,$B30+10)),$E$11,Inputs!$B$39,TRUE())-NORMDIST(MIN($D$11,MAX($C$11,$B30)),$E$11,Inputs!$B$39,TRUE()))/$F$11 -> 10.543437 | I30: =$B$12*(NORMDIST(MIN($D$12,MAX($C$12,$B30+10)),$E$12,Inputs!$B$39,TRUE())-NORMDIST(MIN($D$12,MAX($C$12,$B30)),$E$12,Inputs!$B$39,TRUE()))/$F$12 -> 8.6026565 | J30: =$B$13*(NORMDIST(MIN($D$13,MAX($C$13,$B30+10)),$E$13,Inputs!$B$39,TRUE())-NORMDIST(MIN($D$13,MAX($C$13,$B30)),$E$13,Inputs!$B$39,TRUE()))/$F$13 -> 2.5287033 | K30: =SUM(C30:J30) -> 355.06664 | L30: =K30/SUM($K$19:$K$36) -> 0.11995495
... A36: 14:20 | B36: 170 | C36: =$B$6*(NORMDIST(MIN($D$6,MAX($C$6,$B36+10)),$E$6,Inputs!$B$39,TRUE())-NORMDIST(MIN($D$6,MAX($C$6,$B36)),$E$6,Inputs!$B$39,TRUE()))/$F$6 -> 0 | D36: =$B$7*(NORMDIST(MIN($D$7,MAX($C$7,$B36+10)),$E$7,Inputs!$B$39,TRUE())-NORMDIST(MIN($D$7,MAX($C$7,$B36)),$E$7,Inputs!$B$39,TRUE()))/$F$7 -> 0 | E36: =$B$8*(NORMDIST(MIN($D$8,MAX($C$8,$B36+10)),$E$8,Inputs!$B$39,TRUE())-NORMDIST(MIN($D$8,MAX($C$8,$B36)),$E$8,Inputs!$B$39,TRUE()))/$F$8 -> 0 | F36: =$B$9*(NORMDIST(MIN($D$9,MAX($C$9,$B36+10)),$E$9,Inputs!$B$39,TRUE())-NORMDIST(MIN($D$9,MAX($C$9,$B36)),$E$9,Inputs!$B$39,TRUE()))/$F$9 -> 0 | G36: =$B$10*(NORMDIST(MIN($D$10,MAX($C$10,$B36+10)),$E$10,Inputs!$B$39,TRUE())-NORMDIST(MIN($D$10,MAX($C$10,$B36)),$E$10,Inputs!$B$39,TRUE()))/$F$10 -> 0 | H36: =$B$11*(NORMDIST(MIN($D$11,MAX($C$11,$B36+10)),$E$11,Inputs!$B$39,TRUE())-NORMDIST(MIN($D$11,MAX($C$11,$B36)),$E$11,Inputs!$B$39,TRUE()))/$F$11 -> 0 | I36: =$B$12*(NORMDIST(MIN($D$12,MAX($C$12,$B36+10)),$E$12,Inputs!$B$39,TRUE())-NORMDIST(MIN($D$12,MAX($C$12,$B36)),$E$12,Inputs!$B$39,TRUE()))/$F$12 -> 0 | J36: =$B$13*(NORMDIST(MIN($D$13,MAX($C$13,$B36+10)),$E$13,Inputs!$B$39,TRUE())-NORMDIST(MIN($D$13,MAX($C$13,$B36)),$E$13,Inputs!$B$39,TRUE()))/$F$13 -> 0 | K36: =SUM(C36:J36) -> 0 | L36: =K36/SUM($K$19:$K$36) -> 0
A38: Busiest 10-minute slot | B38: =INDEX(A19:A36,MATCH(MAX(K19:K36),K19:K36,0)) -> 13:10
A39: Students arriving in it (both messes) | B39: =MAX(K19:K36) -> 374.35746
A40: Capacity of both messes in 10 min (4 stations) | B40: =(Inputs!$B$82+Inputs!$B$83)*10 -> 400
A41: Two surges: about 12:10 (MIT and SMI) and a larger one about 13:10–13:30, when MIT's lab-day batch, TAPMI, DOC/MICFE, DLHS/MILHS and MLS overlap. In the busiest slot arrivals reach about 94% of what both messes together can serve, and 80% of them head to Central, which alone can serve only 200. Balancing uses Munch's spare capacity; staggering one department's break by 15 minutes is the demand-side fix (Scenarios: stagger tests).

Sheet S15 Queuing
A1: Queuing analysis: M/M/1, M/M/c and lunch-peak overload, without vs with the screens
A2: Session 15: Introduction to queuing theory and waiting-line models
A4: 1. Check against the lecture example (Hatti Kaapi, M/M/1) | J4: 2. Why waits explode near 100% busy (M/M/1, one serving station)
A5: λ /hour | B5: μ /hour | C5: ρ | D5: Wq (hours) | E5: Wq (min) | F5: W (min) | G5: Lq | H5: L | J5: μ per hour | K5: =Inputs!$B$26*60 -> 600
A6: 18 | B6: 24 | C6: =A6/B6 -> 0.75 | D6: =A6/(B6*(B6-A6)) -> 0.125 | E6: =D6*60 -> 7.5 | F6: =60/(B6-A6) -> 10 | G6: =A6*D6 -> 2.25 | H6: =A6*F6/60 -> 3 | J6: ρ | K6: λ /hour | L6: Wq (min) | M6: Lq
A7: Lecture answers: ρ = 75%, Wq = 7.5 min, W = 10 min, Lq = 2.25. If these match, the formulas below are right. | J7: 0.5 | K7: =J7*$K$5 -> 300 | L7: =K7/($K$5*($K$5-K7))*60 -> 0.1 | M7: =K7*L7/60 -> 0.5
J8: 0.6 | K8: =J8*$K$5 -> 360 | L8: =K8/($K$5*($K$5-K8))*60 -> 0.15 | M8: =K8*L8/60 -> 0.9
J9: 0.7 | K9: =J9*$K$5 -> 420 | L9: =K9/($K$5*($K$5-K9))*60 -> 0.23333333 | M9: =K9*L9/60 -> 1.6333333
J10: 0.75 | K10: =J10*$K$5 -> 450 | L10: =K10/($K$5*($K$5-K10))*60 -> 0.3 | M10: =K10*L10/60 -> 2.25
J11: 0.8 | K11: =J11*$K$5 -> 480 | L11: =K11/($K$5*($K$5-K11))*60 -> 0.4 | M11: =K11*L11/60 -> 3.2
J12: 0.85 | K12: =J12*$K$5 -> 510 | L12: =K12/($K$5*($K$5-K12))*60 -> 0.56666667 | M12: =K12*L12/60 -> 4.8166667
J13: 0.9 | K13: =J13*$K$5 -> 540 | L13: =K13/($K$5*($K$5-K13))*60 -> 0.9 | M13: =K13*L13/60 -> 8.1
J14: 0.93 | K14: =J14*$K$5 -> 558 | L14: =K14/($K$5*($K$5-K14))*60 -> 1.3285714 | M14: =K14*L14/60 -> 12.355714
J15: 0.95 | K15: =J15*$K$5 -> 570 | L15: =K15/($K$5*($K$5-K15))*60 -> 1.9 | M15: =K15*L15/60 -> 18.05
J16: 0.96 | K16: =J16*$K$5 -> 576 | L16: =K16/($K$5*($K$5-K16))*60 -> 2.4 | M16: =K16*L16/60 -> 23.04
J17: 0.97 | K17: =J17*$K$5 -> 582 | L17: =K17/($K$5*($K$5-K17))*60 -> 3.2333333 | M17: =K17*L17/60 -> 31.363333
J18: 0.98 | K18: =J18*$K$5 -> 588 | L18: =K18/($K$5*($K$5-K18))*60 -> 4.9 | M18: =K18*L18/60 -> 48.02
A22: 3. Lunch by 10-minute slot: without vs with the door screens (M/M/c, plus a fluid queue for overload)
A23: Arrivals = the department lunch breaks added up (Arrival Curve tab; shape ASSUMED until the biometric logs replace column C). Backlog (end of slot) = max(0, backlog at the start + arrivals − capacity × 10): the line carried from slot to slot. Queue wait = (backlog at the start + backlog at the end) ÷ 2 ÷ capacity (the line a student meets half-way through the slot) + the M/M/c wait with ρ capped at 95% for the randomness a smooth average misses (P(wait) and Wq random use the capped rate; the live engine uses the same rule). Throughput = stage 1 + queue wait + serving + food line + eating + disposal. 'With screens' moves the share who comply toward equal utilisation in every slot, with perfect knowledge (see Reconciliation).
A25: Equal-utilisation share for Central | E25: =Inputs!$B$82/(Inputs!$B$82+Inputs!$B$83) -> 0.5 | F25: Formula: capacity of Central ÷ (capacity of Central + capacity of Munch)
A26: Realised share for Central with screens | E26: =Inputs!$B$35+Inputs!$B$36*(E25-Inputs!$B$35) -> 0.6188 | F26: Formula: habit + compliance × (target − habit). Only students who follow the screen move
E28: Without screens — Central CT | N28: Without screens — Munch | W28: With screens — Central CT | AF28: With screens — Munch
A29: Slot start | B29: Curve share | C29: Arrivals (both messes) | D29: λ total /min | E29: λ /min | F29: Scanner ρ | G29: ρ | H29: P(wait) | I29: Wq random (min) | J29: Backlog end | K29: Queue wait (min) | L29: Throughput (min) | M29: People inside | N29: λ /min | O29: Scanner ρ | P29: ρ | Q29: P(wait) | R29: Wq random (min) | S29: Backlog end | T29: Queue wait (min) | U29: Throughput (min) | V29: People inside | W29: λ /min | X29: Scanner ρ | Y29: ρ | Z29: P(wait) | AA29: Wq random (min) | AB29: Backlog end | AC29: Queue wait (min) | AD29: Throughput (min) | AE29: People inside | AF29: λ /min | AG29: Scanner ρ | AH29: ρ | AI29: P(wait) | AJ29: Wq random (min) | AK29: Backlog end | AL29: Queue wait (min) | AM29: Throughput (min) | AN29: People inside
A30: 11:30 | B30: ='Arrival Curve'!$L$19 -> 0 | C30: ='Arrival Curve'!$K$19 -> 0 | D30: =C30/10 -> 0 | E30: =$D30*Inputs!$B$35 -> 0 | F30: =E30/Inputs!$B$84 -> 0 | G30: =E30/(Inputs!$B$11*Inputs!$B$26) -> 0 | H30: =IF(E30>0,((MIN(E30,0.95*Inputs!$B$11*Inputs!$B$26)/Inputs!$B$26)^Inputs!$B$11/FACT(Inputs!$B$11)*Inputs!$B$11/(Inputs!$B$11-(MIN(E30,0.95*Inputs!$B$11*Inputs!$B$26)/Inputs!$B$26)))/(SUMPRODUCT(--({0,1,2,3,4,5,6,7,8,9}<Inputs!$B$11),(MIN(E30,0.95*Inputs!$B$11*Inputs!$B$26)/Inputs!$B$26)^{0,1,2,3,4,5,6,7,8,9}/FACT({0,1,2,3,4,5,6,7,8,9}))+((MIN(E30,0.95*Inputs!$B$11*Inputs!$B$26)/Inputs!$B$26)^Inputs!$B$11/FACT(Inputs!$B$11)*Inputs!$B$11/(Inputs!$B$11-(MIN(E30,0.95*Inputs!$B$11*Inputs!$B$26)/Inputs!$B$26)))),0) -> 0 | I30: =IF(E30>0,H30/(Inputs!$B$11*Inputs!$B$26-MIN(E30,0.95*Inputs!$B$11*Inputs!$B$26)),0) -> 0 | J30: =MAX(0,0+(E30-Inputs!$B$11*Inputs!$B$26)*10) -> 0 | K30: =(0+J30)/2/(Inputs!$B$11*Inputs!$B$26)+I30 -> 0 | L30: =Inputs!$B$86+K30+1/Inputs!$B$26+Inputs!$B$87+Inputs!$B$88+Inputs!$B$89 -> 28.625 | M30: =E30*L30 -> 0 | N30: =$D30*(1-Inputs!$B$35) -> 0 | O30: =N30/Inputs!$B$85 -> 0 | P30: =N30/(Inputs!$B$12*Inputs!$B$26) -> 0 | Q30: =IF(N30>0,((MIN(N30,0.95*Inputs!$B$12*Inputs!$B$26)/Inputs!$B$26)^Inputs!$B$12/FACT(Inputs!$B$12)*Inputs!$B$12/(Inputs!$B$12-(MIN(N30,0.95*Inputs!$B$12*Inputs!$B$26)/Inputs!$B$26)))/(SUMPRODUCT(--({0,1,2,3,4,5,6,7,8,9}<Inputs!$B$12),(MIN(N30,0.95*Inputs!$B$12*Inputs!$B$26)/Inputs!$B$26)^{0,1,2,3,4,5,6,7,8,9}/FACT({0,1,2,3,4,5,6,7,8,9}))+((MIN(N30,0.95*Inputs!$B$12*Inputs!$B$26)/Inputs!$B$26)^Inputs!$B$12/FACT(Inputs!$B$12)*Inputs!$B$12/(Inputs!$B$12-(MIN(N30,0.95*Inputs!$B$12*Inputs!$B$26)/Inputs!$B$26)))),0) -> 0 | R30: =IF(N30>0,Q30/(Inputs!$B$12*Inputs!$B$26-MIN(N30,0.95*Inputs!$B$12*Inputs!$B$26)),0) -> 0 | S30: =MAX(0,0+(N30-Inputs!$B$12*Inputs!$B$26)*10) -> 0 | T30: =(0+S30)/2/(Inputs!$B$12*Inputs!$B$26)+R30 -> 0 | U30: =Inputs!$B$86+T30+1/Inputs!$B$26+Inputs!$B$87+Inputs!$B$88+Inputs!$B$89 -> 28.625 | V30: =N30*U30 -> 0 | W30: =$D30*$E$26 -> 0 | X30: =W30/Inputs!$B$84 -> 0 | Y30: =W30/(Inputs!$B$11*Inputs!$B$26) -> 0 | Z30: =IF(W30>0,((MIN(W30,0.95*Inputs!$B$11*Inputs!$B$26)/Inputs!$B$26)^Inputs!$B$11/FACT(Inputs!$B$11)*Inputs!$B$11/(Inputs!$B$11-(MIN(W30,0.95*Inputs!$B$11*Inputs!$B$26)/Inputs!$B$26)))/(SUMPRODUCT(--({0,1,2,3,4,5,6,7,8,9}<Inputs!$B$11),(MIN(W30,0.95*Inputs!$B$11*Inputs!$B$26)/Inputs!$B$26)^{0,1,2,3,4,5,6,7,8,9}/FACT({0,1,2,3,4,5,6,7,8,9}))+((MIN(W30,0.95*Inputs!$B$11*Inputs!$B$26)/Inputs!$B$26)^Inputs!$B$11/FACT(Inputs!$B$11)*Inputs!$B$11/(Inputs!$B$11-(MIN(W30,0.95*Inputs!$B$11*Inputs!$B$26)/Inputs!$B$26)))),0) -> 0 | AA30: =IF(W30>0,Z30/(Inputs!$B$11*Inputs!$B$26-MIN(W30,0.95*Inputs!$B$11*Inputs!$B$26)),0) -> 0 | AB30: =MAX(0,0+(W30-Inputs!$B$11*Inputs!$B$26)*10) -> 0 | AC30: =(0+AB30)/2/(Inputs!$B$11*Inputs!$B$26)+AA30 -> 0 | AD30: =Inputs!$B$86+AC30+1/Inputs!$B$26+Inputs!$B$87+Inputs!$B$88+Inputs!$B$89 -> 28.625 | AE30: =W30*AD30 -> 0 | AF30: =$D30*(1-$E$26) -> 0 | AG30: =AF30/Inputs!$B$85 -> 0 | AH30: =AF30/(Inputs!$B$12*Inputs!$B$26) -> 0 | AI30: =IF(AF30>0,((MIN(AF30,0.95*Inputs!$B$12*Inputs!$B$26)/Inputs!$B$26)^Inputs!$B$12/FACT(Inputs!$B$12)*Inputs!$B$12/(Inputs!$B$12-(MIN(AF30,0.95*Inputs!$B$12*Inputs!$B$26)/Inputs!$B$26)))/(SUMPRODUCT(--({0,1,2,3,4,5,6,7,8,9}<Inputs!$B$12),(MIN(AF30,0.95*Inputs!$B$12*Inputs!$B$26)/Inputs!$B$26)^{0,1,2,3,4,5,6,7,8,9}/FACT({0,1,2,3,4,5,6,7,8,9}))+((MIN(AF30,0.95*Inputs!$B$12*Inputs!$B$26)/Inputs!$B$26)^Inputs!$B$12/FACT(Inputs!$B$12)*Inputs!$B$12/(Inputs!$B$12-(MIN(AF30,0.95*Inputs!$B$12*Inputs!$B$26)/Inputs!$B$26)))),0) -> 0 | AJ30: =IF(AF30>0,AI30/(Inputs!$B$12*Inputs!$B$26-MIN(AF30,0.95*Inputs!$B$12*Inputs!$B$26)),0) -> 0 | AK30: =MAX(0,0+(AF30-Inputs!$B$12*Inputs!$B$26)*10) -> 0 | AL30: =(0+AK30)/2/(Inputs!$B$12*Inputs!$B$26)+AJ30 -> 0 | AM30: =Inputs!$B$86+AL30+1/Inputs!$B$26+Inputs!$B$87+Inputs!$B$88+Inputs!$B$89 -> 28.625 | AN30: =AF30*AM30 -> 0
A31: 11:40 | B31: ='Arrival Curve'!$L$20 -> 0 | C31: ='Arrival Curve'!$K$20 -> 0 | D31: =C31/10 -> 0 | E31: =$D31*Inputs!$B$35 -> 0 | F31: =E31/Inputs!$B$84 -> 0 | G31: =E31/(Inputs!$B$11*Inputs!$B$26) -> 0 | H31: =IF(E31>0,((MIN(E31,0.95*Inputs!$B$11*Inputs!$B$26)/Inputs!$B$26)^Inputs!$B$11/FACT(Inputs!$B$11)*Inputs!$B$11/(Inputs!$B$11-(MIN(E31,0.95*Inputs!$B$11*Inputs!$B$26)/Inputs!$B$26)))/(SUMPRODUCT(--({0,1,2,3,4,5,6,7,8,9}<Inputs!$B$11),(MIN(E31,0.95*Inputs!$B$11*Inputs!$B$26)/Inputs!$B$26)^{0,1,2,3,4,5,6,7,8,9}/FACT({0,1,2,3,4,5,6,7,8,9}))+((MIN(E31,0.95*Inputs!$B$11*Inputs!$B$26)/Inputs!$B$26)^Inputs!$B$11/FACT(Inputs!$B$11)*Inputs!$B$11/(Inputs!$B$11-(MIN(E31,0.95*Inputs!$B$11*Inputs!$B$26)/Inputs!$B$26)))),0) -> 0 | I31: =IF(E31>0,H31/(Inputs!$B$11*Inputs!$B$26-MIN(E31,0.95*Inputs!$B$11*Inputs!$B$26)),0) -> 0 | J31: =MAX(0,J30+(E31-Inputs!$B$11*Inputs!$B$26)*10) -> 0 | K31: =(J30+J31)/2/(Inputs!$B$11*Inputs!$B$26)+I31 -> 0 | L31: =Inputs!$B$86+K31+1/Inputs!$B$26+Inputs!$B$87+Inputs!$B$88+Inputs!$B$89 -> 28.625 | M31: =E31*L31 -> 0 | N31: =$D31*(1-Inputs!$B$35) -> 0 | O31: =N31/Inputs!$B$85 -> 0 | P31: =N31/(Inputs!$B$12*Inputs!$B$26) -> 0 | Q31: =IF(N31>0,((MIN(N31,0.95*Inputs!$B$12*Inputs!$B$26)/Inputs!$B$26)^Inputs!$B$12/FACT(Inputs!$B$12)*Inputs!$B$12/(Inputs!$B$12-(MIN(N31,0.95*Inputs!$B$12*Inputs!$B$26)/Inputs!$B$26)))/(SUMPRODUCT(--({0,1,2,3,4,5,6,7,8,9}<Inputs!$B$12),(MIN(N31,0.95*Inputs!$B$12*Inputs!$B$26)/Inputs!$B$26)^{0,1,2,3,4,5,6,7,8,9}/FACT({0,1,2,3,4,5,6,7,8,9}))+((MIN(N31,0.95*Inputs!$B$12*Inputs!$B$26)/Inputs!$B$26)^Inputs!$B$12/FACT(Inputs!$B$12)*Inputs!$B$12/(Inputs!$B$12-(MIN(N31,0.95*Inputs!$B$12*Inputs!$B$26)/Inputs!$B$26)))),0) -> 0 | R31: =IF(N31>0,Q31/(Inputs!$B$12*Inputs!$B$26-MIN(N31,0.95*Inputs!$B$12*Inputs!$B$26)),0) -> 0 | S31: =MAX(0,S30+(N31-Inputs!$B$12*Inputs!$B$26)*10) -> 0 | T31: =(S30+S31)/2/(Inputs!$B$12*Inputs!$B$26)+R31 -> 0 | U31: =Inputs!$B$86+T31+1/Inputs!$B$26+Inputs!$B$87+Inputs!$B$88+Inputs!$B$89 -> 28.625 | V31: =N31*U31 -> 0 | W31: =$D31*$E$26 -> 0 | X31: =W31/Inputs!$B$84 -> 0 | Y31: =W31/(Inputs!$B$11*Inputs!$B$26) -> 0 | Z31: =IF(W31>0,((MIN(W31,0.95*Inputs!$B$11*Inputs!$B$26)/Inputs!$B$26)^Inputs!$B$11/FACT(Inputs!$B$11)*Inputs!$B$11/(Inputs!$B$11-(MIN(W31,0.95*Inputs!$B$11*Inputs!$B$26)/Inputs!$B$26)))/(SUMPRODUCT(--({0,1,2,3,4,5,6,7,8,9}<Inputs!$B$11),(MIN(W31,0.95*Inputs!$B$11*Inputs!$B$26)/Inputs!$B$26)^{0,1,2,3,4,5,6,7,8,9}/FACT({0,1,2,3,4,5,6,7,8,9}))+((MIN(W31,0.95*Inputs!$B$11*Inputs!$B$26)/Inputs!$B$26)^Inputs!$B$11/FACT(Inputs!$B$11)*Inputs!$B$11/(Inputs!$B$11-(MIN(W31,0.95*Inputs!$B$11*Inputs!$B$26)/Inputs!$B$26)))),0) -> 0 | AA31: =IF(W31>0,Z31/(Inputs!$B$11*Inputs!$B$26-MIN(W31,0.95*Inputs!$B$11*Inputs!$B$26)),0) -> 0 | AB31: =MAX(0,AB30+(W31-Inputs!$B$11*Inputs!$B$26)*10) -> 0 | AC31: =(AB30+AB31)/2/(Inputs!$B$11*Inputs!$B$26)+AA31 -> 0 | AD31: =Inputs!$B$86+AC31+1/Inputs!$B$26+Inputs!$B$87+Inputs!$B$88+Inputs!$B$89 -> 28.625 | AE31: =W31*AD31 -> 0 | AF31: =$D31*(1-$E$26) -> 0 | AG31: =AF31/Inputs!$B$85 -> 0 | AH31: =AF31/(Inputs!$B$12*Inputs!$B$26) -> 0 | AI31: =IF(AF31>0,((MIN(AF31,0.95*Inputs!$B$12*Inputs!$B$26)/Inputs!$B$26)^Inputs!$B$12/FACT(Inputs!$B$12)*Inputs!$B$12/(Inputs!$B$12-(MIN(AF31,0.95*Inputs!$B$12*Inputs!$B$26)/Inputs!$B$26)))/(SUMPRODUCT(--({0,1,2,3,4,5,6,7,8,9}<Inputs!$B$12),(MIN(AF31,0.95*Inputs!$B$12*Inputs!$B$26)/Inputs!$B$26)^{0,1,2,3,4,5,6,7,8,9}/FACT({0,1,2,3,4,5,6,7,8,9}))+((MIN(AF31,0.95*Inputs!$B$12*Inputs!$B$26)/Inputs!$B$26)^Inputs!$B$12/FACT(Inputs!$B$12)*Inputs!$B$12/(Inputs!$B$12-(MIN(AF31,0.95*Inputs!$B$12*Inputs!$B$26)/Inputs!$B$26)))),0) -> 0 | AJ31: =IF(AF31>0,AI31/(Inputs!$B$12*Inputs!$B$26-MIN(AF31,0.95*Inputs!$B$12*Inputs!$B$26)),0) -> 0 | AK31: =MAX(0,AK30+(AF31-Inputs!$B$12*Inputs!$B$26)*10) -> 0 | AL31: =(AK30+AK31)/2/(Inputs!$B$12*Inputs!$B$26)+AJ31 -> 0 | AM31: =Inputs!$B$86+AL31+1/Inputs!$B$26+Inputs!$B$87+Inputs!$B$88+Inputs!$B$89 -> 28.625 | AN31: =AF31*AM31 -> 0
A32: 11:50 | B32: ='Arrival Curve'!$L$21 -> 0 | C32: ='Arrival Curve'!$K$21 -> 0 | D32: =C32/10 -> 0 | E32: =$D32*Inputs!$B$35 -> 0 | F32: =E32/Inputs!$B$84 -> 0 | G32: =E32/(Inputs!$B$11*Inputs!$B$26) -> 0 | H32: =IF(E32>0,((MIN(E32,0.95*Inputs!$B$11*Inputs!$B$26)/Inputs!$B$26)^Inputs!$B$11/FACT(Inputs!$B$11)*Inputs!$B$11/(Inputs!$B$11-(MIN(E32,0.95*Inputs!$B$11*Inputs!$B$26)/Inputs!$B$26)))/(SUMPRODUCT(--({0,1,2,3,4,5,6,7,8,9}<Inputs!$B$11),(MIN(E32,0.95*Inputs!$B$11*Inputs!$B$26)/Inputs!$B$26)^{0,1,2,3,4,5,6,7,8,9}/FACT({0,1,2,3,4,5,6,7,8,9}))+((MIN(E32,0.95*Inputs!$B$11*Inputs!$B$26)/Inputs!$B$26)^Inputs!$B$11/FACT(Inputs!$B$11)*Inputs!$B$11/(Inputs!$B$11-(MIN(E32,0.95*Inputs!$B$11*Inputs!$B$26)/Inputs!$B$26)))),0) -> 0 | I32: =IF(E32>0,H32/(Inputs!$B$11*Inputs!$B$26-MIN(E32,0.95*Inputs!$B$11*Inputs!$B$26)),0) -> 0 | J32: =MAX(0,J31+(E32-Inputs!$B$11*Inputs!$B$26)*10) -> 0 | K32: =(J31+J32)/2/(Inputs!$B$11*Inputs!$B$26)+I32 -> 0 | L32: =Inputs!$B$86+K32+1/Inputs!$B$26+Inputs!$B$87+Inputs!$B$88+Inputs!$B$89 -> 28.625 | M32: =E32*L32 -> 0 | N32: =$D32*(1-Inputs!$B$35) -> 0 | O32: =N32/Inputs!$B$85 -> 0 | P32: =N32/(Inputs!$B$12*Inputs!$B$26) -> 0 | Q32: =IF(N32>0,((MIN(N32,0.95*Inputs!$B$12*Inputs!$B$26)/Inputs!$B$26)^Inputs!$B$12/FACT(Inputs!$B$12)*Inputs!$B$12/(Inputs!$B$12-(MIN(N32,0.95*Inputs!$B$12*Inputs!$B$26)/Inputs!$B$26)))/(SUMPRODUCT(--({0,1,2,3,4,5,6,7,8,9}<Inputs!$B$12),(MIN(N32,0.95*Inputs!$B$12*Inputs!$B$26)/Inputs!$B$26)^{0,1,2,3,4,5,6,7,8,9}/FACT({0,1,2,3,4,5,6,7,8,9}))+((MIN(N32,0.95*Inputs!$B$12*Inputs!$B$26)/Inputs!$B$26)^Inputs!$B$12/FACT(Inputs!$B$12)*Inputs!$B$12/(Inputs!$B$12-(MIN(N32,0.95*Inputs!$B$12*Inputs!$B$26)/Inputs!$B$26)))),0) -> 0 | R32: =IF(N32>0,Q32/(Inputs!$B$12*Inputs!$B$26-MIN(N32,0.95*Inputs!$B$12*Inputs!$B$26)),0) -> 0 | S32: =MAX(0,S31+(N32-Inputs!$B$12*Inputs!$B$26)*10) -> 0 | T32: =(S31+S32)/2/(Inputs!$B$12*Inputs!$B$26)+R32 -> 0 | U32: =Inputs!$B$86+T32+1/Inputs!$B$26+Inputs!$B$87+Inputs!$B$88+Inputs!$B$89 -> 28.625 | V32: =N32*U32 -> 0 | W32: =$D32*$E$26 -> 0 | X32: =W32/Inputs!$B$84 -> 0 | Y32: =W32/(Inputs!$B$11*Inputs!$B$26) -> 0 | Z32: =IF(W32>0,((MIN(W32,0.95*Inputs!$B$11*Inputs!$B$26)/Inputs!$B$26)^Inputs!$B$11/FACT(Inputs!$B$11)*Inputs!$B$11/(Inputs!$B$11-(MIN(W32,0.95*Inputs!$B$11*Inputs!$B$26)/Inputs!$B$26)))/(SUMPRODUCT(--({0,1,2,3,4,5,6,7,8,9}<Inputs!$B$11),(MIN(W32,0.95*Inputs!$B$11*Inputs!$B$26)/Inputs!$B$26)^{0,1,2,3,4,5,6,7,8,9}/FACT({0,1,2,3,4,5,6,7,8,9}))+((MIN(W32,0.95*Inputs!$B$11*Inputs!$B$26)/Inputs!$B$26)^Inputs!$B$11/FACT(Inputs!$B$11)*Inputs!$B$11/(Inputs!$B$11-(MIN(W32,0.95*Inputs!$B$11*Inputs!$B$26)/Inputs!$B$26)))),0) -> 0 | AA32: =IF(W32>0,Z32/(Inputs!$B$11*Inputs!$B$26-MIN(W32,0.95*Inputs!$B$11*Inputs!$B$26)),0) -> 0 | AB32: =MAX(0,AB31+(W32-Inputs!$B$11*Inputs!$B$26)*10) -> 0 | AC32: =(AB31+AB32)/2/(Inputs!$B$11*Inputs!$B$26)+AA32 -> 0 | AD32: =Inputs!$B$86+AC32+1/Inputs!$B$26+Inputs!$B$87+Inputs!$B$88+Inputs!$B$89 -> 28.625 | AE32: =W32*AD32 -> 0 | AF32: =$D32*(1-$E$26) -> 0 | AG32: =AF32/Inputs!$B$85 -> 0 | AH32: =AF32/(Inputs!$B$12*Inputs!$B$26) -> 0 | AI32: =IF(AF32>0,((MIN(AF32,0.95*Inputs!$B$12*Inputs!$B$26)/Inputs!$B$26)^Inputs!$B$12/FACT(Inputs!$B$12)*Inputs!$B$12/(Inputs!$B$12-(MIN(AF32,0.95*Inputs!$B$12*Inputs!$B$26)/Inputs!$B$26)))/(SUMPRODUCT(--({0,1,2,3,4,5,6,7,8,9}<Inputs!$B$12),(MIN(AF32,0.95*Inputs!$B$12*Inputs!$B$26)/Inputs!$B$26)^{0,1,2,3,4,5,6,7,8,9}/FACT({0,1,2,3,4,5,6,7,8,9}))+((MIN(AF32,0.95*Inputs!$B$12*Inputs!$B$26)/Inputs!$B$26)^Inputs!$B$12/FACT(Inputs!$B$12)*Inputs!$B$12/(Inputs!$B$12-(MIN(AF32,0.95*Inputs!$B$12*Inputs!$B$26)/Inputs!$B$26)))),0) -> 0 | AJ32: =IF(AF32>0,AI32/(Inputs!$B$12*Inputs!$B$26-MIN(AF32,0.95*Inputs!$B$12*Inputs!$B$26)),0) -> 0 | AK32: =MAX(0,AK31+(AF32-Inputs!$B$12*Inputs!$B$26)*10) -> 0 | AL32: =(AK31+AK32)/2/(Inputs!$B$12*Inputs!$B$26)+AJ32 -> 0 | AM32: =Inputs!$B$86+AL32+1/Inputs!$B$26+Inputs!$B$87+Inputs!$B$88+Inputs!$B$89 -> 28.625 | AN32: =AF32*AM32 -> 0
