Workbook

Sheet Start Here
A1: MDS decision workbook — Mess queue and allocation project (Group WGB3)
A2: Every Management Decision Science course topic applied to the Chefs Touch lunch problem (Central CT and Munch Mess, lunch 11:30–14:30).
A4: How to use
A5: 1. Change only BLUE cells. Black cells are formulas; GREEN cells pull values from another tab.
A6: 2. YELLOW-filled cells are assumed or illustrative. Replace them with measurements when you have them (biometric logs, stopwatch, CT data).
A7: 3. Start with the Inputs tab — most tabs read from it, so one change updates the whole workbook.
A8: 4. Green-filled cells are the key results of each tab.
A10: Status tags used
A11: Tag | B11: Meaning | C11: Example
A12: Measured | B12: From our field work, the Phase 1 deck or the group | C12: 2,960 students (= plates); seats 900 / 500; 2 stations + 1 scanner per mess; ~18 min visit
A13: Assumed | B13: A placeholder until measured | C13: 85% go to Central by habit; 10 students/min per serving station
A14: Illustrative | B14: Made-up numbers to demonstrate a method | C14: Probabilities, ₹ values in the decision tree, AHP judgements
A15: Simulated | B15: Output of our prototype's simulator | C15: Average wait 7.1 → 0.8 min
A17: Tabs and course sessions
A18: Tab | B18: Session(s) | C18: What it does
A19: Inputs | B19: — | C19: All shared numbers, with status and source
A20: S2-3 Problem & Root Cause | B20: 2–3 | C20: Nature of the decision; problem statement; 5 Whys; fishbone; issue tree
A21: S4 Biases & Ethics | B21: 4 | C21: Decision biases in the mess problem and how we counter them; ethics checklist (DPDP)
A22: S5-6 Priority Matrix | B22: 5–6 | C22: ABC/XYZ menu matrix; impact–effort matrix of interventions; decision dilemmas
A23: S7 Payoff Matrix | B23: 7 | C23: With vs without the system across normal / busy / surge days, in minutes saved: maximax, maximin, minimax regret, Hurwicz, Laplace, EMV, EVPI
A24: S7 Decision Tree | B24: 7 | C24: Pre-stage a batch or wait and react: EMV, break-even probability, sensitivity
A25: S10-11 LP Allocation | B25: 10–11 | C25: LP formulation, constraints, graphical method (corner points), Solver/simplex
A26: S12-14 IP Staffing | B26: 12–14 | C26: Integer serving stations per slot, with vs without screens; branch-and-bound illustration
A27: S15 Queuing | B27: 15 | C27: Lecture check (Hatti Kaapi), utilisation curve, M/M/c by 10-min bin with overload, without vs with screens, Little's Law
A28: S16-17 AHP | B28: 16–17 | C28: Pairwise comparisons, weights, consistency ratio, ranking of alternatives
A29: S16-17 BWM | B29: 16–17 | C29: Best–Worst Method weights and consistency; comparison with AHP
... A32: Simulation Results | B32: — | C32: Prototype simulator results used as anchors
A34: Only the queuing tab's arrival curve and the decision models' costs and probabilities are placeholders. Once the biometric logs arrive, paste arrivals per 10 minutes into S15 Queuing column B, and the share of normal / busy / surge days into S7 Payoff Matrix row 14.

Sheet Inputs
A1: Inputs: every number the workbook uses
A2: Change BLUE cells only. Yellow = assumed or illustrative: replace with measured data when available.
A4: Parameter | B4: Value | C4: Unit | D4: Status | E4: Source / notes
A5: MEASURED (from Phase 1 field work / the group)
A6: Students per lunch at Central CT + Munch (= plates served) | B6: 2960 | C6: students | D6: Measured | E6: Phase 1 deck: ~2,960 plates; one plate per student
A7: Lunch opens | B7: 11:30 | C7: time | D7: Measured | E7: Mess timings 11:30–14:30
A8: Lunch window length | B8: 180 | C8: minutes | D8: Measured | E8: 11:30–14:30
A9: Seats: Central CT | B9: 900 | C9: seats | D9: Measured | E9: Group measurement
A10: Seats: Munch Mess | B10: 500 | C10: seats | D10: Measured | E10: Group measurement
A11: Serving stations: Central CT | B11: 2 | C11: stations | D11: Measured | E11: Group observation
A12: Serving stations: Munch Mess | B12: 2 | C12: stations | D12: Measured | E12: Group observation
A13: Face scanners at the entrance: Central CT | B13: 1 | C13: scanners | D13: Measured | E13: Group observation
A14: Face scanners at the entrance: Munch Mess | B14: 1 | C14: scanners | D14: Measured | E14: Group observation
A15: Normal visit, scan to leaving | B15: 18 | C15: minutes | D15: Measured | E15: Group observation; normal day. Surges add queue time
A16: Restock after a 'running low' call: kitchen makes it and sends it (total) | B16: 30 | C16: minutes | D16: Measured | E16: Group: the 30 min starts when the mess calls the kitchen
A17: Restock when the food is already made: sending only (low) | B17: 10 | C17: minutes | D17: Measured | E17: Group: 10–14 min
A18: Restock when the food is already made: sending only (high) | B18: 14 | C18: minutes | D18: Measured | E18: Group: 10–14 min
A19: Chance the next batch is already made when the mess calls | B19: 0.5 | C19: share | D19: Assumed | E19: Simulator default; ask CT how often food is cooked ahead
A20: Delay faced by students (observed) | B20: 15 | C20: minutes | D20: Measured | E20: Phase 1 deck: ~15 min
A21: ASSUMED (replace with measurements)
A22: Share who go to Central CT by habit | B22: 0.85 | C22: fraction | D22: Assumed | E22: Pure assumption (group's estimate). A day of biometric logs without screens will measure it
A23: Service rate per serving station | B23: 10 | C23: students/min | D23: Assumed | E23: ≈6 s per student. Must be about this fast: 2 stations serve ~2,500 Central students in 3 hours. Stopwatch it
A24: Time for one face scan | B24: 2 | C24: seconds | D24: Assumed | E24: Step up, recognise, move on. Stopwatch it
A25: Eating time after being served | B25: 17 | C25: minutes | D25: Derived | E25: Calibrated so a normal visit ≈ 18 min (simulator)
A26: Walk between the two mess doors | B26: 0.5 | C26: minutes | D26: Assumed | E26: 30 s; time it
A27: Share of students who follow the screen | B27: 0.6 | C27: fraction | D27: Assumed | E27: Pilot will measure
A28: POLICY SETTINGS (our choice)
A29: Target maximum utilisation per station | B29: 0.85 | C29: fraction | D29: Policy | E29: Above ~85% waits rise steeply (see S15 Queuing)
A30: Minimum saving before suggesting a switch | B30: 2 | C30: minutes | D30: Policy | E30: Prototype setting
A31: MONEY VALUES — used ONLY in 'S7 Decision Tree' and 'S12-14 IP Staffing' (see the note below)
A32: Value of one student-minute of waiting | B32: 5 | C32: ₹ per student-min | D32: Illustrative | E32: Used in S7 Decision Tree to compare students' time with wasted food. A value judgement, not a price
A33: Cost of one portion wasted | B33: 30 | C33: ₹ per portion | D33: Illustrative | E33: Used in S7 Decision Tree. Ask CT for food cost per portion
A34: Staff cost per staff-hour | B34: 150 | C34: ₹ per hour | D34: Illustrative | E34: Used in S12-14 IP Staffing. Ask CT
A35: Staff needed per serving station | B35: 2 | C35: staff | D35: Assumed | E35: Used in S12-14 IP Staffing. Observe
A36: Derived capacity
A37: Capacity: Central CT (lines × service rate) | B37: =B11*B23 -> 20 | C37: students/min
A38: Capacity: Munch Mess (lines × service rate) | B38: =B12*B23 -> 20 | C38: students/min
A39: Max arrivals seats can absorb: Central (Little's Law N/W) | B39: =Inputs!$B$9/Inputs!$B$15 -> 50 | C39: students/min
A40: Max arrivals seats can absorb: Munch (Little's Law N/W) | B40: =Inputs!$B$10/Inputs!$B$15 -> 27.777778 | C40: students/min
A41: Scanner capacity: Central (scanners × 60 ÷ seconds per scan) | B41: =Inputs!$B$13*60/Inputs!$B$24 -> 30 | C41: students/min
...

Sheet S2-3 Problem & Root Cause
A1: Problem definition, decision context and root causes
A2: Sessions 2–3: Nature of business decisions · Problem identification, structuring, root cause analysis
A4: Problem statement
A5: During the 11:30–14:30 lunch window, Chefs Touch serves about 2,960 plates. Demand is concentrated while kitchen, delivery and serving capacity are fixed, so students wait (~15 min observed), star dishes run out mid-service and replenishment arrives during the peak. Decision question: are resources (food, serving lines, students' choice of mess) reaching the right centre, in the right quantity, at the right time?
A7: Session 2: nature of the decision
A8: Dimension | B8: Classification | C8: Why
A9: Level | B9: Operational | C9: Made every lunch, at centre and kitchen level
A10: Structure | B10: Structured / programmable | C10: Same choice repeats daily; inputs can be measured (scans, stock, lines)
A11: Certainty | B11: Under risk / uncertainty | C11: Daily demand varies; probabilities can be estimated from biometric logs
A12: Frequency | B12: Recurring (daily, 5 centres) | C12: Justifies building a model instead of ad-hoc judgement
A13: Decision makers | B13: CT operations, centre teams, students | C13: Students' choice of mess is itself a decision we can influence
A15: Session 3: 5 Whys
A16: Why? | B16: Answer | C16: Evidence
A17: 1. Why do students wait ~15 min? | B17: The serving line runs at or above capacity at peak | C17: Phase 1 deck; field notes O5, O15
A18: 2. Why is it above capacity? | B18: Arrivals cluster at peak times, and service stops when a dish runs out | C18: Run-outs 13:20–13:23 (O4, O10); timing of arrivals to be confirmed by logs
A19: 3. Why do dishes run out? | B19: Replenishment is triggered when stock is already low | C19: Top-up arrives inside the peak (O2, O7)
A20: 4. Why is it triggered late? | B20: The mess only calls the kitchen when the dish is running low; if it has to be made, the refill takes 30 min in total (10–14 min if already made) | C20: Phase 1 deck
A21: 5. Why is there no early warning? | B21: Entry data (biometric scans) is not used for operations | C21: Root cause → our project
A23: Session 3: fishbone (cause-and-effect) for 'long wait at lunch'
A24: People | B24: Process | C24: Policy | D24: Information | E24: Logistics / place
A25: Students arrive together at peak | B25: 2 serving stations and 1 face scanner per hall | C25: Replenishment is reactive | D25: No live view of demand | E25: Delivery shares the student walkway (O3, O8)
A26: Habit: same mess every day | B26: Refilling at the counter stops the line (O14) | C26: Base foods under-buffered (O13) | D26: Published menu ≠ served menu | E26: Return station/waste point unmeasured (O19)
A27: Students queue for dishes already gone (O11) | B27: Serving rate not measured | C27: No reorder point | D27: No per-centre forecast | E27: One kitchen supplies five centres
A29: Issue tree (problem structuring)
A30: Branch | B30: Sub-question | C30: Tool in this workbook
A31: Demand side | B31: When and where do students arrive? | C31: S15 Queuing (λ per 10 min)
A32: Capacity side | B32: How many lines, how fast? | C32: S15 Queuing, S12-14 IP Staffing
A33: Allocation | B33: How much of each dish to each centre? | C33: S10-11 LP Allocation, S5-6 Priority Matrix
A34: Timing | B34: When to replenish? | C34: S7 Decision Tree, S18 Heuristics (reorder point)
A35: Choice of intervention | B35: Which option is best overall? | C35: S7 Payoff Matrix, S16-17 AHP / BWM
A36: Cause structure | B36: Which causes drive the others? | C36: S16-17 ISM-MICMAC

Sheet S4 Biases & Ethics
A1: Decision biases and ethical decision making
A2: Session 4: Decision-making frameworks, decision biases, ethical decision making
A4: Bias | B4: Where it shows up in the mess problem | C4: How the project counters it
A5: Status quo / habit | B5: Students go to the same mess daily even when the other is faster | C5: Door screens set a default ('Recommended'), show concrete gains, fresh-batch cues
A6: Herding | B6: If everyone follows one signal, the 'empty' mess becomes the busy one | C6: Equilibrium split + 2-minute minimum saving; soft vs strong messages
A7: Anchoring | B7: Kitchen plans from the published menu; served menu differed on the day | C7: Record the actual menu; forecast from observed arrivals, not the plan
A8: Availability | B8: Managers remember the worst day and over-react | C8: Use logged data (distribution of days) and EMV, not memorable events
A9: Confirmation | B9: Our team wants the screens to look good | C9: Report simulated vs measured separately; A/B test with screens on/off
A10: Overconfidence | B10: Point estimates of waits shown as exact | C10: Show '~' and ranges; explain estimates come from scans
A12: Ethics checklist
A13: Principle | B13: What we do | C13: Status
A14: Data minimisation (DPDP Act 2023) | B14: Request only scan time + mess; no face data or templates | C14: Built into data request
A15: Pseudonymisation | B15: IDs hashed on reading; names hidden by default | C15: Built into prototype
A16: Purpose limitation & retention | B16: Use for this project only; delete at semester end | C16: Committed in email
A17: Honesty to students | B17: Never suggest switching unless it saves ≥ 2 min; stale kitchen taps expire | C17: Built into prototype
A18: Consent / approval | B18: Written approval from college and vendor before any live connection | C18: Pending
A19: Fairness | B19: Advice is the same for everyone; no priority for any group | C19: Built into prototype

Sheet S5-6 Priority Matrix
A1: Decision dilemma and priority matrices
A2: Sessions 5–6: Decision dilemma and project priority matrix
A4: 1. Menu criticality × predictability (ABC/XYZ) — from our CT Priority Matrix workbook, menu week 31 Aug–6 Sep
A5: Policy | B5: Class | C5: Menu entries | D5: Share | E5: What to do
A6: Tight Control | B6: AZ | C6: 20 | D6: =C6/$C$10 -> 0.19417476 | E6: Measure and model (chapattis, star dishes)
A7: Calculated Issue | B7: AX | C7: 16 | D7: =C7/$C$10 -> 0.15533981 | E7: Derive from plate count (curd, raitha, sweets)
A8: Buffered Issue | B8: CZ | C8: 40 | D8: =C8/$C$10 -> 0.38834951 | E8: Issue with a safety margin (rice, dal, sambar)
A9: Free Issue | B9: CX | C9: 27 | D9: =C9/$C$10 -> 0.26213592 | E9: Issue without control (pickle, salt, sugar)
A10: Total | C10: =SUM(C6:C9) -> 103 | D10: =SUM(D6:D9) -> 1
A12: 2. Intervention priority matrix (impact vs effort). Scores 1–5 are illustrative: agree them as a group.
A13: Quadrant threshold (score above this = high) | C13: 3
A15: Intervention | B15: Impact (1–5) | C15: Effort (1–5) | D15: Quadrant | E15: Reason (impact) | F15: Reason (effort)
A16: A2 Door screens + routing | B16: 4 | C16: 3 | D16: =IF(B16>$C$13,IF(C16>$C$13,"Major project","Quick win"),IF(C16>$C$13,"Thankless task","Fill-in")) -> Quick win | E16: Spreads students; ~halves waits in simulation | F16: Two screens + a laptop; needs data access
A17: A3 Screens + kitchen early alerts | B17: 5 | C17: 3 | D17: =IF(B17>$C$13,IF(C17>$C$13,"Major project","Quick win"),IF(C17>$C$13,"Thankless task","Fill-in")) -> Quick win | E17: Also attacks stock-outs (root cause) | F17: Same as A2 + kitchen page habit
A18: A4 3rd serving station at peak | B18: 4 | C18: 4 | D18: =IF(B18>$C$13,IF(C18>$C$13,"Major project","Quick win"),IF(C18>$C$13,"Thankless task","Fill-in")) -> Major project | E18: Raises capacity directly | F18: Recurring staff cost; space at counter
A19: A6 Larger buffers for base foods (CZ) | B19: 3 | C19: 1 | D19: =IF(B19>$C$13,IF(C19>$C$13,"Major project","Quick win"),IF(C19>$C$13,"Thankless task","Fill-in")) -> Fill-in | E19: Base foods ran dry (O13) | F19: Just send more rice/dal/sambar
A20: A7 Stagger class end times | B20: 4 | C20: 5 | D20: =IF(B20>$C$13,IF(C20>$C$13,"Major project","Quick win"),IF(C20>$C$13,"Thankless task","Fill-in")) -> Major project | E20: Lowers peak arrivals | F20: Needs academic administration
A21: A8 Separate counter for one-per-plate items | B21: 2 | C21: 2 | D21: =IF(B21>$C$13,IF(C21>$C$13,"Major project","Quick win"),IF(C21>$C$13,"Thankless task","Fill-in")) -> Fill-in | E21: Shortens main line slightly | F21: Small layout change
A23: 3. Decision dilemma
A24: Dilemma | B24: Option 1 | C24: Option 2 | E24: Trade-off | F24: How we resolve it
A25: Send more food early? | B25: Pre-stage (risk waste) | C25: Wait and react (risk run-out) | E25: Waste ₹ vs students' time | F25: S7 Decision Tree: break-even probability
A26: Send students to the other mess? | B26: Strong advice (risk herding) | C26: No advice (uneven load) | E26: Balance vs trust | F26: Equilibrium split + 2-min threshold (S18)
A27: Add a serving station? | B27: Yes (cost every day) | C27: No (long peak waits) | E27: Staff cost vs waiting | F27: S12-14 IP Staffing; S7 Payoff Matrix

Sheet S15 Queuing
A1: Queuing analysis: M/M/1, M/M/c and lunch-peak overload, without vs with the screens
A2: Session 15: Introduction to queuing theory and waiting-line models
A4: 1. Check against the lecture example (Hatti Kaapi, M/M/1) | J4: 2. Why waits explode near 100% busy (M/M/1, one serving station)
A5: λ /hour | B5: μ /hour | C5: ρ | D5: Wq (hours) | E5: Wq (min) | F5: W (min) | G5: Lq | H5: L | J5: μ per hour | K5: =Inputs!$B$23*60 -> 600
A6: 18 | B6: 24 | C6: =A6/B6 -> 0.75 | D6: =A6/(B6*(B6-A6)) -> 0.125 | E6: =D6*60 -> 7.5 | F6: =60/(B6-A6) -> 10 | G6: =A6*D6 -> 2.25 | H6: =A6*F6/60 -> 3 | J6: ρ | K6: λ /hour | L6: Wq (min) | M6: Lq
A7: Lecture answers: ρ = 75%, Wq = 7.5 min, W = 10 min, Lq = 2.25. If these match, the formulas below are right. | J7: 0.5 | K7: =J7*$K$5 -> 300 | L7: =K7/($K$5*($K$5-K7))*60 -> 0.1 | M7: =K7*L7/60 -> 0.5
J8: 0.6 | K8: =J8*$K$5 -> 360 | L8: =K8/($K$5*($K$5-K8))*60 -> 0.15 | M8: =K8*L8/60 -> 0.9
J9: 0.7 | K9: =J9*$K$5 -> 420 | L9: =K9/($K$5*($K$5-K9))*60 -> 0.23333333 | M9: =K9*L9/60 -> 1.6333333
J10: 0.75 | K10: =J10*$K$5 -> 450 | L10: =K10/($K$5*($K$5-K10))*60 -> 0.3 | M10: =K10*L10/60 -> 2.25
J11: 0.8 | K11: =J11*$K$5 -> 480 | L11: =K11/($K$5*($K$5-K11))*60 -> 0.4 | M11: =K11*L11/60 -> 3.2
J12: 0.85 | K12: =J12*$K$5 -> 510 | L12: =K12/($K$5*($K$5-K12))*60 -> 0.56666667 | M12: =K12*L12/60 -> 4.8166667
J13: 0.9 | K13: =J13*$K$5 -> 540 | L13: =K13/($K$5*($K$5-K13))*60 -> 0.9 | M13: =K13*L13/60 -> 8.1
J14: 0.93 | K14: =J14*$K$5 -> 558 | L14: =K14/($K$5*($K$5-K14))*60 -> 1.3285714 | M14: =K14*L14/60 -> 12.355714
J15: 0.95 | K15: =J15*$K$5 -> 570 | L15: =K15/($K$5*($K$5-K15))*60 -> 1.9 | M15: =K15*L15/60 -> 18.05
J16: 0.96 | K16: =J16*$K$5 -> 576 | L16: =K16/($K$5*($K$5-K16))*60 -> 2.4 | M16: =K16*L16/60 -> 23.04
J17: 0.97 | K17: =J17*$K$5 -> 582 | L17: =K17/($K$5*($K$5-K17))*60 -> 3.2333333 | M17: =K17*L17/60 -> 31.363333
J18: 0.98 | K18: =J18*$K$5 -> 588 | L18: =K18/($K$5*($K$5-K18))*60 -> 4.9 | M18: =K18*L18/60 -> 48.02
A22: 3. Lunch peak by 10-minute bin: without vs with the door screens (M/M/c + overload)
A23: Blue column B = arrivals per 10 min at both messes together, 11:30–14:30. ILLUSTRATIVE: 2,960 students (measured total) on an assumed bell-shaped curve. Replace them with counts from the biometric logs. 'With screens' moves students from the busier mess toward equal utilisation; only the share who comply move. When ρ ≥ 1 the steady-state formula does not apply, so the queue is carried forward (fluid model): backlog = max(0, previous + arrivals − capacity).
A25: Equal-utilisation share for Central | E25: =Inputs!$B$37/(Inputs!$B$37+Inputs!$B$38) -> 0.5 | F25: Formula: capacity of Central ÷ (capacity of Central + capacity of Munch)
A26: Realised share for Central with screens | E26: =Inputs!$B$22+Inputs!$B$27*(E25-Inputs!$B$22) -> 0.64 | F26: Formula: habit + compliance × (target − habit). Only students who follow the screen move
D28: Without screens — Central CT | L28: Without screens — Munch | T28: With screens — Central CT | AB28: With screens — Munch
A29: Bin start | B29: Arrivals (both messes) | C29: λ total /min | D29: λ /min | E29: Scanner ρ | F29: ρ | G29: P(wait) | H29: Wq steady (min) | I29: Backlog end | J29: Est. wait (min) | K29: People inside | L29: λ /min | M29: Scanner ρ | N29: ρ | O29: P(wait) | P29: Wq steady (min) | Q29: Backlog end | R29: Est. wait (min) | S29: People inside | T29: λ /min | U29: Scanner ρ | V29: ρ | W29: P(wait) | X29: Wq steady (min) | Y29: Backlog end | Z29: Est. wait (min) | AA29: People inside | AB29: λ /min | AC29: Scanner ρ | AD29: ρ | AE29: P(wait) | AF29: Wq steady (min) | AG29: Backlog end | AH29: Est. wait (min) | AI29: People inside
A30: 11:30 | B30: 13 | C30: =B30/10 -> 1.3 | D30: =$C30*Inputs!$B$22 -> 1.105 | E30: =D30/Inputs!$B$41 -> 0.036833333 | F30: =D30/(Inputs!$B$11*Inputs!$B$23) -> 0.05525 | G30: =IF(F30<1,((D30/Inputs!$B$23)^Inputs!$B$11/FACT(Inputs!$B$11)*Inputs!$B$11/(Inputs!$B$11-(D30/Inputs!$B$23)))/(SUMPRODUCT(--({0,1,2,3,4,5,6,7,8,9}<Inputs!$B$11),(D30/Inputs!$B$23)^{0,1,2,3,4,5,6,7,8,9}/FACT({0,1,2,3,4,5,6,7,8,9}))+((D30/Inputs!$B$23)^Inputs!$B$11/FACT(Inputs!$B$11)*Inputs!$B$11/(Inputs!$B$11-(D30/Inputs!$B$23)))),1) -> 0.0057854774 | H30: =IF(F30<1,G30/(Inputs!$B$11*Inputs!$B$23-D30),0) -> 0.00030619092 | I30: =MAX(0,0+(D30-Inputs!$B$11*Inputs!$B$23)*10) -> 0 | J30: =I30/(Inputs!$B$11*Inputs!$B$23)+H30 -> 0.00030619092 | K30: =D30*(J30+1/Inputs!$B$23+Inputs!$B$25) -> 18.895838 | L30: =$C30*(1-Inputs!$B$22) -> 0.195 | M30: =L30/Inputs!$B$42 -> 0.0065 | N30: =L30/(Inputs!$B$12*Inputs!$B$23) -> 0.00975 | O30: =IF(N30<1,((L30/Inputs!$B$23)^Inputs!$B$12/FACT(Inputs!$B$12)*Inputs!$B$12/(Inputs!$B$12-(L30/Inputs!$B$23)))/(SUMPRODUCT(--({0,1,2,3,4,5,6,7,8,9}<Inputs!$B$12),(L30/Inputs!$B$23)^{0,1,2,3,4,5,6,7,8,9}/FACT({0,1,2,3,4,5,6,7,8,9}))+((L30/Inputs!$B$23)^Inputs!$B$12/FACT(Inputs!$B$12)*Inputs!$B$12/(Inputs!$B$12-(L30/Inputs!$B$23)))),1) -> 0.00018828918 | P30: =IF(N30<1,O30/(Inputs!$B$12*Inputs!$B$23-L30),0) -> 9.5071538e-06 | Q30: =MAX(0,0+(L30-Inputs!$B$12*Inputs!$B$23)*10) -> 0 | R30: =Q30/(Inputs!$B$12*Inputs!$B$23)+P30 -> 9.5071538e-06 | S30: =L30*(R30+1/Inputs!$B$23+Inputs!$B$25) -> 3.3345019 | T30: =$C30*$E$26 -> 0.832 | U30: =T30/Inputs!$B$41 -> 0.027733333 | V30: =T30/(Inputs!$B$11*Inputs!$B$23) -> 0.0416 | W30: =IF(V30<1,((T30/Inputs!$B$23)^Inputs!$B$11/FACT(Inputs!$B$11)*Inputs!$B$11/(Inputs!$B$11-(T30/Inputs!$B$23)))/(SUMPRODUCT(--({0,1,2,3,4,5,6,7,8,9}<Inputs!$B$11),(T30/Inputs!$B$23)^{0,1,2,3,4,5,6,7,8,9}/FACT({0,1,2,3,4,5,6,7,8,9}))+((T30/Inputs!$B$23)^Inputs!$B$11/FACT(Inputs!$B$11)*Inputs!$B$11/(Inputs!$B$11-(T30/Inputs!$B$23)))),1) -> 0.0033228879 | X30: =IF(V30<1,W30/(Inputs!$B$11*Inputs!$B$23-T30),0) -> 0.000173356 | Y30: =MAX(0,0+(T30-Inputs!$B$11*Inputs!$B$23)*10) -> 0 | Z30: =Y30/(Inputs!$B$11*Inputs!$B$23)+X30 -> 0.000173356 | AA30: =T30*(Z30+1/Inputs!$B$23+Inputs!$B$25) -> 14.227344 | AB30: =$C30*(1-$E$26) -> 0.468 | AC30: =AB30/Inputs!$B$42 -> 0.0156 | AD30: =AB30/(Inputs!$B$12*Inputs!$B$23) -> 0.0234 | AE30: =IF(AD30<1,((AB30/Inputs!$B$23)^Inputs!$B$12/FACT(Inputs!$B$12)*Inputs!$B$12/(Inputs!$B$12-(AB30/Inputs!$B$23)))/(SUMPRODUCT(--({0,1,2,3,4,5,6,7,8,9}<Inputs!$B$12),(AB30/Inputs!$B$23)^{0,1,2,3,4,5,6,7,8,9}/FACT({0,1,2,3,4,5,6,7,8,9}))+((AB30/Inputs!$B$23)^Inputs!$B$12/FACT(Inputs!$B$12)*Inputs!$B$12/(Inputs!$B$12-(AB30/Inputs!$B$23)))),1) -> 0.0010700801 | AF30: =IF(AD30<1,AE30/(Inputs!$B$12*Inputs!$B$23-AB30),0) -> 5.4785999e-05 | AG30: =MAX(0,0+(AB30-Inputs!$B$12*Inputs!$B$23)*10) -> 0 | AH30: =AG30/(Inputs!$B$12*Inputs!$B$23)+AF30 -> 5.4785999e-05 | AI30: =AB30*(AH30+1/Inputs!$B$23+Inputs!$B$25) -> 8.0028256
A31: 11:40 | B31: 25 | C31: =B31/10 -> 2.5 | D31: =$C31*Inputs!$B$22 -> 2.125 | E31: =D31/Inputs!$B$41 -> 0.070833333 | F31: =D31/(Inputs!$B$11*Inputs!$B$23) -> 0.10625 | G31: =IF(F31<1,((D31/Inputs!$B$23)^Inputs!$B$11/FACT(Inputs!$B$11)*Inputs!$B$11/(Inputs!$B$11-(D31/Inputs!$B$23)))/(SUMPRODUCT(--({0,1,2,3,4,5,6,7,8,9}<Inputs!$B$11),(D31/Inputs!$B$23)^{0,1,2,3,4,5,6,7,8,9}/FACT({0,1,2,3,4,5,6,7,8,9}))+((D31/Inputs!$B$23)^Inputs!$B$11/FACT(Inputs!$B$11)*Inputs!$B$11/(Inputs!$B$11-(D31/Inputs!$B$23)))),1) -> 0.020409605 | H31: =IF(F31<1,G31/(Inputs!$B$11*Inputs!$B$23-D31),0) -> 0.0011417961 | I31: =MAX(0,I30+(D31-Inputs!$B$11*Inputs!$B$23)*10) -> 0 | J31: =I31/(Inputs!$B$11*Inputs!$B$23)+H31 -> 0.0011417961 | K31: =D31*(J31+1/Inputs!$B$23+Inputs!$B$25) -> 36.339926 | L31: =$C31*(1-Inputs!$B$22) -> 0.375 | M31: =L31/Inputs!$B$42 -> 0.0125 | N31: =L31/(Inputs!$B$12*Inputs!$B$23) -> 0.01875 | O31: =IF(N31<1,((L31/Inputs!$B$23)^Inputs!$B$12/FACT(Inputs!$B$12)*Inputs!$B$12/(Inputs!$B$12-(L31/Inputs!$B$23)))/(SUMPRODUCT(--({0,1,2,3,4,5,6,7,8,9}<Inputs!$B$12),(L31/Inputs!$B$23)^{0,1,2,3,4,5,6,7,8,9}/FACT({0,1,2,3,4,5,6,7,8,9}))+((L31/Inputs!$B$23)^Inputs!$B$12/FACT(Inputs!$B$12)*Inputs!$B$12/(Inputs!$B$12-(L31/Inputs!$B$23)))),1) -> 0.00069018405 | P31: =IF(N31<1,O31/(Inputs!$B$12*Inputs!$B$23-L31),0) -> 3.5168614e-05 | Q31: =MAX(0,Q30+(L31-Inputs!$B$12*Inputs!$B$23)*10) -> 0 | R31: =Q31/(Inputs!$B$12*Inputs!$B$23)+P31 -> 3.5168614e-05 | S31: =L31*(R31+1/Inputs!$B$23+Inputs!$B$25) -> 6.4125132 | T31: =$C31*$E$26 -> 1.6 | U31: =T31/Inputs!$B$41 -> 0.053333333 | V31: =T31/(Inputs!$B$11*Inputs!$B$23) -> 0.08 | W31: =IF(V31<1,((T31/Inputs!$B$23)^Inputs!$B$11/FACT(Inputs!$B$11)*Inputs!$B$11/(Inputs!$B$11-(T31/Inputs!$B$23)))/(SUMPRODUCT(--({0,1,2,3,4,5,6,7,8,9}<Inputs!$B$11),(T31/Inputs!$B$23)^{0,1,2,3,4,5,6,7,8,9}/FACT({0,1,2,3,4,5,6,7,8,9}))+((T31/Inputs!$B$23)^Inputs!$B$11/FACT(Inputs!$B$11)*Inputs!$B$11/(Inputs!$B$11-(T31/Inputs!$B$23)))),1) -> 0.011851852 | X31: =IF(V31<1,W31/(Inputs!$B$11*Inputs!$B$23-T31),0) -> 0.00064412238 | Y31: =MAX(0,Y30+(T31-Inputs!$B$11*Inputs!$B$23)*10) -> 0 | Z31: =Y31/(Inputs!$B$11*Inputs!$B$23)+X31 -> 0.00064412238 | AA31: =T31*(Z31+1/Inputs!$B$23+Inputs!$B$25) -> 27.361031 | AB31: =$C31*(1-$E$26) -> 0.9 | AC31: =AB31/Inputs!$B$42 -> 0.03 | AD31: =AB31/(Inputs!$B$12*Inputs!$B$23) -> 0.045 | AE31: =IF(AD31<1,((AB31/Inputs!$B$23)^Inputs!$B$12/FACT(Inputs!$B$12)*Inputs!$B$12/(Inputs!$B$12-(AB31/Inputs!$B$23)))/(SUMPRODUCT(--({0,1,2,3,4,5,6,7,8,9}<Inputs!$B$12),(AB31/Inputs!$B$23)^{0,1,2,3,4,5,6,7,8,9}/FACT({0,1,2,3,4,5,6,7,8,9}))+((AB31/Inputs!$B$23)^Inputs!$B$12/FACT(Inputs!$B$12)*Inputs!$B$12/(Inputs!$B$12-(AB31/Inputs!$B$23)))),1) -> 0.0038755981 | AF31: =IF(AD31<1,AE31/(Inputs!$B$12*Inputs!$B$23-AB31),0) -> 0.00020291089 | AG31: =MAX(0,AG30+(AB31-Inputs!$B$12*Inputs!$B$23)*10) -> 0 | AH31: =AG31/(Inputs!$B$12*Inputs!$B$23)+AF31 -> 0.00020291089 | AI31: =AB31*(AH31+1/Inputs!$B$23+Inputs!$B$25) -> 15.390183
A32: 11:50 | B32: 47 | C32: =B32/10 -> 4.7 | D32: =$C32*Inputs!$B$22 -> 3.995 | E32: =D32/Inputs!$B$41 -> 0.13316667 | F32: =D32/(Inputs!$B$11*Inputs!$B$23) -> 0.19975 | G32: =IF(F32<1,((D32/Inputs!$B$23)^Inputs!$B$11/FACT(Inputs!$B$11)*Inputs!$B$11/(Inputs!$B$11-(D32/Inputs!$B$23)))/(SUMPRODUCT(--({0,1,2,3,4,5,6,7,8,9}<Inputs!$B$11),(D32/Inputs!$B$23)^{0,1,2,3,4,5,6,7,8,9}/FACT({0,1,2,3,4,5,6,7,8,9}))+((D32/Inputs!$B$23)^Inputs!$B$11/FACT(Inputs!$B$11)*Inputs!$B$11/(Inputs!$B$11-(D32/Inputs!$B$23)))),1) -> 0.066513961 | H32: =IF(F32<1,G32/(Inputs!$B$11*Inputs!$B$23-D32),0) -> 0.0041558239 | I32: =MAX(0,I31+(D32-Inputs!$B$11*Inputs!$B$23)*10) -> 0 | J32: =I32/(Inputs!$B$11*Inputs!$B$23)+H32 -> 0.0041558239 | K32: =D32*(J32+1/Inputs!$B$23+Inputs!$B$25) -> 68.331103 | L32: =$C32*(1-Inputs!$B$22) -> 0.705 | M32: =L32/Inputs!$B$42 -> 0.0235 | N32: =L32/(Inputs!$B$12*Inputs!$B$23) -> 0.03525 | O32: =IF(N32<1,((L32/Inputs!$B$23)^Inputs!$B$12/FACT(Inputs!$B$12)*Inputs!$B$12/(Inputs!$B$12-(L32/Inputs!$B$23)))/(SUMPRODUCT(--({0,1,2,3,4,5,6,7,8,9}<Inputs!$B$12),(L32/Inputs!$B$23)^{0,1,2,3,4,5,6,7,8,9}/FACT({0,1,2,3,4,5,6,7,8,9}))+((L32/Inputs!$B$23)^Inputs!$B$12/FACT(Inputs!$B$12)*Inputs!$B$12/(Inputs!$B$12-(L32/Inputs!$B$23)))),1) -> 0.0024005071 | P32: =IF(N32<1,O32/(Inputs!$B$12*Inputs!$B$23-L32),0) -> 0.00012441084 | Q32: =MAX(0,Q31+(L32-Inputs!$B$12*Inputs!$B$23)*10) -> 0 | R32: =Q32/(Inputs!$B$12*Inputs!$B$23)+P32 -> 0.00012441084 | S32: =L32*(R32+1/Inputs!$B$23+Inputs!$B$25) -> 12.055588 | T32: =$C32*$E$26 -> 3.008 | U32: =T32/Inputs!$B$41 -> 0.10026667 | V32: =T32/(Inputs!$B$11*Inputs!$B$23) -> 0.1504 | W32: =IF(V32<1,((T32/Inputs!$B$23)^Inputs!$B$11/FACT(Inputs!$B$11)*Inputs!$B$11/(Inputs!$B$11-(T32/Inputs!$B$23)))/(SUMPRODUCT(--({0,1,2,3,4,5,6,7,8,9}<Inputs!$B$11),(T32/Inputs!$B$23)^{0,1,2,3,4,5,6,7,8,9}/FACT({0,1,2,3,4,5,6,7,8,9}))+((T32/Inputs!$B$23)^Inputs!$B$11/FACT(Inputs!$B$11)*Inputs!$B$11/(Inputs!$B$11-(T32/Inputs!$B$23)))),1) -> 0.03932573 | X32: =IF(V32<1,W32/(Inputs!$B$11*Inputs!$B$23-T32),0) -> 0.0023143674 | Y32: =MAX(0,Y31+(T32-Inputs!$B$11*Inputs!$B$23)*10) -> 0 | Z32: =Y32/(Inputs!$B$11*Inputs!$B$23)+X32 -> 0.0023143674 | AA32: =T32*(Z32+1/Inputs!$B$23+Inputs!$B$25) -> 51.443762 | AB32: =$C32*(1-$E$26) -> 1.692 | AC32: =AB32/Inputs!$B$42 -> 0.0564 | AD32: =AB32/(Inputs!$B$12*Inputs!$B$23) -> 0.0846 | AE32: =IF(AD32<1,((AB32/Inputs!$B$23)^Inputs!$B$12/FACT(Inputs!$B$12)*Inputs!$B$12/(Inputs!$B$12-(AB32/Inputs!$B$23)))/(SUMPRODUCT(--({0,1,2,3,4,5,6,7,8,9}<Inputs!$B$12),(AB32/Inputs!$B$23)^{0,1,2,3,4,5,6,7,8,9}/FACT({0,1,2,3,4,5,6,7,8,9}))+((AB32/Inputs!$B$23)^Inputs!$B$12/FACT(Inputs!$B$12)*Inputs!$B$12/(Inputs!$B$12-(AB32/Inputs!$B$23)))),1) -> 0.013197787 | AF32: =IF(AD32<1,AE32/(Inputs!$B$12*Inputs!$B$23-AB32),0) -> 0.00072087542 | AG32: =MAX(0,AG31+(AB32-Inputs!$B$12*Inputs!$B$23)*10) -> 0 | AH32: =AG32/(Inputs!$B$12*Inputs!$B$23)+AF32 -> 0.00072087542 | AI32: =AB32*(AH32+1/Inputs!$B$23+Inputs!$B$25) -> 28.93442
A33: 12:00 | B33: 79 | C33: =B33/10 -> 7.9 | D33: =$C33*Inputs!$B$22 -> 6.715 | E33: =D33/Inputs!$B$41 -> 0.22383333 | F33: =D33/(Inputs!$B$11*Inputs!$B$23) -> 0.33575 | G33: =IF(F33<1,((D33/Inputs!$B$23)^Inputs!$B$11/FACT(Inputs!$B$11)*Inputs!$B$11/(Inputs!$B$11-(D33/Inputs!$B$23)))/(SUMPRODUCT(--({0,1,2,3,4,5,6,7,8,9}<Inputs!$B$11),(D33/Inputs!$B$23)^{0,1,2,3,4,5,6,7,8,9}/FACT({0,1,2,3,4,5,6,7,8,9}))+((D33/Inputs!$B$23)^Inputs!$B$11/FACT(Inputs!$B$11)*Inputs!$B$11/(Inputs!$B$11-(D33/Inputs!$B$23)))),1) -> 0.16878617 | H33: =IF(F33<1,G33/(Inputs!$B$11*Inputs!$B$23-D33),0) -> 0.012705018 | I33: =MAX(0,I32+(D33-Inputs!$B$11*Inputs!$B$23)*10) -> 0 | J33: =I33/(Inputs!$B$11*Inputs!$B$23)+H33 -> 0.012705018 | K33: =D33*(J33+1/Inputs!$B$23+Inputs!$B$25) -> 114.91181 | L33: =$C33*(1-Inputs!$B$22) -> 1.185 | M33: =L33/Inputs!$B$42 -> 0.0395 | N33: =L33/(Inputs!$B$12*Inputs!$B$23) -> 0.05925 | O33: =IF(N33<1,((L33/Inputs!$B$23)^Inputs!$B$12/FACT(Inputs!$B$12)*Inputs!$B$12/(Inputs!$B$12-(L33/Inputs!$B$23)))/(SUMPRODUCT(--({0,1,2,3,4,5,6,7,8,9}<Inputs!$B$12),(L33/Inputs!$B$23)^{0,1,2,3,4,5,6,7,8,9}/FACT({0,1,2,3,4,5,6,7,8,9}))+((L33/Inputs!$B$23)^Inputs!$B$12/FACT(Inputs!$B$12)*Inputs!$B$12/(Inputs!$B$12-(L33/Inputs!$B$23)))),1) -> 0.0066283927 | P33: =IF(N33<1,O33/(Inputs!$B$12*Inputs!$B$23-L33),0) -> 0.000352293 | Q33: =MAX(0,Q32+(L33-Inputs!$B$12*Inputs!$B$23)*10) -> 0 | R33: =Q33/(Inputs!$B$12*Inputs!$B$23)+P33 -> 0.000352293 | S33: =L33*(R33+1/Inputs!$B$23+Inputs!$B$25) -> 20.263917 | T33: =$C33*$E$26 -> 5.056 | U33: =T33/Inputs!$B$41 -> 0.16853333 | V33: =T33/(Inputs!$B$11*Inputs!$B$23) -> 0.2528 | W33: =IF(V33<1,((T33/Inputs!$B$23)^Inputs!$B$11/FACT(Inputs!$B$11)*Inputs!$B$11/(Inputs!$B$11-(T33/Inputs!$B$23)))/(SUMPRODUCT(--({0,1,2,3,4,5,6,7,8,9}<Inputs!$B$11),(T33/Inputs!$B$23)^{0,1,2,3,4,5,6,7,8,9}/FACT({0,1,2,3,4,5,6,7,8,9}))+((T33/Inputs!$B$23)^Inputs!$B$11/FACT(Inputs!$B$11)*Inputs!$B$11/(Inputs!$B$11-(T33/Inputs!$B$23)))),1) -> 0.10202401 | X33: =IF(V33<1,W33/(Inputs!$B$11*Inputs!$B$23-T33),0) -> 0.0068270885 | Y33: =MAX(0,Y32+(T33-Inputs!$B$11*Inputs!$B$23)*10) -> 0 | Z33: =Y33/(Inputs!$B$11*Inputs!$B$23)+X33 -> 0.0068270885 | AA33: =T33*(Z33+1/Inputs!$B$23+Inputs!$B$25) -> 86.492118 | AB33: =$C33*(1-$E$26) -> 2.844 | AC33: =AB33/Inputs!$B$42 -> 0.0948 | AD33: =AB33/(Inputs!$B$12*Inputs!$B$23) -> 0.1422 | AE33: =IF(AD33<1,((AB33/Inputs!$B$23)^Inputs!$B$12/FACT(Inputs!$B$12)*Inputs!$B$12/(Inputs!$B$12-(AB33/Inputs!$B$23)))/(SUMPRODUCT(--({0,1,2,3,4,5,6,7,8,9}<Inputs!$B$12),(AB33/Inputs!$B$23)^{0,1,2,3,4,5,6,7,8,9}/FACT({0,1,2,3,4,5,6,7,8,9}))+((AB33/Inputs!$B$23)^Inputs!$B$12/FACT(Inputs!$B$12)*Inputs!$B$12/(Inputs!$B$12-(AB33/Inputs!$B$23)))),1) -> 0.035406829 | AF33: =IF(AD33<1,AE33/(Inputs!$B$12*Inputs!$B$23-AB33),0) -> 0.0020638161 | AG33: =MAX(0,AG32+(AB33-Inputs!$B$12*Inputs!$B$23)*10) -> 0 | AH33: =AG33/(Inputs!$B$12*Inputs!$B$23)+AF33 -> 0.0020638161 | AI33: =AB33*(AH33+1/Inputs!$B$23+Inputs!$B$25) -> 48.638269
A34: 12:10 | B34: 123 | C34: =B34/10 -> 12.3 | D34: =$C34*Inputs!$B$22 -> 10.455 | E34: =D34/Inputs!$B$41 -> 0.3485 | F34: =D34/(Inputs!$B$11*Inputs!$B$23) -> 0.52275 | G34: =IF(F34<1,((D34/Inputs!$B$23)^Inputs!$B$11/FACT(Inputs!$B$11)*Inputs!$B$11/(Inputs!$B$11-(D34/Inputs!$B$23)))/(SUMPRODUCT(--({0,1,2,3,4,5,6,7,8,9}<Inputs!$B$11),(D34/Inputs!$B$23)^{0,1,2,3,4,5,6,7,8,9}/FACT({0,1,2,3,4,5,6,7,8,9}))+((D34/Inputs!$B$23)^Inputs!$B$11/FACT(Inputs!$B$11)*Inputs!$B$11/(Inputs!$B$11-(D34/Inputs!$B$23)))),1) -> 0.35891323 | H34: =IF(F34<1,G34/(Inputs!$B$11*Inputs!$B$23-D34),0) -> 0.037602224 | I34: =MAX(0,I33+(D34-Inputs!$B$11*Inputs!$B$23)*10) -> 0 | J34: =I34/(Inputs!$B$11*Inputs!$B$23)+H34 -> 0.037602224 | K34: =D34*(J34+1/Inputs!$B$23+Inputs!$B$25) -> 179.17363 | L34: =$C34*(1-Inputs!$B$22) -> 1.845 | M34: =L34/Inputs!$B$42 -> 0.0615 | N34: =L34/(Inputs!$B$12*Inputs!$B$23) -> 0.09225 | O34: =IF(N34<1,((L34/Inputs!$B$23)^Inputs!$B$12/FACT(Inputs!$B$12)*Inputs!$B$12/(Inputs!$B$12-(L34/Inputs!$B$23)))/(SUMPRODUCT(--({0,1,2,3,4,5,6,7,8,9}<Inputs!$B$12),(L34/Inputs!$B$23)^{0,1,2,3,4,5,6,7,8,9}/FACT({0,1,2,3,4,5,6,7,8,9}))+((L34/Inputs!$B$23)^Inputs!$B$12/FACT(Inputs!$B$12)*Inputs!$B$12/(Inputs!$B$12-(L34/Inputs!$B$23)))),1) -> 0.015582628 | P34: =IF(N34<1,O34/(Inputs!$B$12*Inputs!$B$23-L34),0) -> 0.00085831053 | Q34: =MAX(0,Q33+(L34-Inputs!$B$12*Inputs!$B$23)*10) -> 0 | R34: =Q34/(Inputs!$B$12*Inputs!$B$23)+P34 -> 0.00085831053 | S34: =L34*(R34+1/Inputs!$B$23+Inputs!$B$25) -> 31.551084 | T34: =$C34*$E$26 -> 7.872 | U34: =T34/Inputs!$B$41 -> 0.2624 | V34: =T34/(Inputs!$B$11*Inputs!$B$23) -> 0.3936 | W34: =IF(V34<1,((T34/Inputs!$B$23)^Inputs!$B$11/FACT(Inputs!$B$11)*Inputs!$B$11/(Inputs!$B$11-(T34/Inputs!$B$23)))/(SUMPRODUCT(--({0,1,2,3,4,5,6,7,8,9}<Inputs!$B$11),(T34/Inputs!$B$23)^{0,1,2,3,4,5,6,7,8,9}/FACT({0,1,2,3,4,5,6,7,8,9}))+((T34/Inputs!$B$23)^Inputs!$B$11/FACT(Inputs!$B$11)*Inputs!$B$11/(Inputs!$B$11-(T34/Inputs!$B$23)))),1) -> 0.22233203 | X34: =IF(V34<1,W34/(Inputs!$B$11*Inputs!$B$23-T34),0) -> 0.018332127 | Y34: =MAX(0,Y33+(T34-Inputs!$B$11*Inputs!$B$23)*10) -> 0 | Z34: =Y34/(Inputs!$B$11*Inputs!$B$23)+X34 -> 0.018332127 | AA34: =T34*(Z34+1/Inputs!$B$23+Inputs!$B$25) -> 134.75551 | AB34: =$C34*(1-$E$26) -> 4.428 | AC34: =AB34/Inputs!$B$42 -> 0.1476 | AD34: =AB34/(Inputs!$B$12*Inputs!$B$23) -> 0.2214 | AE34: =IF(AD34<1,((AB34/Inputs!$B$23)^Inputs!$B$12/FACT(Inputs!$B$12)*Inputs!$B$12/(Inputs!$B$12-(AB34/Inputs!$B$23)))/(SUMPRODUCT(--({0,1,2,3,4,5,6,7,8,9}<Inputs!$B$12),(AB34/Inputs!$B$23)^{0,1,2,3,4,5,6,7,8,9}/FACT({0,1,2,3,4,5,6,7,8,9}))+((AB34/Inputs!$B$23)^Inputs!$B$12/FACT(Inputs!$B$12)*Inputs!$B$12/(Inputs!$B$12-(AB34/Inputs!$B$23)))),1) -> 0.080265204 | AF34: =IF(AD34<1,AE34/(Inputs!$B$12*Inputs!$B$23-AB34),0) -> 0.005154457 | AG34: =MAX(0,AG33+(AB34-Inputs!$B$12*Inputs!$B$23)*10) -> 0 | AH34: =AG34/(Inputs!$B$12*Inputs!$B$23)+AF34 -> 0.005154457 | AI34: =AB34*(AH34+1/Inputs!$B$23+Inputs!$B$25) -> 75.741624
A35: 12:20 | B35: 178 | C35: =B35/10 -> 17.8 | D35: =$C35*Inputs!$B$22 -> 15.13 | E35: =D35/Inputs!$B$41 -> 0.50433333 | F35: =D35/(Inputs!$B$11*Inputs!$B$23) -> 0.7565 | G35: =IF(F35<1,((D35/Inputs!$B$23)^Inputs!$B$11/FACT(Inputs!$B$11)*Inputs!$B$11/(Inputs!$B$11-(D35/Inputs!$B$23)))/(SUMPRODUCT(--({0,1,2,3,4,5,6,7,8,9}<Inputs!$B$11),(D35/Inputs!$B$23)^{0,1,2,3,4,5,6,7,8,9}/FACT({0,1,2,3,4,5,6,7,8,9}))+((D35/Inputs!$B$23)^Inputs!$B$11/FACT(Inputs!$B$11)*Inputs!$B$11/(Inputs!$B$11-(D35/Inputs!$B$23)))),1) -> 0.65162795 | H35: =IF(F35<1,G35/(Inputs!$B$11*Inputs!$B$23-D35),0) -> 0.13380451 | I35: =MAX(0,I34+(D35-Inputs!$B$11*Inputs!$B$23)*10) -> 0 | J35: =I35/(Inputs!$B$11*Inputs!$B$23)+H35 -> 0.13380451 | K35: =D35*(J35+1/Inputs!$B$23+Inputs!$B$25) -> 260.74746 | L35: =$C35*(1-Inputs!$B$22) -> 2.67 | M35: =L35/Inputs!$B$42 -> 0.089 | N35: =L35/(Inputs!$B$12*Inputs!$B$23) -> 0.1335 | O35: =IF(N35<1,((L35/Inputs!$B$23)^Inputs!$B$12/FACT(Inputs!$B$12)*Inputs!$B$12/(Inputs!$B$12-(L35/Inputs!$B$23)))/(SUMPRODUCT(--({0,1,2,3,4,5,6,7,8,9}<Inputs!$B$12),(L35/Inputs!$B$23)^{0,1,2,3,4,5,6,7,8,9}/FACT({0,1,2,3,4,5,6,7,8,9}))+((L35/Inputs!$B$23)^Inputs!$B$12/FACT(Inputs!$B$12)*Inputs!$B$12/(Inputs!$B$12-(L35/Inputs!$B$23)))),1) -> 0.031446405 | P35: =IF(N35<1,O35/(Inputs!$B$12*Inputs!$B$23-L35),0) -> 0.0018145646 | Q35: =MAX(0,Q34+(L35-Inputs!$B$12*Inputs!$B$23)*10) -> 0 | R35: =Q35/(Inputs!$B$12*Inputs!$B$23)+P35 -> 0.0018145646 | S35: =L35*(R35+1/Inputs!$B$23+Inputs!$B$25) -> 45.661845 | T35: =$C35*$E$26 -> 11.392 | U35: =T35/Inputs!$B$41 -> 0.37973333 | V35: =T35/(Inputs!$B$11*Inputs!$B$23) -> 0.5696 | W35: =IF(V35<1,((T35/Inputs!$B$23)^Inputs!$B$11/FACT(Inputs!$B$11)*Inputs!$B$11/(Inputs!$B$11-(T35/Inputs!$B$23)))/(SUMPRODUCT(--({0,1,2,3,4,5,6,7,8,9}<Inputs!$B$11),(T35/Inputs!$B$23)^{0,1,2,3,4,5,6,7,8,9}/FACT({0,1,2,3,4,5,6,7,8,9}))+((T35/Inputs!$B$23)^Inputs!$B$11/FACT(Inputs!$B$11)*Inputs!$B$11/(Inputs!$B$11-(T35/Inputs!$B$23)))),1) -> 0.41340999 | X35: =IF(V35<1,W35/(Inputs!$B$11*Inputs!$B$23-T35),0) -> 0.048026253 | Y35: =MAX(0,Y34+(T35-Inputs!$B$11*Inputs!$B$23)*10) -> 0 | Z35: =Y35/(Inputs!$B$11*Inputs!$B$23)+X35 -> 0.048026253 | AA35: =T35*(Z35+1/Inputs!$B$23+Inputs!$B$25) -> 195.35032 | AB35: =$C35*(1-$E$26) -> 6.408 | AC35: =AB35/Inputs!$B$42 -> 0.2136 | AD35: =AB35/(Inputs!$B$12*Inputs!$B$23) -> 0.3204 | AE35: =IF(AD35<1,((AB35/Inputs!$B$23)^Inputs!$B$12/FACT(Inputs!$B$12)*Inputs!$B$12/(Inputs!$B$12-(AB35/Inputs!$B$23)))/(SUMPRODUCT(--({0,1,2,3,4,5,6,7,8,9}<Inputs!$B$12),(AB35/Inputs!$B$23)^{0,1,2,3,4,5,6,7,8,9}/FACT({0,1,2,3,4,5,6,7,8,9}))+((AB35/Inputs!$B$23)^Inputs!$B$12/FACT(Inputs!$B$12)*Inputs!$B$12/(Inputs!$B$12-(AB35/Inputs!$B$23)))),1) -> 0.15549252 | AF35: =IF(AD35<1,AE35/(Inputs!$B$12*Inputs!$B$23-AB35),0) -> 0.011440003 | AG35: =MAX(0,AG34+(AB35-Inputs!$B$12*Inputs!$B$23)*10) -> 0 | AH35: =AG35/(Inputs!$B$12*Inputs!$B$23)+AF35 -> 0.011440003 | AI35: =AB35*(AH35+1/Inputs!$B$23+Inputs!$B$25) -> 109.65011
A36: 12:30 | B36: 236 | C36: =B36/10 -> 23.6 | D36: =$C36*Inputs!$B$22 -> 20.06 | E36: =D36/Inputs!$B$41 -> 0.66866667 | F36: =D36/(Inputs!$B$11*Inputs!$B$23) -> 1.003 | G36: =IF(F36<1,((D36/Inputs!$B$23)^Inputs!$B$11/FACT(Inputs!$B$11)*Inputs!$B$11/(Inputs!$B$11-(D36/Inputs!$B$23)))/(SUMPRODUCT(--({0,1,2,3,4,5,6,7,8,9}<Inputs!$B$11),(D36/Inputs!$B$23)^{0,1,2,3,4,5,6,7,8,9}/FACT({0,1,2,3,4,5,6,7,8,9}))+((D36/Inputs!$B$23)^Inputs!$B$11/FACT(Inputs!$B$11)*Inputs!$B$11/(Inputs!$B$11-(D36/Inputs!$B$23)))),1) -> 1 | H36: =IF(F36<1,G36/(Inputs!$B$11*Inputs!$B$23-D36),0) -> 0 | I36: =MAX(0,I35+(D36-Inputs!$B$11*Inputs!$B$23)*10) -> 0.6 | J36: =I36/(Inputs!$B$11*Inputs!$B$23)+H36 -> 0.03 | K36: =D36*(J36+1/Inputs!$B$23+Inputs!$B$25) -> 343.6278 | L36: =$C36*(1-Inputs!$B$22) -> 3.54 | M36: =L36/Inputs!$B$42 -> 0.118 | N36: =L36/(Inputs!$B$12*Inputs!$B$23) -> 0.177 | O36: =IF(N36<1,((L36/Inputs!$B$23)^Inputs!$B$12/FACT(Inputs!$B$12)*Inputs!$B$12/(Inputs!$B$12-(L36/Inputs!$B$23)))/(SUMPRODUCT(--({0,1,2,3,4,5,6,7,8,9}<Inputs!$B$12),(L36/Inputs!$B$23)^{0,1,2,3,4,5,6,7,8,9}/FACT({0,1,2,3,4,5,6,7,8,9}))+((L36/Inputs!$B$23)^Inputs!$B$12/FACT(Inputs!$B$12)*Inputs!$B$12/(Inputs!$B$12-(L36/Inputs!$B$23)))),1) -> 0.053235344 | P36: =IF(N36<1,O36/(Inputs!$B$12*Inputs!$B$23-L36),0) -> 0.003234225 | Q36: =MAX(0,Q35+(L36-Inputs!$B$12*Inputs!$B$23)*10) -> 0 | R36: =Q36/(Inputs!$B$12*Inputs!$B$23)+P36 -> 0.003234225 | S36: =L36*(R36+1/Inputs!$B$23+Inputs!$B$25) -> 60.545449 | T36: =$C36*$E$26 -> 15.104 | U36: =T36/Inputs!$B$41 -> 0.50346667 | V36: =T36/(Inputs!$B$11*Inputs!$B$23) -> 0.7552 | W36: =IF(V36<1,((T36/Inputs!$B$23)^Inputs!$B$11/FACT(Inputs!$B$11)*Inputs!$B$11/(Inputs!$B$11-(T36/Inputs!$B$23)))/(SUMPRODUCT(--({0,1,2,3,4,5,6,7,8,9}<Inputs!$B$11),(T36/Inputs!$B$23)^{0,1,2,3,4,5,6,7,8,9}/FACT({0,1,2,3,4,5,6,7,8,9}))+((T36/Inputs!$B$23)^Inputs!$B$11/FACT(Inputs!$B$11)*Inputs!$B$11/(Inputs!$B$11-(T36/Inputs!$B$23)))),1) -> 0.64987129 | X36: =IF(V36<1,W36/(Inputs!$B$11*Inputs!$B$23-T36),0) -> 0.13273515 | Y36: =MAX(0,Y35+(T36-Inputs!$B$11*Inputs!$B$23)*10) -> 0 | Z36: =Y36/(Inputs!$B$11*Inputs!$B$23)+X36 -> 0.13273515 | AA36: =T36*(Z36+1/Inputs!$B$23+Inputs!$B$25) -> 260.28323 | AB36: =$C36*(1-$E$26) -> 8.496 | AC36: =AB36/Inputs!$B$42 -> 0.2832 | AD36: =AB36/(Inputs!$B$12*Inputs!$B$23) -> 0.4248 | AE36: =IF(AD36<1,((AB36/Inputs!$B$23)^Inputs!$B$12/FACT(Inputs!$B$12)*Inputs!$B$12/(Inputs!$B$12-(AB36/Inputs!$B$23)))/(SUMPRODUCT(--({0,1,2,3,4,5,6,7,8,9}<Inputs!$B$12),(AB36/Inputs!$B$23)^{0,1,2,3,4,5,6,7,8,9}/FACT({0,1,2,3,4,5,6,7,8,9}))+((AB36/Inputs!$B$23)^Inputs!$B$12/FACT(Inputs!$B$12)*Inputs!$B$12/(Inputs!$B$12-(AB36/Inputs!$B$23)))),1) -> 0.25330578 | AF36: =IF(AD36<1,AE36/(Inputs!$B$12*Inputs!$B$23-AB36),0) -> 0.022018931 | AG36: =MAX(0,AG35+(AB36-Inputs!$B$12*Inputs!$B$23)*10) -> 0 | AH36: =AG36/(Inputs!$B$12*Inputs!$B$23)+AF36 -> 0.022018931 | AI36: =AB36*(AH36+1/Inputs!$B$23+Inputs!$B$25) -> 145.46867
A37: 12:40 | B37: 289 | C37: =B37/10 -> 28.9 | D37: =$C37*Inputs!$B$22 -> 24.565 | E37: =D37/Inputs!$B$41 -> 0.81883333 | F37: =D37/(Inputs!$B$11*Inputs!$B$23) -> 1.22825 | G37: =IF(F37<1,((D37/Inputs!$B$23)^Inputs!$B$11/FACT(Inputs!$B$11)*Inputs!$B$11/(Inputs!$B$11-(D37/Inputs!$B$23)))/(SUMPRODUCT(--({0,1,2,3,4,5,6,7,8,9}<Inputs!$B$11),(D37/Inputs!$B$23)^{0,1,2,3,4,5,6,7,8,9}/FACT({0,1,2,3,4,5,6,7,8,9}))+((D37/Inputs!$B$23)^Inputs!$B$11/FACT(Inputs!$B$11)*Inputs!$B$11/(Inputs!$B$11-(D37/Inputs!$B$23)))),1) -> 1 | H37: =IF(F37<1,G37/(Inputs!$B$11*Inputs!$B$23-D37),0) -> 0 | I37: =MAX(0,I36+(D37-Inputs!$B$11*Inputs!$B$23)*10) -> 46.25 | J37: =I37/(Inputs!$B$11*Inputs!$B$23)+H37 -> 2.3125 | K37: =D37*(J37+1/Inputs!$B$23+Inputs!$B$25) -> 476.86806 | L37: =$C37*(1-Inputs!$B$22) -> 4.335 | M37: =L37/Inputs!$B$42 -> 0.1445 | N37: =L37/(Inputs!$B$12*Inputs!$B$23) -> 0.21675 | O37: =IF(N37<1,((L37/Inputs!$B$23)^Inputs!$B$12/FACT(Inputs!$B$12)*Inputs!$B$12/(Inputs!$B$12-(L37/Inputs!$B$23)))/(SUMPRODUCT(--({0,1,2,3,4,5,6,7,8,9}<Inputs!$B$12),(L37/Inputs!$B$23)^{0,1,2,3,4,5,6,7,8,9}/FACT({0,1,2,3,4,5,6,7,8,9}))+((L37/Inputs!$B$23)^Inputs!$B$12/FACT(Inputs!$B$12)*Inputs!$B$12/(Inputs!$B$12-(L37/Inputs!$B$23)))),1) -> 0.077223033 | P37: =IF(N37<1,O37/(Inputs!$B$12*Inputs!$B$23-L37),0) -> 0.0049296542 | Q37: =MAX(0,Q36+(L37-Inputs!$B$12*Inputs!$B$23)*10) -> 0 | R37: =Q37/(Inputs!$B$12*Inputs!$B$23)+P37 -> 0.0049296542 | S37: =L37*(R37+1/Inputs!$B$23+Inputs!$B$25) -> 74.14987 | T37: =$C37*$E$26 -> 18.496 | U37: =T37/Inputs!$B$41 -> 0.61653333 | V37: =T37/(Inputs!$B$11*Inputs!$B$23) -> 0.9248 | W37: =IF(V37<1,((T37/Inputs!$B$23)^Inputs!$B$11/FACT(Inputs!$B$11)*Inputs!$B$11/(Inputs!$B$11-(T37/Inputs!$B$23)))/(SUMPRODUCT(--({0,1,2,3,4,5,6,7,8,9}<Inputs!$B$11),(T37/Inputs!$B$23)^{0,1,2,3,4,5,6,7,8,9}/FACT({0,1,2,3,4,5,6,7,8,9}))+((T37/Inputs!$B$23)^Inputs!$B$11/FACT(Inputs!$B$11)*Inputs!$B$11/(Inputs!$B$11-(T37/Inputs!$B$23)))),1) -> 0.88866899 | X37: =IF(V37<1,W37/(Inputs!$B$11*Inputs!$B$23-T37),0) -> 0.59087034 | Y37: =MAX(0,Y36+(T37-Inputs!$B$11*Inputs!$B$23)*10) -> 0 | Z37: =Y37/(Inputs!$B$11*Inputs!$B$23)+X37 -> 0.59087034 | AA37: =T37*(Z37+1/Inputs!$B$23+Inputs!$B$25) -> 327.21034 | AB37: =$C37*(1-$E$26) -> 10.404 | AC37: =AB37/Inputs!$B$42 -> 0.3468 | AD37: =AB37/(Inputs!$B$12*Inputs!$B$23) -> 0.5202 | AE37: =IF(AD37<1,((AB37/Inputs!$B$23)^Inputs!$B$12/FACT(Inputs!$B$12)*Inputs!$B$12/(Inputs!$B$12-(AB37/Inputs!$B$23)))/(SUMPRODUCT(--({0,1,2,3,4,5,6,7,8,9}<Inputs!$B$12),(AB37/Inputs!$B$23)^{0,1,2,3,4,5,6,7,8,9}/FACT({0,1,2,3,4,5,6,7,8,9}))+((AB37/Inputs!$B$23)^Inputs!$B$12/FACT(Inputs!$B$12)*Inputs!$B$12/(Inputs!$B$12-(AB37/Inputs!$B$23)))),1) -> 0.35601637 | AF37: =IF(AD37<1,AE37/(Inputs!$B$12*Inputs!$B$23-AB37),0) -> 0.037100497 | AG37: =MAX(0,AG36+(AB37-Inputs!$B$12*Inputs!$B$23)*10) -> 0 | AH37: =AG37/(Inputs!$B$12*Inputs!$B$23)+AF37 -> 0.037100497 | AI37: =AB37*(AH37+1/Inputs!$B$23+Inputs!$B$25) -> 178.29439
A38: 12:50 | B38: 326 | C38: =B38/10 -> 32.6 | D38: =$C38*Inputs!$B$22 -> 27.71 | E38: =D38/Inputs!$B$41 -> 0.92366667 | F38: =D38/(Inputs!$B$11*Inputs!$B$23) -> 1.3855 | G38: =IF(F38<1,((D38/Inputs!$B$23)^Inputs!$B$11/FACT(Inputs!$B$11)*Inputs!$B$11/(Inputs!$B$11-(D38/Inputs!$B$23)))/(SUMPRODUCT(--({0,1,2,3,4,5,6,7,8,9}<Inputs!$B$11),(D38/Inputs!$B$23)^{0,1,2,3,4,5,6,7,8,9}/FACT({0,1,2,3,4,5,6,7,8,9}))+((D38/Inputs!$B$23)^Inputs!$B$11/FACT(Inputs!$B$11)*Inputs!$B$11/(Inputs!$B$11-(D38/Inputs!$B$23)))),1) -> 1 | H38: =IF(F38<1,G38/(Inputs!$B$11*Inputs!$B$23-D38),0) -> 0 | I38: =MAX(0,I37+(D38-Inputs!$B$11*Inputs!$B$23)*10) -> 123.35 | J38: =I38/(Inputs!$B$11*Inputs!$B$23)+H38 -> 6.1675 | K38: =D38*(J38+1/Inputs!$B$23+Inputs!$B$25) -> 644.74243 | L38: =$C38*(1-Inputs!$B$22) -> 4.89 | M38: =L38/Inputs!$B$42 -> 0.163 | N38: =L38/(Inputs!$B$12*Inputs!$B$23) -> 0.2445 | O38: =IF(N38<1,((L38/Inputs!$B$23)^Inputs!$B$12/FACT(Inputs!$B$12)*Inputs!$B$12/(Inputs!$B$12-(L38/Inputs!$B$23)))/(SUMPRODUCT(--({0,1,2,3,4,5,6,7,8,9}<Inputs!$B$12),(L38/Inputs!$B$23)^{0,1,2,3,4,5,6,7,8,9}/FACT({0,1,2,3,4,5,6,7,8,9}))+((L38/Inputs!$B$23)^Inputs!$B$12/FACT(Inputs!$B$12)*Inputs!$B$12/(Inputs!$B$12-(L38/Inputs!$B$23)))),1) -> 0.096071113 | P38: =IF(N38<1,O38/(Inputs!$B$12*Inputs!$B$23-L38),0) -> 0.0063581147 | Q38: =MAX(0,Q37+(L38-Inputs!$B$12*Inputs!$B$23)*10) -> 0 | R38: =Q38/(Inputs!$B$12*Inputs!$B$23)+P38 -> 0.0063581147 | S38: =L38*(R38+1/Inputs!$B$23+Inputs!$B$25) -> 83.650091 | T38: =$C38*$E$26 -> 20.864 | U38: =T38/Inputs!$B$41 -> 0.69546667 | V38: =T38/(Inputs!$B$11*Inputs!$B$23) -> 1.0432 | W38: =IF(V38<1,((T38/Inputs!$B$23)^Inputs!$B$11/FACT(Inputs!$B$11)*Inputs!$B$11/(Inputs!$B$11-(T38/Inputs!$B$23)))/(SUMPRODUCT(--({0,1,2,3,4,5,6,7,8,9}<Inputs!$B$11),(T38/Inputs!$B$23)^{0,1,2,3,4,5,6,7,8,9}/FACT({0,1,2,3,4,5,6,7,8,9}))+((T38/Inputs!$B$23)^Inputs!$B$11/FACT(Inputs!$B$11)*Inputs!$B$11/(Inputs!$B$11-(T38/Inputs!$B$23)))),1) -> 1 | X38: =IF(V38<1,W38/(Inputs!$B$11*Inputs!$B$23-T38),0) -> 0 | Y38: =MAX(0,Y37+(T38-Inputs!$B$11*Inputs!$B$23)*10) -> 8.64 | Z38: =Y38/(Inputs!$B$11*Inputs!$B$23)+X38 -> 0.432 | AA38: =T38*(Z38+1/Inputs!$B$23+Inputs!$B$25) -> 365.78765 | AB38: =$C38*(1-$E$26) -> 11.736 | AC38: =AB38/Inputs!$B$42 -> 0.3912 | AD38: =AB38/(Inputs!$B$12*Inputs!$B$23) -> 0.5868 | AE38: =IF(AD38<1,((AB38/Inputs!$B$23)^Inputs!$B$12/FACT(Inputs!$B$12)*Inputs!$B$12/(Inputs!$B$12-(AB38/Inputs!$B$23)))/(SUMPRODUCT(--({0,1,2,3,4,5,6,7,8,9}<Inputs!$B$12),(AB38/Inputs!$B$23)^{0,1,2,3,4,5,6,7,8,9}/FACT({0,1,2,3,4,5,6,7,8,9}))+((AB38/Inputs!$B$23)^Inputs!$B$12/FACT(Inputs!$B$12)*Inputs!$B$12/(Inputs!$B$12-(AB38/Inputs!$B$23)))),1) -> 0.43399829 | AF38: =IF(AD38<1,AE38/(Inputs!$B$12*Inputs!$B$23-AB38),0) -> 0.052516734 | AG38: =MAX(0,AG37+(AB38-Inputs!$B$12*Inputs!$B$23)*10) -> 0 | AH38: =AG38/(Inputs!$B$12*Inputs!$B$23)+AF38 -> 0.052516734 | AI38: =AB38*(AH38+1/Inputs!$B$23+Inputs!$B$25) -> 201.30194
A39: 13:00 | B39: 340 | C39: =B39/10 -> 34 | D39: =$C39*Inputs!$B$22 -> 28.9 | E39: =D39/Inputs!$B$41 -> 0.96333333 | F39: =D39/(Inputs!$B$11*Inputs!$B$23) -> 1.445 | G39: =IF(F39<1,((D39/Inputs!$B$23)^Inputs!$B$11/FACT(Inputs!$B$11)*Inputs!$B$11/(Inputs!$B$11-(D39/Inputs!$B$23)))/(SUMPRODUCT(--({0,1,2,3,4,5,6,7,8,9}<Inputs!$B$11),(D39/Inputs!$B$23)^{0,1,2,3,4,5,6,7,8,9}/FACT({0,1,2,3,4,5,6,7,8,9}))+((D39/Inputs!$B$23)^Inputs!$B$11/FACT(Inputs!$B$11)*Inputs!$B$11/(Inputs!$B$11-(D39/Inputs!$B$23)))),1) -> 1 | H39: =IF(F39<1,G39/(Inputs!$B$11*Inputs!$B$23-D39),0) -> 0 | I39: =MAX(0,I38+(D39-Inputs!$B$11*Inputs!$B$23)*10) -> 212.35 | J39: =I39/(Inputs!$B$11*Inputs!$B$23)+H39 -> 10.6175 | K39: =D39*(J39+1/Inputs!$B$23+Inputs!$B$25) -> 801.03575 | L39: =$C39*(1-Inputs!$B$22) -> 5.1 | M39: =L39/Inputs!$B$42 -> 0.17 | N39: =L39/(Inputs!$B$12*Inputs!$B$23) -> 0.255 | O39: =IF(N39<1,((L39/Inputs!$B$23)^Inputs!$B$12/FACT(Inputs!$B$12)*Inputs!$B$12/(Inputs!$B$12-(L39/Inputs!$B$23)))/(SUMPRODUCT(--({0,1,2,3,4,5,6,7,8,9}<Inputs!$B$12),(L39/Inputs!$B$23)^{0,1,2,3,4,5,6,7,8,9}/FACT({0,1,2,3,4,5,6,7,8,9}))+((L39/Inputs!$B$23)^Inputs!$B$12/FACT(Inputs!$B$12)*Inputs!$B$12/(Inputs!$B$12-(L39/Inputs!$B$23)))),1) -> 0.1036255 | P39: =IF(N39<1,O39/(Inputs!$B$12*Inputs!$B$23-L39),0) -> 0.0069547314 | Q39: =MAX(0,Q38+(L39-Inputs!$B$12*Inputs!$B$23)*10) -> 0 | R39: =Q39/(Inputs!$B$12*Inputs!$B$23)+P39 -> 0.0069547314 | S39: =L39*(R39+1/Inputs!$B$23+Inputs!$B$25) -> 87.245469 | T39: =$C39*$E$26 -> 21.76 | U39: =T39/Inputs!$B$41 -> 0.72533333 | V39: =T39/(Inputs!$B$11*Inputs!$B$23) -> 1.088 | W39: =IF(V39<1,((T39/Inputs!$B$23)^Inputs!$B$11/FACT(Inputs!$B$11)*Inputs!$B$11/(Inputs!$B$11-(T39/Inputs!$B$23)))/(SUMPRODUCT(--({0,1,2,3,4,5,6,7,8,9}<Inputs!$B$11),(T39/Inputs!$B$23)^{0,1,2,3,4,5,6,7,8,9}/FACT({0,1,2,3,4,5,6,7,8,9}))+((T39/Inputs!$B$23)^Inputs!$B$11/FACT(Inputs!$B$11)*Inputs!$B$11/(Inputs!$B$11-(T39/Inputs!$B$23)))),1) -> 1 | X39: =IF(V39<1,W39/(Inputs!$B$11*Inputs!$B$23-T39),0) -> 0 | Y39: =MAX(0,Y38+(T39-Inputs!$B$11*Inputs!$B$23)*10) -> 26.24 | Z39: =Y39/(Inputs!$B$11*Inputs!$B$23)+X39 -> 1.312 | AA39: =T39*(Z39+1/Inputs!$B$23+Inputs!$B$25) -> 400.64512 | AB39: =$C39*(1-$E$26) -> 12.24 | AC39: =AB39/Inputs!$B$42 -> 0.408 | AD39: =AB39/(Inputs!$B$12*Inputs!$B$23) -> 0.612 | AE39: =IF(AD39<1,((AB39/Inputs!$B$23)^Inputs!$B$12/FACT(Inputs!$B$12)*Inputs!$B$12/(Inputs!$B$12-(AB39/Inputs!$B$23)))/(SUMPRODUCT(--({0,1,2,3,4,5,6,7,8,9}<Inputs!$B$12),(AB39/Inputs!$B$23)^{0,1,2,3,4,5,6,7,8,9}/FACT({0,1,2,3,4,5,6,7,8,9}))+((AB39/Inputs!$B$23)^Inputs!$B$12/FACT(Inputs!$B$12)*Inputs!$B$12/(Inputs!$B$12-(AB39/Inputs!$B$23)))),1) -> 0.46469479 | AF39: =IF(AD39<1,AE39/(Inputs!$B$12*Inputs!$B$23-AB39),0) -> 0.059883349 | AG39: =MAX(0,AG38+(AB39-Inputs!$B$12*Inputs!$B$23)*10) -> 0 | AH39: =AG39/(Inputs!$B$12*Inputs!$B$23)+AF39 -> 0.059883349 | AI39: =AB39*(AH39+1/Inputs!$B$23+Inputs!$B$25) -> 210.03697
A40: 13:10 | B40: 326 | C40: =B40/10 -> 32.6 | D40: =$C40*Inputs!$B$22 -> 27.71 | E40: =D40/Inputs!$B$41 -> 0.92366667 | F40: =D40/(Inputs!$B$11*Inputs!$B$23) -> 1.3855 | G40: =IF(F40<1,((D40/Inputs!$B$23)^Inputs!$B$11/FACT(Inputs!$B$11)*Inputs!$B$11/(Inputs!$B$11-(D40/Inputs!$B$23)))/(SUMPRODUCT(--({0,1,2,3,4,5,6,7,8,9}<Inputs!$B$11),(D40/Inputs!$B$23)^{0,1,2,3,4,5,6,7,8,9}/FACT({0,1,2,3,4,5,6,7,8,9}))+((D40/Inputs!$B$23)^Inputs!$B$11/FACT(Inputs!$B$11)*Inputs!$B$11/(Inputs!$B$11-(D40/Inputs!$B$23)))),1) -> 1 | H40: =IF(F40<1,G40/(Inputs!$B$11*Inputs!$B$23-D40),0) -> 0 | I40: =MAX(0,I39+(D40-Inputs!$B$11*Inputs!$B$23)*10) -> 289.45 | J40: =I40/(Inputs!$B$11*Inputs!$B$23)+H40 -> 14.4725 | K40: =D40*(J40+1/Inputs!$B$23+Inputs!$B$25) -> 874.87397 | L40: =$C40*(1-Inputs!$B$22) -> 4.89 | M40: =L40/Inputs!$B$42 -> 0.163 | N40: =L40/(Inputs!$B$12*Inputs!$B$23) -> 0.2445 | O40: =IF(N40<1,((L40/Inputs!$B$23)^Inputs!$B$12/FACT(Inputs!$B$12)*Inputs!$B$12/(Inputs!$B$12-(L40/Inputs!$B$23)))/(SUMPRODUCT(--({0,1,2,3,4,5,6,7,8,9}<Inputs!$B$12),(L40/Inputs!$B$23)^{0,1,2,3,4,5,6,7,8,9}/FACT({0,1,2,3,4,5,6,7,8,9}))+((L40/Inputs!$B$23)^Inputs!$B$12/FACT(Inputs!$B$12)*Inputs!$B$12/(Inputs!$B$12-(L40/Inputs!$B$23)))),1) -> 0.096071113 | P40: =IF(N40<1,O40/(Inputs!$B$12*Inputs!$B$23-L40),0) -> 0.0063581147 | Q40: =MAX(0,Q39+(L40-Inputs!$B$12*Inputs!$B$23)*10) -> 0 | R40: =Q40/(Inputs!$B$12*Inputs!$B$23)+P40 -> 0.0063581147 | S40: =L40*(R40+1/Inputs!$B$23+Inputs!$B$25) -> 83.650091 | T40: =$C40*$E$26 -> 20.864 | U40: =T40/Inputs!$B$41 -> 0.69546667 | V40: =T40/(Inputs!$B$11*Inputs!$B$23) -> 1.0432 | W40: =IF(V40<1,((T40/Inputs!$B$23)^Inputs!$B$11/FACT(Inputs!$B$11)*Inputs!$B$11/(Inputs!$B$11-(T40/Inputs!$B$23)))/(SUMPRODUCT(--({0,1,2,3,4,5,6,7,8,9}<Inputs!$B$11),(T40/Inputs!$B$23)^{0,1,2,3,4,5,6,7,8,9}/FACT({0,1,2,3,4,5,6,7,8,9}))+((T40/Inputs!$B$23)^Inputs!$B$11/FACT(Inputs!$B$11)*Inputs!$B$11/(Inputs!$B$11-(T40/Inputs!$B$23)))),1) -> 1 | X40: =IF(V40<1,W40/(Inputs!$B$11*Inputs!$B$23-T40),0) -> 0 | Y40: =MAX(0,Y39+(T40-Inputs!$B$11*Inputs!$B$23)*10) -> 34.88 | Z40: =Y40/(Inputs!$B$11*Inputs!$B$23)+X40 -> 1.744 | AA40: =T40*(Z40+1/Inputs!$B$23+Inputs!$B$25) -> 393.16122 | AB40: =$C40*(1-$E$26) -> 11.736 | AC40: =AB40/Inputs!$B$42 -> 0.3912 | AD40: =AB40/(Inputs!$B$12*Inputs!$B$23) -> 0.5868 | AE40: =IF(AD40<1,((AB40/Inputs!$B$23)^Inputs!$B$12/FACT(Inputs!$B$12)*Inputs!$B$12/(Inputs!$B$12-(AB40/Inputs!$B$23)))/(SUMPRODUCT(--({0,1,2,3,4,5,6,7,8,9}<Inputs!$B$12),(AB40/Inputs!$B$23)^{0,1,2,3,4,5,6,7,8,9}/FACT({0,1,2,3,4,5,6,7,8,9}))+((AB40/Inputs!$B$23)^Inputs!$B$12/FACT(Inputs!$B$12)*Inputs!$B$12/(Inputs!$B$12-(AB40/Inputs!$B$23)))),1) -> 0.43399829 | AF40: =IF(AD40<1,AE40/(Inputs!$B$12*Inputs!$B$23-AB40),0) -> 0.052516734 | AG40: =MAX(0,AG39+(AB40-Inputs!$B$12*Inputs!$B$23)*10) -> 0 | AH40: =AG40/(Inputs!$B$12*Inputs!$B$23)+AF40 -> 0.052516734 | AI40: =AB40*(AH40+1/Inputs!$B$23+Inputs!$B$25) -> 201.30194
A41: 13:20 | B41: 289 | C41: =B41/10 -> 28.9 | D41: =$C41*Inputs!$B$22 -> 24.565 | E41: =D41/Inputs!$B$41 -> 0.81883333 | F41: =D41/(Inputs!$B$11*Inputs!$B$23) -> 1.22825 | G41: =IF(F41<1,((D41/Inputs!$B$23)^Inputs!$B$11/FACT(Inputs!$B$11)*Inputs!$B$11/(Inputs!$B$11-(D41/Inputs!$B$23)))/(SUMPRODUCT(--({0,1,2,3,4,5,6,7,8,9}<Inputs!$B$11),(D41/Inputs!$B$23)^{0,1,2,3,4,5,6,7,8,9}/FACT({0,1,2,3,4,5,6,7,8,9}))+((D41/Inputs!$B$23)^Inputs!$B$11/FACT(Inputs!$B$11)*Inputs!$B$11/(Inputs!$B$11-(D41/Inputs!$B$23)))),1) -> 1 | H41: =IF(F41<1,G41/(Inputs!$B$11*Inputs!$B$23-D41),0) -> 0 | I41: =MAX(0,I40+(D41-Inputs!$B$11*Inputs!$B$23)*10) -> 335.1 | J41: =I41/(Inputs!$B$11*Inputs!$B$23)+H41 -> 16.755 | K41: =D41*(J41+1/Inputs!$B$23+Inputs!$B$25) -> 831.64807 | L41: =$C41*(1-Inputs!$B$22) -> 4.335 | M41: =L41/Inputs!$B$42 -> 0.1445 | N41: =L41/(Inputs!$B$12*Inputs!$B$23) -> 0.21675 | O41: =IF(N41<1,((L41/Inputs!$B$23)^Inputs!$B$12/FACT(Inputs!$B$12)*Inputs!$B$12/(Inputs!$B$12-(L41/Inputs!$B$23)))/(SUMPRODUCT(--({0,1,2,3,4,5,6,7,8,9}<Inputs!$B$12),(L41/Inputs!$B$23)^{0,1,2,3,4,5,6,7,8,9}/FACT({0,1,2,3,4,5,6,7,8,9}))+((L41/Inputs!$B$23)^Inputs!$B$12/FACT(Inputs!$B$12)*Inputs!$B$12/(Inputs!$B$12-(L41/Inputs!$B$23)))),1) -> 0.077223033 | P41: =IF(N41<1,O41/(Inputs!$B$12*Inputs!$B$23-L41),0) -> 0.0049296542 | Q41: =MAX(0,Q40+(L41-Inputs!$B$12*Inputs!$B$23)*10) -> 0 | R41: =Q41/(Inputs!$B$12*Inputs!$B$23)+P41 -> 0.0049296542 | S41: =L41*(R41+1/Inputs!$B$23+Inputs!$B$25) -> 74.14987 | T41: =$C41*$E$26 -> 18.496 | U41: =T41/Inputs!$B$41 -> 0.61653333 | V41: =T41/(Inputs!$B$11*Inputs!$B$23) -> 0.9248 | W41: =IF(V41<1,((T41/Inputs!$B$23)^Inputs!$B$11/FACT(Inputs!$B$11)*Inputs!$B$11/(Inputs!$B$11-(T41/Inputs!$B$23)))/(SUMPRODUCT(--({0,1,2,3,4,5,6,7,8,9}<Inputs!$B$11),(T41/Inputs!$B$23)^{0,1,2,3,4,5,6,7,8,9}/FACT({0,1,2,3,4,5,6,7,8,9}))+((T41/Inputs!$B$23)^Inputs!$B$11/FACT(Inputs!$B$11)*Inputs!$B$11/(Inputs!$B$11-(T41/Inputs!$B$23)))),1) -> 0.88866899 | X41: =IF(V41<1,W41/(Inputs!$B$11*Inputs!$B$23-T41),0) -> 0.59087034 | Y41: =MAX(0,Y40+(T41-Inputs!$B$11*Inputs!$B$23)*10) -> 19.84 | Z41: =Y41/(Inputs!$B$11*Inputs!$B$23)+X41 -> 1.5828703 | AA41: =T41*(Z41+1/Inputs!$B$23+Inputs!$B$25) -> 345.55837 | AB41: =$C41*(1-$E$26) -> 10.404 | AC41: =AB41/Inputs!$B$42 -> 0.3468 | AD41: =AB41/(Inputs!$B$12*Inputs!$B$23) -> 0.5202 | AE41: =IF(AD41<1,((AB41/Inputs!$B$23)^Inputs!$B$12/FACT(Inputs!$B$12)*Inputs!$B$12/(Inputs!$B$12-(AB41/Inputs!$B$23)))/(SUMPRODUCT(--({0,1,2,3,4,5,6,7,8,9}<Inputs!$B$12),(AB41/Inputs!$B$23)^{0,1,2,3,4,5,6,7,8,9}/FACT({0,1,2,3,4,5,6,7,8,9}))+((AB41/Inputs!$B$23)^Inputs!$B$12/FACT(Inputs!$B$12)*Inputs!$B$12/(Inputs!$B$12-(AB41/Inputs!$B$23)))),1) -> 0.35601637 | AF41: =IF(AD41<1,AE41/(Inputs!$B$12*Inputs!$B$23-AB41),0) -> 0.037100497 | AG41: =MAX(0,AG40+(AB41-Inputs!$B$12*Inputs!$B$23)*10) -> 0 | AH41: =AG41/(Inputs!$B$12*Inputs!$B$23)+AF41 -> 0.037100497 | AI41: =AB41*(AH41+1/Inputs!$B$23+Inputs!$B$25) -> 178.29439
A42: 13:30 | B42: 236 | C42: =B42/10 -> 23.6 | D42: =$C42*Inputs!$B$22 -> 20.06 | E42: =D42/Inputs!$B$41 -> 0.66866667 | F42: =D42/(Inputs!$B$11*Inputs!$B$23) -> 1.003 | G42: =IF(F42<1,((D42/Inputs!$B$23)^Inputs!$B$11/FACT(Inputs!$B$11)*Inputs!$B$11/(Inputs!$B$11-(D42/Inputs!$B$23)))/(SUMPRODUCT(--({0,1,2,3,4,5,6,7,8,9}<Inputs!$B$11),(D42/Inputs!$B$23)^{0,1,2,3,4,5,6,7,8,9}/FACT({0,1,2,3,4,5,6,7,8,9}))+((D42/Inputs!$B$23)^Inputs!$B$11/FACT(Inputs!$B$11)*Inputs!$B$11/(Inputs!$B$11-(D42/Inputs!$B$23)))),1) -> 1 | H42: =IF(F42<1,G42/(Inputs!$B$11*Inputs!$B$23-D42),0) -> 0 | I42: =MAX(0,I41+(D42-Inputs!$B$11*Inputs!$B$23)*10) -> 335.7 | J42: =I42/(Inputs!$B$11*Inputs!$B$23)+H42 -> 16.785 | K42: =D42*(J42+1/Inputs!$B$23+Inputs!$B$25) -> 679.7331 | L42: =$C42*(1-Inputs!$B$22) -> 3.54 | M42: =L42/Inputs!$B$42 -> 0.118 | N42: =L42/(Inputs!$B$12*Inputs!$B$23) -> 0.177 | O42: =IF(N42<1,((L42/Inputs!$B$23)^Inputs!$B$12/FACT(Inputs!$B$12)*Inputs!$B$12/(Inputs!$B$12-(L42/Inputs!$B$23)))/(SUMPRODUCT(--({0,1,2,3,4,5,6,7,8,9}<Inputs!$B$12),(L42/Inputs!$B$23)^{0,1,2,3,4,5,6,7,8,9}/FACT({0,1,2,3,4,5,6,7,8,9}))+((L42/Inputs!$B$23)^Inputs!$B$12/FACT(Inputs!$B$12)*Inputs!$B$12/(Inputs!$B$12-(L42/Inputs!$B$23)))),1) -> 0.053235344 | P42: =IF(N42<1,O42/(Inputs!$B$12*Inputs!$B$23-L42),0) -> 0.003234225 | Q42: =MAX(0,Q41+(L42-Inputs!$B$12*Inputs!$B$23)*10) -> 0 | R42: =Q42/(Inputs!$B$12*Inputs!$B$23)+P42 -> 0.003234225 | S42: =L42*(R42+1/Inputs!$B$23+Inputs!$B$25) -> 60.545449 | T42: =$C42*$E$26 -> 15.104 | U42: =T42/Inputs!$B$41 -> 0.50346667 | V42: =T42/(Inputs!$B$11*Inputs!$B$23) -> 0.7552 | W42: =IF(V42<1,((T42/Inputs!$B$23)^Inputs!$B$11/FACT(Inputs!$B$11)*Inputs!$B$11/(Inputs!$B$11-(T42/Inputs!$B$23)))/(SUMPRODUCT(--({0,1,2,3,4,5,6,7,8,9}<Inputs!$B$11),(T42/Inputs!$B$23)^{0,1,2,3,4,5,6,7,8,9}/FACT({0,1,2,3,4,5,6,7,8,9}))+((T42/Inputs!$B$23)^Inputs!$B$11/FACT(Inputs!$B$11)*Inputs!$B$11/(Inputs!$B$11-(T42/Inputs!$B$23)))),1) -> 0.64987129 | X42: =IF(V42<1,W42/(Inputs!$B$11*Inputs!$B$23-T42),0) -> 0.13273515 | Y42: =MAX(0,Y41+(T42-Inputs!$B$11*Inputs!$B$23)*10) -> 0 | Z42: =Y42/(Inputs!$B$11*Inputs!$B$23)+X42 -> 0.13273515 | AA42: =T42*(Z42+1/Inputs!$B$23+Inputs!$B$25) -> 260.28323 | AB42: =$C42*(1-$E$26) -> 8.496 | AC42: =AB42/Inputs!$B$42 -> 0.2832 | AD42: =AB42/(Inputs!$B$12*Inputs!$B$23) -> 0.4248 | AE42: =IF(AD42<1,((AB42/Inputs!$B$23)^Inputs!$B$12/FACT(Inputs!$B$12)*Inputs!$B$12/(Inputs!$B$12-(AB42/Inputs!$B$23)))/(SUMPRODUCT(--({0,1,2,3,4,5,6,7,8,9}<Inputs!$B$12),(AB42/Inputs!$B$23)^{0,1,2,3,4,5,6,7,8,9}/FACT({0,1,2,3,4,5,6,7,8,9}))+((AB42/Inputs!$B$23)^Inputs!$B$12/FACT(Inputs!$B$12)*Inputs!$B$12/(Inputs!$B$12-(AB42/Inputs!$B$23)))),1) -> 0.25330578 | AF42: =IF(AD42<1,AE42/(Inputs!$B$12*Inputs!$B$23-AB42),0) -> 0.022018931 | AG42: =MAX(0,AG41+(AB42-Inputs!$B$12*Inputs!$B$23)*10) -> 0 | AH42: =AG42/(Inputs!$B$12*Inputs!$B$23)+AF42 -> 0.022018931 | AI42: =AB42*(AH42+1/Inputs!$B$23+Inputs!$B$25) -> 145.46867
