Workbook

Sheet Start Here
A1: Smart Mess: queues, capacity and load balancing
A2: Central CT and Munch Mess · lunch 11:30–14:30 · MDS project, Group WGB3
B4: What this workbook shows
B5: Where the lunch queue forms, how much each part of the mess can handle, and how Smart Scan spreads students between the two messes. Three questions, one tab each, all built on the same simulated lunches.
B6: All figures are simulated: 20 simulated lunches per scenario from the Smart Mess model, using the inputs on the Assumptions tab. They show how the system behaves under those assumptions; they are not measurements.
B8: How to walk through it
B9: Tab | C9: What it answers | D9: Concept
B10: Assumptions | C10: What we assumed: students, timings, seats, stations, compliance | D10: Inputs
B11: Variables | C11: What each symbol means, with its value in a real slot (λ = …, ρ = …) | D11: Notation
B12: Q1 Scanner | C12: Can one face scanner keep up? | D12: 1 · Queue management (M/M/1)
B13: Q2 Serving stations | C13: Where does the line form, and when is it unstable? | D13: 1 · Queue management (M/M/c)
B14: Q3 Seats & disposal | C14: Do the seats or the bins ever hold students up? | D14: 1 · Queue management (M/G/c)
B15: Littles Law | C15: When is the mess steady, filling or emptying? | D15: 1 · Little's Law
B16: Capacity | C16: Seat turnover, capacity of each stage, the bottleneck | D16: 2 · Capacity management
B17: Load Balancing | C17: When we send students to the other mess, and why a fixed rule fails | D17: 3 · Load balancing
B18: Sim Data | C18: The simulated numbers every tab reads from | D18: Data
B19: Checks | C19: Do the numbers add up? | D19: Validation
B21: Headline results
B22: Bottleneck at both messes | C22: =Capacity!B36 -> Serving stations
B23: Central's serving stations at the 13:10 surge (today) | C23: =TEXT('Q2 Serving stations'!C6,"0%")&" busy: over capacity" -> 147% busy: over capacity
B24: Slots over capacity at Central: today → with screens | C24: ='Q2 Serving stations'!D6&" → "&'Q2 Serving stations'!D8 -> 6 → 4
B25: Seat turnover at Central | C25: =TEXT(Capacity!B22,"0.0")&" min per diner · "&TEXT(Capacity!B23,"0.0")&" diners per seat per hour" -> 16.2 min per diner · 3.7 diners per seat per hour
B26: Peak seats in use: Central / Munch | C26: =TEXT(Capacity!B29,"0%")&" of 900 / "&TEXT(Capacity!C29,"0%")&" of 492" -> 38% of 900 / 26% of 492
B27: Average wait: today → freshers-at-Munch rule → Smart Scan | C27: =TEXT('Load Balancing'!B64,"0.0")&" → "&TEXT('Load Balancing'!B65,"0.0")&" → "&TEXT('Load Balancing'!B71,"0.0")&" min" -> 4.3 → 2.9 → 0.8 min
B28: All checks | C28: =Checks!C16 -> ALL OK
B30: Colour key
B31: Blue text | C31: an input you can change
B32: Shaded yellow | C32: an assumption not yet measured
B33: Shaded grey | C33: simulated data
B34: Green text | C34: a value pulled from another tab
B35: Shaded green | C35: a key result
B36: Red / amber rows | C36: over capacity / near capacity
B38: To refresh the data: python tools/queue_capacity_data.py, then python tools/build_queue_capacity_workbook.py

Sheet Assumptions
A1: Assumptions
A2: Every input behind the simulated lunches, and where it comes from. Blue = input; shaded yellow = not measured yet.
A4: Assumption | B4: Value | C4: Unit | D4: Status | E4: Source / note
A5: Demand
A6: Students per lunch (both messes) | B6: 2960 | C6: students | D6: Measured | E6: Plates served (Phase 1)
A7: Share who eat at Central by habit (no screens) | B7: 0.797 | C7: share | D7: Measured | E7: Group: ~2,360 Central, ~600 Munch
A8: Lunch window | B8: 180 | C8: minutes | D8: Measured | E8: 11:30–14:30
A9: Total time in the mess: low (quiet) | B9: 17 | C9: minutes | D9: Group estimate | E9: Group: 17–35 min door to leaving, depending on the rush
A10: Total time in the mess: high (rush) | B10: 35 | C10: minutes | D10: Group estimate | E10: As above
A11: Arrival lag after a department's lunch break starts: mean | B11: 20 | C11: minutes | D11: Calibrated | E11: Fits the 17–35 min visit and ~15 min peak delay; department breaks from the group's timetable
A12: Arrival lag: spread | B12: 20 | C12: minutes | D12: Calibrated | E12: As above
A14: Stage 1 · Scan & collect plate (30–45 s)
A15: Face scanners per mess | B15: 1 | C15: scanners | D15: Measured | E15: Group observation
A16: Time per face scan | B16: 2 | C16: seconds | D16: Assumed | E16: Stopwatch at the scanner
A17: Collect a plate after the scan (28–43 s) | B17: 35.5 | C17: seconds | D17: Group estimate | E17: Group: scan + plate takes 30–45 s
A19: Stage 2 · Collect food (1–2 min, plus the queue)
A20: Serving stations per mess | B20: 2 | C20: stations | D20: Measured | E20: Group observation
A21: Service rate per station | B21: 10 | C21: students/min | D21: Assumed | E21: ≈6 s per student; stopwatch 20–30 students
A22: Variability of serving time (coefficient of variation) | B22: 0.6 | C22: ratio | D22: Assumed | E22: 1.0 would be exponential, as M/M/c assumes
A23: Rest of food collection after the station (54–114 s) | B23: 84 | C23: seconds | D23: Group estimate | E23: Group: collecting food takes 1–2 min without a queue (serving ≈ 6 s + the rest); the queue adds up to ~15 min in the rush
A25: Stage 3 · Eat (14–18 min)
A26: Seats: Central CT | B26: 900 | C26: seats | D26: Measured | E26: CT manager
A27: Seats: Munch Mess | B27: 492 | C27: seats | D27: Measured | E27: CT manager
A28: Eating time: low | B28: 14 | C28: minutes | D28: Group estimate | E28: Group: 14–18 min
A29: Eating time: high | B29: 18 | C29: minutes | D29: Group estimate | E29: As above
A30: Seat changeover (next diner sits after the last leaves) | B30: 0.2 | C30: minutes | D30: Assumed | E30: Students clear their own plate; no table cleaning delays between diners as such. Used in the seat-turnover formulas
A32: Stage 4 · Dispose of plate (1–2 min)
A33: Disposal: low | B33: 1 | C33: minutes | D33: Group estimate | E33: Group: 2 min at most
A34: Disposal: high | B34: 2 | C34: minutes | D34: Group estimate | E34: As above
A36: Load balancing (door screens)
A37: Share who follow a screen's advice | B37: 0.6 | C37: share | D37: Assumed | E37: Imaginary adoption rate to measure impact; the pilot measures the real one
A38: Walk between the two mess doors | B38: 0.5 | C38: minutes | D38: Timed | E38: 30 s
A39: Minimum saving before a screen suggests switching | B39: 2 | C39: minutes | D39: Rule-based routing | E39: Our design choice
A40: Freshers as a share of every department (for the fixed freshers-at-Munch rule) | B40: 0.25 | C40: share | D40: Assumed | E40: First year of a four-year course; the messes first split students this way
A42: Simulation
A43: Simulated lunches averaged per scenario | B43: 20 | C43: lunches | D43: Design | E43: Seeds 0–19; the same students in every scenario
A44: Time-slot length in the tables | B44: 10 | C44: minutes | D44: Design | E44: 18 slots from 11:30
A47: Department lunch breaks (they shape the surge; sizes are rough, scaled to the plates served)
A48: Department | B48: Students (scaled) | C48: Break starts | D48: Break ends | E48: Status
A49: MIT | B49: 569 | C49: 12:00 | D49: 13:00 | E49: Timetable from the group
...

Sheet Variables
A1: Variables
A2: What every symbol means, how it is calculated, and its value in a real slot of the simulated lunch
A4: 1. Serving stations at Central, 12:10–12:20 today (M/M/c, stable)
A5: A worked example: every symbol below is calculated live from the simulated 12:10 slot, the first busy slot of the lunch.
A6: Symbol | B6: Name | C6: What it means at the mess | D6: Formula | E6: Value | F6: Unit | G6: Reads as
A7: λ | B7: Arrival rate | C7: Students joining Central's serving line per minute in this slot | D7: counted in the simulation | E7: ='Sim Data'!$E$27 -> 18.49 | F7: students/min | G7: =A7&" = "&IF(ISNUMBER(E7),TEXT(E7,"0.0"),E7)&IF(F7="",""," "&F7) -> λ = 18.5 students/min
A8: Ws | B8: Service time | C8: Average time one student spends being served at a station | D8: measured in the simulation | E8: ='Sim Data'!$G$27 -> 0.1004 | F8: min | G8: =A8&" = "&IF(ISNUMBER(E8),TEXT(E8,"0.00"),E8)&IF(F8="",""," "&F8) -> Ws = 0.10 min
A9: μ | B9: Service rate per station | C9: Students one station can serve per minute | D9: μ = 1 ÷ Ws | E9: =1/E8 -> 9.9601594 | F9: students/min | G9: =A9&" = "&IF(ISNUMBER(E9),TEXT(E9,"0.0"),E9)&IF(F9="",""," "&F9) -> μ = 10.0 students/min
A10: c | B10: Servers | C10: Serving stations at Central | D10: measured | E10: =Assumptions!$B$20 -> 2 | F10: stations | G10: =A10&" = "&IF(ISNUMBER(E10),TEXT(E10,"0"),E10)&IF(F10="",""," "&F10) -> c = 2 stations
A11: a | B11: Offered load | C11: Work arriving, in 'stations' worth of serving | D11: a = λ ÷ μ | E11: =E7/E9 -> 1.856396 | F11: stations | G11: =A11&" = "&IF(ISNUMBER(E11),TEXT(E11,"0.00"),E11)&IF(F11="",""," "&F11) -> a = 1.86 stations
A12: ρ | B12: Utilisation | C12: Share of the time each station is busy | D12: ρ = λ ÷ (c·μ) | E12: =E7/(E10*E9) -> 0.928198 | G12: =A12&" = "&IF(ISNUMBER(E12),TEXT(E12,"0%"),E12)&IF(F12="",""," "&F12) -> ρ = 93%
A13: Stable? | B13: Stability test | C13: Can the stations keep up, so the line settles to a steady size? | D13: stable if ρ < 1 | E13: =IF(E12<1,"yes","no") -> yes | G13: =A13&" = "&IF(ISNUMBER(E13),TEXT(E13,"0.00"),E13)&IF(F13="",""," "&F13) -> Stable? = yes
A14: P0 | B14: Probability empty | C14: Chance nobody is waiting or being served | D14: [Σ aᵏ/k! (k < c) + aᶜ/(c!(1−ρ))]⁻¹ | E14: =1/(SUMPRODUCT(--({0,1,2,3,4,5,6,7,8,9}<E10),E11^{0,1,2,3,4,5,6,7,8,9}/FACT({0,1,2,3,4,5,6,7,8,9}))+E11^E10/FACT(E10)/(1-E12)) -> 0.037237877 | G14: =A14&" = "&IF(ISNUMBER(E14),TEXT(E14,"0.000"),E14)&IF(F14="",""," "&F14) -> P0 = 0.037
A15: C | B15: Probability of waiting (Erlang C) | C15: Chance an arriving student has to wait at all | D15: C = aᶜ/(c!(1−ρ)) × P0 | E15: =E11^E10/FACT(E10)/(1-E12)*E14 -> 0.89363388 | G15: =A15&" = "&IF(ISNUMBER(E15),TEXT(E15,"0%"),E15)&IF(F15="",""," "&F15) -> C = 89%
A16: Wq | B16: Wait in the line | C16: Average minutes from joining the line to reaching a station | D16: Wq = C ÷ (c·μ − λ) | E16: =E15/(E10*E9-E7) -> 0.62477954 | F16: min | G16: =A16&" = "&IF(ISNUMBER(E16),TEXT(E16,"0.00"),E16)&IF(F16="",""," "&F16) -> Wq = 0.62 min
A17: Wq cv | B17: Wait, corrected for regular serving | C17: Serving times vary less than M/M/c assumes (cv 0.6), so the real wait is shorter | D17: Wq × (1 + cv²) ÷ 2 | E17: =E16*(1+Assumptions!$B$22^2)/2 -> 0.42485009 | F17: min | G17: =A17&" = "&IF(ISNUMBER(E17),TEXT(E17,"0.00"),E17)&IF(F17="",""," "&F17) -> Wq cv = 0.42 min
A18: W | B18: Time at the stage | C18: Wait plus being served | D18: W = Wq + Ws | E18: =E16+E8 -> 0.72517954 | F18: min | G18: =A18&" = "&IF(ISNUMBER(E18),TEXT(E18,"0.00"),E18)&IF(F18="",""," "&F18) -> W = 0.73 min
A19: Lq | B19: Students in the line | C19: Average number standing in the line | D19: Lq = λ × Wq (Little's Law) | E19: =E7*E16 -> 11.552174 | F19: students | G19: =A19&" = "&IF(ISNUMBER(E19),TEXT(E19,"0.0"),E19)&IF(F19="",""," "&F19) -> Lq = 11.6 students
A20: Ls | B20: Students being served | C20: Average number at the stations | D20: Ls = λ × Ws | E20: =E7*E8 -> 1.856396 | F20: students | G20: =A20&" = "&IF(ISNUMBER(E20),TEXT(E20,"0.0"),E20)&IF(F20="",""," "&F20) -> Ls = 1.9 students
A21: L | B21: Students at the stage | C21: Everyone at the serving stage | D21: L = λ × W (Little's Law) | E21: =E7*E18 -> 13.40857 | F21: students | G21: =A21&" = "&IF(ISNUMBER(E21),TEXT(E21,"0.0"),E21)&IF(F21="",""," "&F21) -> L = 13.4 students
A22: Wq sim | B22: Simulated wait | C22: What the simulated students actually waited | D22: from the simulation | E22: ='Sim Data'!$F$27 -> 0.2595 | F22: min | G22: =A22&" = "&IF(ISNUMBER(E22),TEXT(E22,"0.00"),E22)&IF(F22="",""," "&F22) -> Wq sim = 0.26 min
A23: Lq sim | B23: Simulated line length | C23: Average number the simulation had waiting | D23: from the simulation | E23: ='Sim Data'!$H$27 -> 4.575 | F23: students | G23: =A23&" = "&IF(ISNUMBER(E23),TEXT(E23,"0.0"),E23)&IF(F23="",""," "&F23) -> Lq sim = 4.6 students
A24: Little | B24: Little's Law check | C24: Simulated line length ÷ (λ × simulated wait). Close to 1 means steady | D24: Lq sim ÷ (λ × Wq sim) | E24: =E23/(E7*E22) -> 0.9534915 | G24: =A24&" = "&IF(ISNUMBER(E24),TEXT(E24,"0.00"),E24)&IF(F24="",""," "&F24) -> Little = 0.95
A26: 2. Serving stations at Central, 13:10–13:20 today (overloaded)
A27: When ρ ≥ 1 the textbook formulas stop applying: the line grows every minute until arrivals fall.
A28: Symbol | B28: Name | C28: What it means at the mess | D28: Formula | E28: Value | F28: Unit | G28: Reads as
A29: λ | B29: Arrival rate | C29: Students joining Central's line per minute at the 13:10 surge | D29: counted in the simulation | E29: ='Sim Data'!$E$33 -> 29.14 | F29: students/min | G29: =A29&" = "&IF(ISNUMBER(E29),TEXT(E29,"0.0"),E29)&IF(F29="",""," "&F29) -> λ = 29.1 students/min
A30: c·μ | B30: Capacity | C30: Most the two stations can serve per minute | D30: c × μ | E30: =Assumptions!$B$20*Assumptions!$B$21 -> 20 | F30: students/min | G30: =A30&" = "&IF(ISNUMBER(E30),TEXT(E30,"0.0"),E30)&IF(F30="",""," "&F30) -> c·μ = 20.0 students/min
A31: ρ | B31: Utilisation | C31: Above 100% the stations cannot keep up | D31: ρ = λ ÷ (c·μ) | E31: =E29/E30 -> 1.457 | G31: =A31&" = "&IF(ISNUMBER(E31),TEXT(E31,"0%"),E31)&IF(F31="",""," "&F31) -> ρ = 146%
A32: Growth | B32: Line growth | C32: Extra students added to the line during these 10 minutes | D32: (λ − c·μ) × 10 | E32: =MAX(0,(E29-E30)*10) -> 91.4 | F32: students | G32: =A32&" = "&IF(ISNUMBER(E32),TEXT(E32,"0"),E32)&IF(F32="",""," "&F32) -> Growth = 91 students
A33: Wq | B33: Steady-state wait | C33: Not defined: with ρ ≥ 1 the line has no steady size | D33: only if ρ < 1 | E33: =IF(E31<1,"defined","none (ρ ≥ 1)") -> none (ρ ≥ 1) | G33: =A33&" = "&IF(ISNUMBER(E33),TEXT(E33,"0.00"),E33)&IF(F33="",""," "&F33) -> Wq = none (ρ ≥ 1)
A35: 3. Biometric scanner at Central, 13:10–13:20 today (M/M/1)
A36: One scanner per mess: the simplest queue, a single server.
A37: Symbol | B37: Name | C37: What it means at the mess | D37: Formula | E37: Value | F37: Unit | G37: Reads as
A38: λ | B38: Arrival rate | C38: Students reaching the face scanner per minute | D38: counted in the simulation | E38: ='Sim Data'!$E$15 -> 29.56 | F38: students/min | G38: =A38&" = "&IF(ISNUMBER(E38),TEXT(E38,"0.0"),E38)&IF(F38="",""," "&F38) -> λ = 29.6 students/min
A39: μ | B39: Scan rate | C39: Students one scanner can handle per minute | D39: μ = 60 ÷ seconds per scan | E39: =60/Assumptions!$B$16 -> 30 | F39: students/min | G39: =A39&" = "&IF(ISNUMBER(E39),TEXT(E39,"0.0"),E39)&IF(F39="",""," "&F39) -> μ = 30.0 students/min
A40: ρ | B40: Utilisation | C40: Share of the time the scanner is busy | D40: ρ = λ ÷ μ | E40: =E38/E39 -> 0.98533333 | G40: =A40&" = "&IF(ISNUMBER(E40),TEXT(E40,"0%"),E40)&IF(F40="",""," "&F40) -> ρ = 99%
A41: Wq | B41: Wait (M/M/1) | C41: Textbook wait outside the door | D41: Wq = ρ ÷ (μ − λ) | E41: =IF(E40<1,E40/(E39-E38),"none (ρ ≥ 1)") -> 2.2393939 | F41: min | G41: =A41&" = "&IF(ISNUMBER(E41),TEXT(E41,"0.00"),E41)&IF(F41="",""," "&F41) -> Wq = 2.24 min
A42: cv | B42: Scan-time variability | C42: Real scans are regular, unlike the exponential times M/M/1 assumes | D42: assumed | E42: 0.3 | G42: =A42&" = "&IF(ISNUMBER(E42),TEXT(E42,"0.0"),E42)&IF(F42="",""," "&F42) -> cv = 0.3
A43: Wq M/G/1 | B43: Corrected wait | C43: Pollaczek–Khinchine correction for regular service | D43: Wq × (1 + cv²) ÷ 2 | E43: =IF(ISNUMBER(E41),E41*(1+E42^2)/2,"none") -> 1.2204697 | F43: min | G43: =A43&" = "&IF(ISNUMBER(E43),TEXT(E43,"0.00"),E43)&IF(F43="",""," "&F43) -> Wq M/G/1 = 1.22 min
...

Sheet Q1 Scanner
A1: Biometric scan: M/M/1
A2: M/M/1, one face scanner per mess. Arrivals, waits and line lengths are simulated; utilisation, stability and the textbook waits are formulas.
A4: Summary
A5: Scenario | B5: Mess | C5: Peak ρ | D5: Slots over | E5: Slots near | F5: Worst wait | G5: Avg wait
A6: Today (no screens) | B6: Central CT | C6: =_xlfn.MAXIFS($H$28:$H$99,$A$28:$A$99,"Today (no screens)",$B$28:$B$99,"Central CT") -> 0.984348 | D6: =COUNTIFS($A$28:$A$99,"Today (no screens)",$B$28:$B$99,"Central CT",$H$28:$H$99,">=1") -> 0 | E6: =COUNTIFS($A$28:$A$99,"Today (no screens)",$B$28:$B$99,"Central CT",$H$28:$H$99,">=0.85",$H$28:$H$99,"<1") -> 2 | F6: =_xlfn.MAXIFS($L$28:$L$99,$A$28:$A$99,"Today (no screens)",$B$28:$B$99,"Central CT") -> 0.3055 | G6: =SUMPRODUCT(($A$28:$A$99="Today (no screens)")*($B$28:$B$99="Central CT")*$L$28:$L$99*$D$28:$D$99)/SUMPRODUCT(($A$28:$A$99="Today (no screens)")*($B$28:$B$99="Central CT")*$D$28:$D$99) -> 0.1075207
A7: Today (no screens) | B7: Munch Mess | C7: =_xlfn.MAXIFS($H$28:$H$99,$A$28:$A$99,"Today (no screens)",$B$28:$B$99,"Munch Mess") -> 0.2490725 | D7: =COUNTIFS($A$28:$A$99,"Today (no screens)",$B$28:$B$99,"Munch Mess",$H$28:$H$99,">=1") -> 0 | E7: =COUNTIFS($A$28:$A$99,"Today (no screens)",$B$28:$B$99,"Munch Mess",$H$28:$H$99,">=0.85",$H$28:$H$99,"<1") -> 0 | F7: =_xlfn.MAXIFS($L$28:$L$99,$A$28:$A$99,"Today (no screens)",$B$28:$B$99,"Munch Mess") -> 0.0067 | G7: =SUMPRODUCT(($A$28:$A$99="Today (no screens)")*($B$28:$B$99="Munch Mess")*$L$28:$L$99*$D$28:$D$99)/SUMPRODUCT(($A$28:$A$99="Today (no screens)")*($B$28:$B$99="Munch Mess")*$D$28:$D$99) -> 0.0041760043
A8: With Smart Scan screens | B8: Central CT | C8: =_xlfn.MAXIFS($H$28:$H$99,$A$28:$A$99,"With Smart Scan screens",$B$28:$B$99,"Central CT") -> 0.7251075 | D8: =COUNTIFS($A$28:$A$99,"With Smart Scan screens",$B$28:$B$99,"Central CT",$H$28:$H$99,">=1") -> 0 | E8: =COUNTIFS($A$28:$A$99,"With Smart Scan screens",$B$28:$B$99,"Central CT",$H$28:$H$99,">=0.85",$H$28:$H$99,"<1") -> 0 | F8: =_xlfn.MAXIFS($L$28:$L$99,$A$28:$A$99,"With Smart Scan screens",$B$28:$B$99,"Central CT") -> 0.0696 | G8: =SUMPRODUCT(($A$28:$A$99="With Smart Scan screens")*($B$28:$B$99="Central CT")*$L$28:$L$99*$D$28:$D$99)/SUMPRODUCT(($A$28:$A$99="With Smart Scan screens")*($B$28:$B$99="Central CT")*$D$28:$D$99) -> 0.040671456
A9: With Smart Scan screens | B9: Munch Mess | C9: =_xlfn.MAXIFS($H$28:$H$99,$A$28:$A$99,"With Smart Scan screens",$B$28:$B$99,"Munch Mess") -> 0.534901 | D9: =COUNTIFS($A$28:$A$99,"With Smart Scan screens",$B$28:$B$99,"Munch Mess",$H$28:$H$99,">=1") -> 0 | E9: =COUNTIFS($A$28:$A$99,"With Smart Scan screens",$B$28:$B$99,"Munch Mess",$H$28:$H$99,">=0.85",$H$28:$H$99,"<1") -> 0 | F9: =_xlfn.MAXIFS($L$28:$L$99,$A$28:$A$99,"With Smart Scan screens",$B$28:$B$99,"Munch Mess") -> 0.0349 | G9: =SUMPRODUCT(($A$28:$A$99="With Smart Scan screens")*($B$28:$B$99="Munch Mess")*$L$28:$L$99*$D$28:$D$99)/SUMPRODUCT(($A$28:$A$99="With Smart Scan screens")*($B$28:$B$99="Munch Mess")*$D$28:$D$99) -> 0.016213995
A10: Slots over = ρ ≥ 100% · slots near = 85–100% · waits in minutes (simulated)
A12: Takeaway: One scanner per mess handles about 30 students a minute. It keeps up all lunch, though Central's scanner gets close (about 98% busy) in the 13:10 surge. Real scans are steadier than M/M/1 assumes, so the corrected wait sits closer to the simulation. Anyone queueing here is still outside the door, so the live system cannot see them yet.
A20: In the table below: red = over capacity (the line keeps growing), amber = near capacity (waits rise steeply).
A26: Slot by slot (filter by scenario or mess)
A27: Scenario | B27: Mess | C27: Slot | D27: λ (/min) | E27: Service time (min) | F27: μ (/min) | G27: c | H27: ρ | I27: Stable? | J27: Wq textbook (min) | K27: Wq corrected for cv (min) | L27: Wq simulated (min) | M27: Lq simulated | N27: λ × Wq simulated | O27: Little's Law: Lq ÷ λWq | P27: What it means
A28: Today (no screens) | B28: Central CT | C28: 11:30 | D28: ='Sim Data'!$E$5 -> 0 | E28: ='Sim Data'!$G$5 -> 0 | F28: =IF(E28>0,1/E28,60/Assumptions!$B$16) -> 30 | G28: =Assumptions!$B$15 -> 1 | H28: =D28/(G28*F28) -> 0 | I28: =IF(D28=0,"no arrivals",IF(H28<0.85,"stable",IF(H28<1,"near capacity","over capacity"))) -> no arrivals | J28: =IF(AND(D28>0,H28<1),H28/(F28-D28),"—") -> — | K28: =IF(ISNUMBER(J28),(1+0.3^2)/2*J28,"—") -> — | L28: ='Sim Data'!$F$5 -> 0 | M28: ='Sim Data'!$H$5 -> 0 | N28: =D28*L28 -> 0 | O28: =IF(MAX(M28,N28)<0.5,"both ≈ 0",IF(N28=0,"no new arrivals",M28/N28)) -> both ≈ 0 | P28: =IF(D28=0,"",IF(H28>=1,"No steady state: the line grows by about "&TEXT((D28-G28*F28)*10,"0")&" in 10 min",IF(ISNUMBER(O28),IF(ABS(O28-1)<=0.2,"Steady: Little's Law holds",IF(O28>1,"Draining a line left from earlier","Line still building")),"Hardly any line")))
A29: Today (no screens) | B29: Central CT | C29: 11:40 | D29: ='Sim Data'!$E$6 -> 0 | E29: ='Sim Data'!$G$6 -> 0 | F29: =IF(E29>0,1/E29,60/Assumptions!$B$16) -> 30 | G29: =Assumptions!$B$15 -> 1 | H29: =D29/(G29*F29) -> 0 | I29: =IF(D29=0,"no arrivals",IF(H29<0.85,"stable",IF(H29<1,"near capacity","over capacity"))) -> no arrivals | J29: =IF(AND(D29>0,H29<1),H29/(F29-D29),"—") -> — | K29: =IF(ISNUMBER(J29),(1+0.3^2)/2*J29,"—") -> — | L29: ='Sim Data'!$F$6 -> 0 | M29: ='Sim Data'!$H$6 -> 0 | N29: =D29*L29 -> 0 | O29: =IF(MAX(M29,N29)<0.5,"both ≈ 0",IF(N29=0,"no new arrivals",M29/N29)) -> both ≈ 0 | P29: =IF(D29=0,"",IF(H29>=1,"No steady state: the line grows by about "&TEXT((D29-G29*F29)*10,"0")&" in 10 min",IF(ISNUMBER(O29),IF(ABS(O29-1)<=0.2,"Steady: Little's Law holds",IF(O29>1,"Draining a line left from earlier","Line still building")),"Hardly any line")))
A30: Today (no screens) | B30: Central CT | C30: 11:50 | D30: ='Sim Data'!$E$7 -> 0 | E30: ='Sim Data'!$G$7 -> 0 | F30: =IF(E30>0,1/E30,60/Assumptions!$B$16) -> 30 | G30: =Assumptions!$B$15 -> 1 | H30: =D30/(G30*F30) -> 0 | I30: =IF(D30=0,"no arrivals",IF(H30<0.85,"stable",IF(H30<1,"near capacity","over capacity"))) -> no arrivals | J30: =IF(AND(D30>0,H30<1),H30/(F30-D30),"—") -> — | K30: =IF(ISNUMBER(J30),(1+0.3^2)/2*J30,"—") -> — | L30: ='Sim Data'!$F$7 -> 0 | M30: ='Sim Data'!$H$7 -> 0 | N30: =D30*L30 -> 0 | O30: =IF(MAX(M30,N30)<0.5,"both ≈ 0",IF(N30=0,"no new arrivals",M30/N30)) -> both ≈ 0 | P30: =IF(D30=0,"",IF(H30>=1,"No steady state: the line grows by about "&TEXT((D30-G30*F30)*10,"0")&" in 10 min",IF(ISNUMBER(O30),IF(ABS(O30-1)<=0.2,"Steady: Little's Law holds",IF(O30>1,"Draining a line left from earlier","Line still building")),"Hardly any line")))
A31: Today (no screens) | B31: Central CT | C31: 12:00 | D31: ='Sim Data'!$E$8 -> 14.52 | E31: ='Sim Data'!$G$8 -> 0.0335 | F31: =IF(E31>0,1/E31,60/Assumptions!$B$16) -> 29.850746 | G31: =Assumptions!$B$15 -> 1 | H31: =D31/(G31*F31) -> 0.48642 | I31: =IF(D31=0,"no arrivals",IF(H31<0.85,"stable",IF(H31<1,"near capacity","over capacity"))) -> stable | J31: =IF(AND(D31>0,H31<1),H31/(F31-D31),"—") -> 0.031728397 | K31: =IF(ISNUMBER(J31),(1+0.3^2)/2*J31,"—") -> 0.017291976 | L31: ='Sim Data'!$F$8 -> 0.0195 | M31: ='Sim Data'!$H$8 -> 0.2811 | N31: =D31*L31 -> 0.28314 | O31: =IF(MAX(M31,N31)<0.5,"both ≈ 0",IF(N31=0,"no new arrivals",M31/N31)) -> both ≈ 0 | P31: =IF(D31=0,"",IF(H31>=1,"No steady state: the line grows by about "&TEXT((D31-G31*F31)*10,"0")&" in 10 min",IF(ISNUMBER(O31),IF(ABS(O31-1)<=0.2,"Steady: Little's Law holds",IF(O31>1,"Draining a line left from earlier","Line still building")),"Hardly any line"))) -> Hardly any line
A32: Today (no screens) | B32: Central CT | C32: 12:10 | D32: ='Sim Data'!$E$9 -> 18.77 | E32: ='Sim Data'!$G$9 -> 0.0333 | F32: =IF(E32>0,1/E32,60/Assumptions!$B$16) -> 30.03003 | G32: =Assumptions!$B$15 -> 1 | H32: =D32/(G32*F32) -> 0.625041 | I32: =IF(D32=0,"no arrivals",IF(H32<0.85,"stable",IF(H32<1,"near capacity","over capacity"))) -> stable | J32: =IF(AND(D32>0,H32<1),H32/(F32-D32),"—") -> 0.05550971 | K32: =IF(ISNUMBER(J32),(1+0.3^2)/2*J32,"—") -> 0.030252792 | L32: ='Sim Data'!$F$9 -> 0.0272 | M32: ='Sim Data'!$H$9 -> 0.5063 | N32: =D32*L32 -> 0.510544 | O32: =IF(MAX(M32,N32)<0.5,"both ≈ 0",IF(N32=0,"no new arrivals",M32/N32)) -> 0.9916873 | P32: =IF(D32=0,"",IF(H32>=1,"No steady state: the line grows by about "&TEXT((D32-G32*F32)*10,"0")&" in 10 min",IF(ISNUMBER(O32),IF(ABS(O32-1)<=0.2,"Steady: Little's Law holds",IF(O32>1,"Draining a line left from earlier","Line still building")),"Hardly any line"))) -> Steady: Little's Law holds
A33: Today (no screens) | B33: Central CT | C33: 12:20 | D33: ='Sim Data'!$E$10 -> 18.825 | E33: ='Sim Data'!$G$10 -> 0.0335 | F33: =IF(E33>0,1/E33,60/Assumptions!$B$16) -> 29.850746 | G33: =Assumptions!$B$15 -> 1 | H33: =D33/(G33*F33) -> 0.6306375 | I33: =IF(D33=0,"no arrivals",IF(H33<0.85,"stable",IF(H33<1,"near capacity","over capacity"))) -> stable | J33: =IF(AND(D33>0,H33<1),H33/(F33-D33),"—") -> 0.057196809 | K33: =IF(ISNUMBER(J33),(1+0.3^2)/2*J33,"—") -> 0.031172261 | L33: ='Sim Data'!$F$10 -> 0.037 | M33: ='Sim Data'!$H$10 -> 0.701 | N33: =D33*L33 -> 0.696525 | O33: =IF(MAX(M33,N33)<0.5,"both ≈ 0",IF(N33=0,"no new arrivals",M33/N33)) -> 1.0064248 | P33: =IF(D33=0,"",IF(H33>=1,"No steady state: the line grows by about "&TEXT((D33-G33*F33)*10,"0")&" in 10 min",IF(ISNUMBER(O33),IF(ABS(O33-1)<=0.2,"Steady: Little's Law holds",IF(O33>1,"Draining a line left from earlier","Line still building")),"Hardly any line"))) -> Steady: Little's Law holds
A34: Today (no screens) | B34: Central CT | C34: 12:30 | D34: ='Sim Data'!$E$11 -> 22.915 | E34: ='Sim Data'!$G$11 -> 0.0335 | F34: =IF(E34>0,1/E34,60/Assumptions!$B$16) -> 29.850746 | G34: =Assumptions!$B$15 -> 1 | H34: =D34/(G34*F34) -> 0.7676525 | I34: =IF(D34=0,"no arrivals",IF(H34<0.85,"stable",IF(H34<1,"near capacity","over capacity"))) -> stable | J34: =IF(AND(D34>0,H34<1),H34/(F34-D34),"—") -> 0.11068059 | K34: =IF(ISNUMBER(J34),(1+0.3^2)/2*J34,"—") -> 0.060320922 | L34: ='Sim Data'!$F$11 -> 0.068 | M34: ='Sim Data'!$H$11 -> 1.5535 | N34: =D34*L34 -> 1.55822 | O34: =IF(MAX(M34,N34)<0.5,"both ≈ 0",IF(N34=0,"no new arrivals",M34/N34)) -> 0.9969709 | P34: =IF(D34=0,"",IF(H34>=1,"No steady state: the line grows by about "&TEXT((D34-G34*F34)*10,"0")&" in 10 min",IF(ISNUMBER(O34),IF(ABS(O34-1)<=0.2,"Steady: Little's Law holds",IF(O34>1,"Draining a line left from earlier","Line still building")),"Hardly any line"))) -> Steady: Little's Law holds
A35: Today (no screens) | B35: Central CT | C35: 12:40 | D35: ='Sim Data'!$E$12 -> 20.35 | E35: ='Sim Data'!$G$12 -> 0.0334 | F35: =IF(E35>0,1/E35,60/Assumptions!$B$16) -> 29.94012 | G35: =Assumptions!$B$15 -> 1 | H35: =D35/(G35*F35) -> 0.67969 | I35: =IF(D35=0,"no arrivals",IF(H35<0.85,"stable",IF(H35<1,"near capacity","over capacity"))) -> stable | J35: =IF(AND(D35>0,H35<1),H35/(F35-D35),"—") -> 0.070873985 | K35: =IF(ISNUMBER(J35),(1+0.3^2)/2*J35,"—") -> 0.038626322 | L35: ='Sim Data'!$F$12 -> 0.0399 | M35: ='Sim Data'!$H$12 -> 0.8137 | N35: =D35*L35 -> 0.811965 | O35: =IF(MAX(M35,N35)<0.5,"both ≈ 0",IF(N35=0,"no new arrivals",M35/N35)) -> 1.0021368 | P35: =IF(D35=0,"",IF(H35>=1,"No steady state: the line grows by about "&TEXT((D35-G35*F35)*10,"0")&" in 10 min",IF(ISNUMBER(O35),IF(ABS(O35-1)<=0.2,"Steady: Little's Law holds",IF(O35>1,"Draining a line left from earlier","Line still building")),"Hardly any line"))) -> Steady: Little's Law holds
A36: Today (no screens) | B36: Central CT | C36: 12:50 | D36: ='Sim Data'!$E$13 -> 16.86 | E36: ='Sim Data'!$G$13 -> 0.0334 | F36: =IF(E36>0,1/E36,60/Assumptions!$B$16) -> 29.94012 | G36: =Assumptions!$B$15 -> 1 | H36: =D36/(G36*F36) -> 0.563124 | I36: =IF(D36=0,"no arrivals",IF(H36<0.85,"stable",IF(H36<1,"near capacity","over capacity"))) -> stable | J36: =IF(AND(D36>0,H36<1),H36/(F36-D36),"—") -> 0.043051899 | K36: =IF(ISNUMBER(J36),(1+0.3^2)/2*J36,"—") -> 0.023463285 | L36: ='Sim Data'!$F$13 -> 0.0222 | M36: ='Sim Data'!$H$13 -> 0.3785 | N36: =D36*L36 -> 0.374292 | O36: =IF(MAX(M36,N36)<0.5,"both ≈ 0",IF(N36=0,"no new arrivals",M36/N36)) -> both ≈ 0 | P36: =IF(D36=0,"",IF(H36>=1,"No steady state: the line grows by about "&TEXT((D36-G36*F36)*10,"0")&" in 10 min",IF(ISNUMBER(O36),IF(ABS(O36-1)<=0.2,"Steady: Little's Law holds",IF(O36>1,"Draining a line left from earlier","Line still building")),"Hardly any line"))) -> Hardly any line
A37: Today (no screens) | B37: Central CT | C37: 13:00 | D37: ='Sim Data'!$E$14 -> 22.705 | E37: ='Sim Data'!$G$14 -> 0.0333 | F37: =IF(E37>0,1/E37,60/Assumptions!$B$16) -> 30.03003 | G37: =Assumptions!$B$15 -> 1 | H37: =D37/(G37*F37) -> 0.7560765 | I37: =IF(D37=0,"no arrivals",IF(H37<0.85,"stable",IF(H37<1,"near capacity","over capacity"))) -> stable | J37: =IF(AND(D37>0,H37<1),H37/(F37-D37),"—") -> 0.10321821 | K37: =IF(ISNUMBER(J37),(1+0.3^2)/2*J37,"—") -> 0.056253925 | L37: ='Sim Data'!$F$14 -> 0.0897 | M37: ='Sim Data'!$H$14 -> 1.9655 | N37: =D37*L37 -> 2.0366385 | O37: =IF(MAX(M37,N37)<0.5,"both ≈ 0",IF(N37=0,"no new arrivals",M37/N37)) -> 0.96507063 | P37: =IF(D37=0,"",IF(H37>=1,"No steady state: the line grows by about "&TEXT((D37-G37*F37)*10,"0")&" in 10 min",IF(ISNUMBER(O37),IF(ABS(O37-1)<=0.2,"Steady: Little's Law holds",IF(O37>1,"Draining a line left from earlier","Line still building")),"Hardly any line"))) -> Steady: Little's Law holds
A38: Today (no screens) | B38: Central CT | C38: 13:10 | D38: ='Sim Data'!$E$15 -> 29.56 | E38: ='Sim Data'!$G$15 -> 0.0333 | F38: =IF(E38>0,1/E38,60/Assumptions!$B$16) -> 30.03003 | G38: =Assumptions!$B$15 -> 1 | H38: =D38/(G38*F38) -> 0.984348 | I38: =IF(D38=0,"no arrivals",IF(H38<0.85,"stable",IF(H38<1,"near capacity","over capacity"))) -> near capacity | J38: =IF(AND(D38>0,H38<1),H38/(F38-D38),"—") -> 2.0942236 | K38: =IF(ISNUMBER(J38),(1+0.3^2)/2*J38,"—") -> 1.1413519 | L38: ='Sim Data'!$F$15 -> 0.3055 | M38: ='Sim Data'!$H$15 -> 8.9063 | N38: =D38*L38 -> 9.03058 | O38: =IF(MAX(M38,N38)<0.5,"both ≈ 0",IF(N38=0,"no new arrivals",M38/N38)) -> 0.98623787 | P38: =IF(D38=0,"",IF(H38>=1,"No steady state: the line grows by about "&TEXT((D38-G38*F38)*10,"0")&" in 10 min",IF(ISNUMBER(O38),IF(ABS(O38-1)<=0.2,"Steady: Little's Law holds",IF(O38>1,"Draining a line left from earlier","Line still building")),"Hardly any line"))) -> Steady: Little's Law holds
A39: Today (no screens) | B39: Central CT | C39: 13:20 | D39: ='Sim Data'!$E$16 -> 28.33 | E39: ='Sim Data'!$G$16 -> 0.0332 | F39: =IF(E39>0,1/E39,60/Assumptions!$B$16) -> 30.120482 | G39: =Assumptions!$B$15 -> 1 | H39: =D39/(G39*F39) -> 0.940556 | I39: =IF(D39=0,"no arrivals",IF(H39<0.85,"stable",IF(H39<1,"near capacity","over capacity"))) -> near capacity | J39: =IF(AND(D39>0,H39<1),H39/(F39-D39),"—") -> 0.52530885 | K39: =IF(ISNUMBER(J39),(1+0.3^2)/2*J39,"—") -> 0.28629332 | L39: ='Sim Data'!$F$16 -> 0.3 | M39: ='Sim Data'!$H$16 -> 8.6 | N39: =D39*L39 -> 8.499 | O39: =IF(MAX(M39,N39)<0.5,"both ≈ 0",IF(N39=0,"no new arrivals",M39/N39)) -> 1.0118838 | P39: =IF(D39=0,"",IF(H39>=1,"No steady state: the line grows by about "&TEXT((D39-G39*F39)*10,"0")&" in 10 min",IF(ISNUMBER(O39),IF(ABS(O39-1)<=0.2,"Steady: Little's Law holds",IF(O39>1,"Draining a line left from earlier","Line still building")),"Hardly any line"))) -> Steady: Little's Law holds
A40: Today (no screens) | B40: Central CT | C40: 13:30 | D40: ='Sim Data'!$E$17 -> 21.35 | E40: ='Sim Data'!$G$17 -> 0.0334 | F40: =IF(E40>0,1/E40,60/Assumptions!$B$16) -> 29.94012 | G40: =Assumptions!$B$15 -> 1 | H40: =D40/(G40*F40) -> 0.71309 | I40: =IF(D40=0,"no arrivals",IF(H40<0.85,"stable",IF(H40<1,"near capacity","over capacity"))) -> stable | J40: =IF(AND(D40>0,H40<1),H40/(F40-D40),"—") -> 0.083012812 | K40: =IF(ISNUMBER(J40),(1+0.3^2)/2*J40,"—") -> 0.045241983 | L40: ='Sim Data'!$F$17 -> 0.059 | M40: ='Sim Data'!$H$17 -> 1.3529 | N40: =D40*L40 -> 1.25965 | O40: =IF(MAX(M40,N40)<0.5,"both ≈ 0",IF(N40=0,"no new arrivals",M40/N40)) -> 1.0740285 | P40: =IF(D40=0,"",IF(H40>=1,"No steady state: the line grows by about "&TEXT((D40-G40*F40)*10,"0")&" in 10 min",IF(ISNUMBER(O40),IF(ABS(O40-1)<=0.2,"Steady: Little's Law holds",IF(O40>1,"Draining a line left from earlier","Line still building")),"Hardly any line"))) -> Steady: Little's Law holds
A41: Today (no screens) | B41: Central CT | C41: 13:40 | D41: ='Sim Data'!$E$18 -> 14.575 | E41: ='Sim Data'!$G$18 -> 0.0333 | F41: =IF(E41>0,1/E41,60/Assumptions!$B$16) -> 30.03003 | G41: =Assumptions!$B$15 -> 1 | H41: =D41/(G41*F41) -> 0.4853475 | I41: =IF(D41=0,"no arrivals",IF(H41<0.85,"stable",IF(H41<1,"near capacity","over capacity"))) -> stable | J41: =IF(AND(D41>0,H41<1),H41/(F41-D41),"—") -> 0.031403854 | K41: =IF(ISNUMBER(J41),(1+0.3^2)/2*J41,"—") -> 0.0171151 | L41: ='Sim Data'!$F$18 -> 0.018 | M41: ='Sim Data'!$H$18 -> 0.263 | N41: =D41*L41 -> 0.26235 | O41: =IF(MAX(M41,N41)<0.5,"both ≈ 0",IF(N41=0,"no new arrivals",M41/N41)) -> both ≈ 0 | P41: =IF(D41=0,"",IF(H41>=1,"No steady state: the line grows by about "&TEXT((D41-G41*F41)*10,"0")&" in 10 min",IF(ISNUMBER(O41),IF(ABS(O41-1)<=0.2,"Steady: Little's Law holds",IF(O41>1,"Draining a line left from earlier","Line still building")),"Hardly any line"))) -> Hardly any line
A42: Today (no screens) | B42: Central CT | C42: 13:50 | D42: ='Sim Data'!$E$19 -> 7.17 | E42: ='Sim Data'!$G$19 -> 0.0333 | F42: =IF(E42>0,1/E42,60/Assumptions!$B$16) -> 30.03003 | G42: =Assumptions!$B$15 -> 1 | H42: =D42/(G42*F42) -> 0.238761 | I42: =IF(D42=0,"no arrivals",IF(H42<0.85,"stable",IF(H42<1,"near capacity","over capacity"))) -> stable | J42: =IF(AND(D42>0,H42<1),H42/(F42-D42),"—") -> 0.010444474 | K42: =IF(ISNUMBER(J42),(1+0.3^2)/2*J42,"—") -> 0.0056922386 | L42: ='Sim Data'!$F$19 -> 0.0062 | M42: ='Sim Data'!$H$19 -> 0.0447 | N42: =D42*L42 -> 0.044454 | O42: =IF(MAX(M42,N42)<0.5,"both ≈ 0",IF(N42=0,"no new arrivals",M42/N42)) -> both ≈ 0 | P42: =IF(D42=0,"",IF(H42>=1,"No steady state: the line grows by about "&TEXT((D42-G42*F42)*10,"0")&" in 10 min",IF(ISNUMBER(O42),IF(ABS(O42-1)<=0.2,"Steady: Little's Law holds",IF(O42>1,"Draining a line left from earlier","Line still building")),"Hardly any line"))) -> Hardly any line
A43: Today (no screens) | B43: Central CT | C43: 14:00 | D43: ='Sim Data'!$E$20 -> 0 | E43: ='Sim Data'!$G$20 -> 0 | F43: =IF(E43>0,1/E43,60/Assumptions!$B$16) -> 30 | G43: =Assumptions!$B$15 -> 1 | H43: =D43/(G43*F43) -> 0 | I43: =IF(D43=0,"no arrivals",IF(H43<0.85,"stable",IF(H43<1,"near capacity","over capacity"))) -> no arrivals | J43: =IF(AND(D43>0,H43<1),H43/(F43-D43),"—") -> — | K43: =IF(ISNUMBER(J43),(1+0.3^2)/2*J43,"—") -> — | L43: ='Sim Data'!$F$20 -> 0 | M43: ='Sim Data'!$H$20 -> 0 | N43: =D43*L43 -> 0 | O43: =IF(MAX(M43,N43)<0.5,"both ≈ 0",IF(N43=0,"no new arrivals",M43/N43)) -> both ≈ 0 | P43: =IF(D43=0,"",IF(H43>=1,"No steady state: the line grows by about "&TEXT((D43-G43*F43)*10,"0")&" in 10 min",IF(ISNUMBER(O43),IF(ABS(O43-1)<=0.2,"Steady: Little's Law holds",IF(O43>1,"Draining a line left from earlier","Line still building")),"Hardly any line")))
A44: Today (no screens) | B44: Central CT | C44: 14:10 | D44: ='Sim Data'!$E$21 -> 0 | E44: ='Sim Data'!$G$21 -> 0 | F44: =IF(E44>0,1/E44,60/Assumptions!$B$16) -> 30 | G44: =Assumptions!$B$15 -> 1 | H44: =D44/(G44*F44) -> 0 | I44: =IF(D44=0,"no arrivals",IF(H44<0.85,"stable",IF(H44<1,"near capacity","over capacity"))) -> no arrivals | J44: =IF(AND(D44>0,H44<1),H44/(F44-D44),"—") -> — | K44: =IF(ISNUMBER(J44),(1+0.3^2)/2*J44,"—") -> — | L44: ='Sim Data'!$F$21 -> 0 | M44: ='Sim Data'!$H$21 -> 0 | N44: =D44*L44 -> 0 | O44: =IF(MAX(M44,N44)<0.5,"both ≈ 0",IF(N44=0,"no new arrivals",M44/N44)) -> both ≈ 0 | P44: =IF(D44=0,"",IF(H44>=1,"No steady state: the line grows by about "&TEXT((D44-G44*F44)*10,"0")&" in 10 min",IF(ISNUMBER(O44),IF(ABS(O44-1)<=0.2,"Steady: Little's Law holds",IF(O44>1,"Draining a line left from earlier","Line still building")),"Hardly any line")))
A45: Today (no screens) | B45: Central CT | C45: 14:20 | D45: ='Sim Data'!$E$22 -> 0 | E45: ='Sim Data'!$G$22 -> 0 | F45: =IF(E45>0,1/E45,60/Assumptions!$B$16) -> 30 | G45: =Assumptions!$B$15 -> 1 | H45: =D45/(G45*F45) -> 0 | I45: =IF(D45=0,"no arrivals",IF(H45<0.85,"stable",IF(H45<1,"near capacity","over capacity"))) -> no arrivals | J45: =IF(AND(D45>0,H45<1),H45/(F45-D45),"—") -> — | K45: =IF(ISNUMBER(J45),(1+0.3^2)/2*J45,"—") -> — | L45: ='Sim Data'!$F$22 -> 0 | M45: ='Sim Data'!$H$22 -> 0 | N45: =D45*L45 -> 0 | O45: =IF(MAX(M45,N45)<0.5,"both ≈ 0",IF(N45=0,"no new arrivals",M45/N45)) -> both ≈ 0 | P45: =IF(D45=0,"",IF(H45>=1,"No steady state: the line grows by about "&TEXT((D45-G45*F45)*10,"0")&" in 10 min",IF(ISNUMBER(O45),IF(ABS(O45-1)<=0.2,"Steady: Little's Law holds",IF(O45>1,"Draining a line left from earlier","Line still building")),"Hardly any line")))
A46: Today (no screens) | B46: Munch Mess | C46: 11:30 | D46: ='Sim Data'!$E$95 -> 0 | E46: ='Sim Data'!$G$95 -> 0 | F46: =IF(E46>0,1/E46,60/Assumptions!$B$16) -> 30 | G46: =Assumptions!$B$15 -> 1 | H46: =D46/(G46*F46) -> 0 | I46: =IF(D46=0,"no arrivals",IF(H46<0.85,"stable",IF(H46<1,"near capacity","over capacity"))) -> no arrivals | J46: =IF(AND(D46>0,H46<1),H46/(F46-D46),"—") -> — | K46: =IF(ISNUMBER(J46),(1+0.3^2)/2*J46,"—") -> — | L46: ='Sim Data'!$F$95 -> 0 | M46: ='Sim Data'!$H$95 -> 0 | N46: =D46*L46 -> 0 | O46: =IF(MAX(M46,N46)<0.5,"both ≈ 0",IF(N46=0,"no new arrivals",M46/N46)) -> both ≈ 0 | P46: =IF(D46=0,"",IF(H46>=1,"No steady state: the line grows by about "&TEXT((D46-G46*F46)*10,"0")&" in 10 min",IF(ISNUMBER(O46),IF(ABS(O46-1)<=0.2,"Steady: Little's Law holds",IF(O46>1,"Draining a line left from earlier","Line still building")),"Hardly any line")))
A47: Today (no screens) | B47: Munch Mess | C47: 11:40 | D47: ='Sim Data'!$E$96 -> 0 | E47: ='Sim Data'!$G$96 -> 0 | F47: =IF(E47>0,1/E47,60/Assumptions!$B$16) -> 30 | G47: =Assumptions!$B$15 -> 1 | H47: =D47/(G47*F47) -> 0 | I47: =IF(D47=0,"no arrivals",IF(H47<0.85,"stable",IF(H47<1,"near capacity","over capacity"))) -> no arrivals | J47: =IF(AND(D47>0,H47<1),H47/(F47-D47),"—") -> — | K47: =IF(ISNUMBER(J47),(1+0.3^2)/2*J47,"—") -> — | L47: ='Sim Data'!$F$96 -> 0 | M47: ='Sim Data'!$H$96 -> 0 | N47: =D47*L47 -> 0 | O47: =IF(MAX(M47,N47)<0.5,"both ≈ 0",IF(N47=0,"no new arrivals",M47/N47)) -> both ≈ 0 | P47: =IF(D47=0,"",IF(H47>=1,"No steady state: the line grows by about "&TEXT((D47-G47*F47)*10,"0")&" in 10 min",IF(ISNUMBER(O47),IF(ABS(O47-1)<=0.2,"Steady: Little's Law holds",IF(O47>1,"Draining a line left from earlier","Line still building")),"Hardly any line")))
A48: Today (no screens) | B48: Munch Mess | C48: 11:50 | D48: ='Sim Data'!$E$97 -> 0 | E48: ='Sim Data'!$G$97 -> 0 | F48: =IF(E48>0,1/E48,60/Assumptions!$B$16) -> 30 | G48: =Assumptions!$B$15 -> 1 | H48: =D48/(G48*F48) -> 0 | I48: =IF(D48=0,"no arrivals",IF(H48<0.85,"stable",IF(H48<1,"near capacity","over capacity"))) -> no arrivals | J48: =IF(AND(D48>0,H48<1),H48/(F48-D48),"—") -> — | K48: =IF(ISNUMBER(J48),(1+0.3^2)/2*J48,"—") -> — | L48: ='Sim Data'!$F$97 -> 0 | M48: ='Sim Data'!$H$97 -> 0 | N48: =D48*L48 -> 0 | O48: =IF(MAX(M48,N48)<0.5,"both ≈ 0",IF(N48=0,"no new arrivals",M48/N48)) -> both ≈ 0 | P48: =IF(D48=0,"",IF(H48>=1,"No steady state: the line grows by about "&TEXT((D48-G48*F48)*10,"0")&" in 10 min",IF(ISNUMBER(O48),IF(ABS(O48-1)<=0.2,"Steady: Little's Law holds",IF(O48>1,"Draining a line left from earlier","Line still building")),"Hardly any line")))
A49: Today (no screens) | B49: Munch Mess | C49: 12:00 | D49: ='Sim Data'!$E$98 -> 3.88 | E49: ='Sim Data'!$G$98 -> 0.0333 | F49: =IF(E49>0,1/E49,60/Assumptions!$B$16) -> 30.03003 | G49: =Assumptions!$B$15 -> 1 | H49: =D49/(G49*F49) -> 0.129204 | I49: =IF(D49=0,"no arrivals",IF(H49<0.85,"stable",IF(H49<1,"near capacity","over capacity"))) -> stable | J49: =IF(AND(D49>0,H49<1),H49/(F49-D49),"—") -> 0.0049408739 | K49: =IF(ISNUMBER(J49),(1+0.3^2)/2*J49,"—") -> 0.0026927763 | L49: ='Sim Data'!$F$98 -> 0.003 | M49: ='Sim Data'!$H$98 -> 0.0117 | N49: =D49*L49 -> 0.01164 | O49: =IF(MAX(M49,N49)<0.5,"both ≈ 0",IF(N49=0,"no new arrivals",M49/N49)) -> both ≈ 0 | P49: =IF(D49=0,"",IF(H49>=1,"No steady state: the line grows by about "&TEXT((D49-G49*F49)*10,"0")&" in 10 min",IF(ISNUMBER(O49),IF(ABS(O49-1)<=0.2,"Steady: Little's Law holds",IF(O49>1,"Draining a line left from earlier","Line still building")),"Hardly any line"))) -> Hardly any line
A50: Today (no screens) | B50: Munch Mess | C50: 12:10 | D50: ='Sim Data'!$E$99 -> 4.64 | E50: ='Sim Data'!$G$99 -> 0.0334 | F50: =IF(E50>0,1/E50,60/Assumptions!$B$16) -> 29.94012 | G50: =Assumptions!$B$15 -> 1 | H50: =D50/(G50*F50) -> 0.154976 | I50: =IF(D50=0,"no arrivals",IF(H50<0.85,"stable",IF(H50<1,"near capacity","over capacity"))) -> stable | J50: =IF(AND(D50>0,H50<1),H50/(F50-D50),"—") -> 0.0061255046 | K50: =IF(ISNUMBER(J50),(1+0.3^2)/2*J50,"—") -> 0.0033384 | L50: ='Sim Data'!$F$99 -> 0.003 | M50: ='Sim Data'!$H$99 -> 0.0138 | N50: =D50*L50 -> 0.01392 | O50: =IF(MAX(M50,N50)<0.5,"both ≈ 0",IF(N50=0,"no new arrivals",M50/N50)) -> both ≈ 0 | P50: =IF(D50=0,"",IF(H50>=1,"No steady state: the line grows by about "&TEXT((D50-G50*F50)*10,"0")&" in 10 min",IF(ISNUMBER(O50),IF(ABS(O50-1)<=0.2,"Steady: Little's Law holds",IF(O50>1,"Draining a line left from earlier","Line still building")),"Hardly any line"))) -> Hardly any line
A51: Today (no screens) | B51: Munch Mess | C51: 12:20 | D51: ='Sim Data'!$E$100 -> 4.78 | E51: ='Sim Data'!$G$100 -> 0.0338 | F51: =IF(E51>0,1/E51,60/Assumptions!$B$16) -> 29.585799 | G51: =Assumptions!$B$15 -> 1 | H51: =D51/(G51*F51) -> 0.161564 | I51: =IF(D51=0,"no arrivals",IF(H51<0.85,"stable",IF(H51<1,"near capacity","over capacity"))) -> stable | J51: =IF(AND(D51>0,H51<1),H51/(F51-D51),"—") -> 0.0065131545 | K51: =IF(ISNUMBER(J51),(1+0.3^2)/2*J51,"—") -> 0.0035496692 | L51: ='Sim Data'!$F$100 -> 0.0039 | M51: ='Sim Data'!$H$100 -> 0.0188 | N51: =D51*L51 -> 0.018642 | O51: =IF(MAX(M51,N51)<0.5,"both ≈ 0",IF(N51=0,"no new arrivals",M51/N51)) -> both ≈ 0 | P51: =IF(D51=0,"",IF(H51>=1,"No steady state: the line grows by about "&TEXT((D51-G51*F51)*10,"0")&" in 10 min",IF(ISNUMBER(O51),IF(ABS(O51-1)<=0.2,"Steady: Little's Law holds",IF(O51>1,"Draining a line left from earlier","Line still building")),"Hardly any line"))) -> Hardly any line
A52: Today (no screens) | B52: Munch Mess | C52: 12:30 | D52: ='Sim Data'!$E$101 -> 5.73 | E52: ='Sim Data'!$G$101 -> 0.0338 | F52: =IF(E52>0,1/E52,60/Assumptions!$B$16) -> 29.585799 | G52: =Assumptions!$B$15 -> 1 | H52: =D52/(G52*F52) -> 0.193674 | I52: =IF(D52=0,"no arrivals",IF(H52<0.85,"stable",IF(H52<1,"near capacity","over capacity"))) -> stable | J52: =IF(AND(D52>0,H52<1),H52/(F52-D52),"—") -> 0.0081185292 | K52: =IF(ISNUMBER(J52),(1+0.3^2)/2*J52,"—") -> 0.0044245984 | L52: ='Sim Data'!$F$101 -> 0.0044 | M52: ='Sim Data'!$H$101 -> 0.0254 | N52: =D52*L52 -> 0.025212 | O52: =IF(MAX(M52,N52)<0.5,"both ≈ 0",IF(N52=0,"no new arrivals",M52/N52)) -> both ≈ 0 | P52: =IF(D52=0,"",IF(H52>=1,"No steady state: the line grows by about "&TEXT((D52-G52*F52)*10,"0")&" in 10 min",IF(ISNUMBER(O52),IF(ABS(O52-1)<=0.2,"Steady: Little's Law holds",IF(O52>1,"Draining a line left from earlier","Line still building")),"Hardly any line"))) -> Hardly any line
A53: Today (no screens) | B53: Munch Mess | C53: 12:40 | D53: ='Sim Data'!$E$102 -> 5.36 | E53: ='Sim Data'!$G$102 -> 0.0336 | F53: =IF(E53>0,1/E53,60/Assumptions!$B$16) -> 29.761905 | G53: =Assumptions!$B$15 -> 1 | H53: =D53/(G53*F53) -> 0.180096 | I53: =IF(D53=0,"no arrivals",IF(H53<0.85,"stable",IF(H53<1,"near capacity","over capacity"))) -> stable | J53: =IF(AND(D53>0,H53<1),H53/(F53-D53),"—") -> 0.0073804075 | K53: =IF(ISNUMBER(J53),(1+0.3^2)/2*J53,"—") -> 0.0040223221 | L53: ='Sim Data'!$F$102 -> 0.0039 | M53: ='Sim Data'!$H$102 -> 0.0209 | N53: =D53*L53 -> 0.020904 | O53: =IF(MAX(M53,N53)<0.5,"both ≈ 0",IF(N53=0,"no new arrivals",M53/N53)) -> both ≈ 0 | P53: =IF(D53=0,"",IF(H53>=1,"No steady state: the line grows by about "&TEXT((D53-G53*F53)*10,"0")&" in 10 min",IF(ISNUMBER(O53),IF(ABS(O53-1)<=0.2,"Steady: Little's Law holds",IF(O53>1,"Draining a line left from earlier","Line still building")),"Hardly any line"))) -> Hardly any line
A54: Today (no screens) | B54: Munch Mess | C54: 12:50 | D54: ='Sim Data'!$E$103 -> 4.375 | E54: ='Sim Data'!$G$103 -> 0.0336 | F54: =IF(E54>0,1/E54,60/Assumptions!$B$16) -> 29.761905 | G54: =Assumptions!$B$15 -> 1 | H54: =D54/(G54*F54) -> 0.147 | I54: =IF(D54=0,"no arrivals",IF(H54<0.85,"stable",IF(H54<1,"near capacity","over capacity"))) -> stable | J54: =IF(AND(D54>0,H54<1),H54/(F54-D54),"—") -> 0.0057903869 | K54: =IF(ISNUMBER(J54),(1+0.3^2)/2*J54,"—") -> 0.0031557608 | L54: ='Sim Data'!$F$103 -> 0.0032 | M54: ='Sim Data'!$H$103 -> 0.0141 | N54: =D54*L54 -> 0.014 | O54: =IF(MAX(M54,N54)<0.5,"both ≈ 0",IF(N54=0,"no new arrivals",M54/N54)) -> both ≈ 0 | P54: =IF(D54=0,"",IF(H54>=1,"No steady state: the line grows by about "&TEXT((D54-G54*F54)*10,"0")&" in 10 min",IF(ISNUMBER(O54),IF(ABS(O54-1)<=0.2,"Steady: Little's Law holds",IF(O54>1,"Draining a line left from earlier","Line still building")),"Hardly any line"))) -> Hardly any line
...

Sheet Q2 Serving stations
A1: Serving stations: M/M/c
A2: M/M/c, two serving stations per mess. Arrivals, waits and line lengths are simulated; utilisation, stability and the textbook waits are formulas.
A4: Summary
A5: Scenario | B5: Mess | C5: Peak ρ | D5: Slots over | E5: Slots near | F5: Worst wait | G5: Avg wait
A6: Today (no screens) | B6: Central CT | C6: =_xlfn.MAXIFS($H$28:$H$99,$A$28:$A$99,"Today (no screens)",$B$28:$B$99,"Central CT") -> 1.4695395 | D6: =COUNTIFS($A$28:$A$99,"Today (no screens)",$B$28:$B$99,"Central CT",$H$28:$H$99,">=1") -> 6 | E6: =COUNTIFS($A$28:$A$99,"Today (no screens)",$B$28:$B$99,"Central CT",$H$28:$H$99,">=0.85",$H$28:$H$99,"<1") -> 3 | F6: =_xlfn.MAXIFS($L$28:$L$99,$A$28:$A$99,"Today (no screens)",$B$28:$B$99,"Central CT") -> 14.4096 | G6: =SUMPRODUCT(($A$28:$A$99="Today (no screens)")*($B$28:$B$99="Central CT")*$L$28:$L$99*$D$28:$D$99)/SUMPRODUCT(($A$28:$A$99="Today (no screens)")*($B$28:$B$99="Central CT")*$D$28:$D$99) -> 5.3059144
A7: Today (no screens) | B7: Munch Mess | C7: =_xlfn.MAXIFS($H$28:$H$99,$A$28:$A$99,"Today (no screens)",$B$28:$B$99,"Munch Mess") -> 0.381 | D7: =COUNTIFS($A$28:$A$99,"Today (no screens)",$B$28:$B$99,"Munch Mess",$H$28:$H$99,">=1") -> 0 | E7: =COUNTIFS($A$28:$A$99,"Today (no screens)",$B$28:$B$99,"Munch Mess",$H$28:$H$99,">=0.85",$H$28:$H$99,"<1") -> 0 | F7: =_xlfn.MAXIFS($L$28:$L$99,$A$28:$A$99,"Today (no screens)",$B$28:$B$99,"Munch Mess") -> 0.0121 | G7: =SUMPRODUCT(($A$28:$A$99="Today (no screens)")*($B$28:$B$99="Munch Mess")*$L$28:$L$99*$D$28:$D$99)/SUMPRODUCT(($A$28:$A$99="Today (no screens)")*($B$28:$B$99="Munch Mess")*$D$28:$D$99) -> 0.0063195523
A8: With Smart Scan screens | B8: Central CT | C8: =_xlfn.MAXIFS($H$28:$H$99,$A$28:$A$99,"With Smart Scan screens",$B$28:$B$99,"Central CT") -> 1.0648225 | D8: =COUNTIFS($A$28:$A$99,"With Smart Scan screens",$B$28:$B$99,"Central CT",$H$28:$H$99,">=1") -> 4 | E8: =COUNTIFS($A$28:$A$99,"With Smart Scan screens",$B$28:$B$99,"Central CT",$H$28:$H$99,">=0.85",$H$28:$H$99,"<1") -> 4 | F8: =_xlfn.MAXIFS($L$28:$L$99,$A$28:$A$99,"With Smart Scan screens",$B$28:$B$99,"Central CT") -> 2.1938 | G8: =SUMPRODUCT(($A$28:$A$99="With Smart Scan screens")*($B$28:$B$99="Central CT")*$L$28:$L$99*$D$28:$D$99)/SUMPRODUCT(($A$28:$A$99="With Smart Scan screens")*($B$28:$B$99="Central CT")*$D$28:$D$99) -> 1.0512015
A9: With Smart Scan screens | B9: Munch Mess | C9: =_xlfn.MAXIFS($H$28:$H$99,$A$28:$A$99,"With Smart Scan screens",$B$28:$B$99,"Munch Mess") -> 0.78864 | D9: =COUNTIFS($A$28:$A$99,"With Smart Scan screens",$B$28:$B$99,"Munch Mess",$H$28:$H$99,">=1") -> 0 | E9: =COUNTIFS($A$28:$A$99,"With Smart Scan screens",$B$28:$B$99,"Munch Mess",$H$28:$H$99,">=0.85",$H$28:$H$99,"<1") -> 0 | F9: =_xlfn.MAXIFS($L$28:$L$99,$A$28:$A$99,"With Smart Scan screens",$B$28:$B$99,"Munch Mess") -> 0.1552 | G9: =SUMPRODUCT(($A$28:$A$99="With Smart Scan screens")*($B$28:$B$99="Munch Mess")*$L$28:$L$99*$D$28:$D$99)/SUMPRODUCT(($A$28:$A$99="With Smart Scan screens")*($B$28:$B$99="Munch Mess")*$D$28:$D$99) -> 0.07231788
A10: Slots over = ρ ≥ 100% · slots near = 85–100% · waits in minutes (simulated)
A12: Takeaway: This is the bottleneck. Two stations serve 20 students a minute. Today Central runs at up to 147% in the 13:10 surge, so the line grows every minute and there is no steady state until the surge passes. With the screens Central peaks at 106% for a short while and Munch takes the overflow (peak 79%). The screens only ask students to walk when it saves at least 2 minutes, and only 60% follow.
A20: In the table below: red = over capacity (the line keeps growing), amber = near capacity (waits rise steeply).
A26: Slot by slot (filter by scenario or mess)
A27: Scenario | B27: Mess | C27: Slot | D27: λ (/min) | E27: Service time (min) | F27: μ (/min) | G27: c | H27: ρ | I27: Stable? | J27: Wq textbook (min) | K27: Wq corrected for cv (min) | L27: Wq simulated (min) | M27: Lq simulated | N27: λ × Wq simulated | O27: Little's Law: Lq ÷ λWq | P27: What it means
A28: Today (no screens) | B28: Central CT | C28: 11:30 | D28: ='Sim Data'!$E$23 -> 0 | E28: ='Sim Data'!$G$23 -> 0 | F28: =IF(E28>0,1/E28,Assumptions!$B$21) -> 10 | G28: =Assumptions!$B$20 -> 2 | H28: =D28/(G28*F28) -> 0 | I28: =IF(D28=0,"no arrivals",IF(H28<0.85,"stable",IF(H28<1,"near capacity","over capacity"))) -> no arrivals | J28: =IF(AND(D28>0,H28<1),((D28/F28)^G28/FACT(G28)/(1-H28))/(SUMPRODUCT(--({0,1,2,3,4,5,6,7,8,9}<G28),(D28/F28)^{0,1,2,3,4,5,6,7,8,9}/FACT({0,1,2,3,4,5,6,7,8,9}))+((D28/F28)^G28/FACT(G28)/(1-H28)))/(G28*F28-D28),"—") -> — | K28: =IF(ISNUMBER(J28),(1+Assumptions!$B$22^2)/2*J28,"—") -> — | L28: ='Sim Data'!$F$23 -> 0 | M28: ='Sim Data'!$H$23 -> 0 | N28: =D28*L28 -> 0 | O28: =IF(MAX(M28,N28)<0.5,"both ≈ 0",IF(N28=0,"no new arrivals",M28/N28)) -> both ≈ 0 | P28: =IF(D28=0,"",IF(H28>=1,"No steady state: the line grows by about "&TEXT((D28-G28*F28)*10,"0")&" in 10 min",IF(ISNUMBER(O28),IF(ABS(O28-1)<=0.2,"Steady: Little's Law holds",IF(O28>1,"Draining a line left from earlier","Line still building")),"Hardly any line")))
A29: Today (no screens) | B29: Central CT | C29: 11:40 | D29: ='Sim Data'!$E$24 -> 0 | E29: ='Sim Data'!$G$24 -> 0 | F29: =IF(E29>0,1/E29,Assumptions!$B$21) -> 10 | G29: =Assumptions!$B$20 -> 2 | H29: =D29/(G29*F29) -> 0 | I29: =IF(D29=0,"no arrivals",IF(H29<0.85,"stable",IF(H29<1,"near capacity","over capacity"))) -> no arrivals | J29: =IF(AND(D29>0,H29<1),((D29/F29)^G29/FACT(G29)/(1-H29))/(SUMPRODUCT(--({0,1,2,3,4,5,6,7,8,9}<G29),(D29/F29)^{0,1,2,3,4,5,6,7,8,9}/FACT({0,1,2,3,4,5,6,7,8,9}))+((D29/F29)^G29/FACT(G29)/(1-H29)))/(G29*F29-D29),"—") -> — | K29: =IF(ISNUMBER(J29),(1+Assumptions!$B$22^2)/2*J29,"—") -> — | L29: ='Sim Data'!$F$24 -> 0 | M29: ='Sim Data'!$H$24 -> 0 | N29: =D29*L29 -> 0 | O29: =IF(MAX(M29,N29)<0.5,"both ≈ 0",IF(N29=0,"no new arrivals",M29/N29)) -> both ≈ 0 | P29: =IF(D29=0,"",IF(H29>=1,"No steady state: the line grows by about "&TEXT((D29-G29*F29)*10,"0")&" in 10 min",IF(ISNUMBER(O29),IF(ABS(O29-1)<=0.2,"Steady: Little's Law holds",IF(O29>1,"Draining a line left from earlier","Line still building")),"Hardly any line")))
A30: Today (no screens) | B30: Central CT | C30: 11:50 | D30: ='Sim Data'!$E$25 -> 0 | E30: ='Sim Data'!$G$25 -> 0 | F30: =IF(E30>0,1/E30,Assumptions!$B$21) -> 10 | G30: =Assumptions!$B$20 -> 2 | H30: =D30/(G30*F30) -> 0 | I30: =IF(D30=0,"no arrivals",IF(H30<0.85,"stable",IF(H30<1,"near capacity","over capacity"))) -> no arrivals | J30: =IF(AND(D30>0,H30<1),((D30/F30)^G30/FACT(G30)/(1-H30))/(SUMPRODUCT(--({0,1,2,3,4,5,6,7,8,9}<G30),(D30/F30)^{0,1,2,3,4,5,6,7,8,9}/FACT({0,1,2,3,4,5,6,7,8,9}))+((D30/F30)^G30/FACT(G30)/(1-H30)))/(G30*F30-D30),"—") -> — | K30: =IF(ISNUMBER(J30),(1+Assumptions!$B$22^2)/2*J30,"—") -> — | L30: ='Sim Data'!$F$25 -> 0 | M30: ='Sim Data'!$H$25 -> 0 | N30: =D30*L30 -> 0 | O30: =IF(MAX(M30,N30)<0.5,"both ≈ 0",IF(N30=0,"no new arrivals",M30/N30)) -> both ≈ 0 | P30: =IF(D30=0,"",IF(H30>=1,"No steady state: the line grows by about "&TEXT((D30-G30*F30)*10,"0")&" in 10 min",IF(ISNUMBER(O30),IF(ABS(O30-1)<=0.2,"Steady: Little's Law holds",IF(O30>1,"Draining a line left from earlier","Line still building")),"Hardly any line")))
A31: Today (no screens) | B31: Central CT | C31: 12:00 | D31: ='Sim Data'!$E$26 -> 13.485 | E31: ='Sim Data'!$G$26 -> 0.1019 | F31: =IF(E31>0,1/E31,Assumptions!$B$21) -> 9.8135427 | G31: =Assumptions!$B$20 -> 2 | H31: =D31/(G31*F31) -> 0.68706075 | I31: =IF(D31=0,"no arrivals",IF(H31<0.85,"stable",IF(H31<1,"near capacity","over capacity"))) -> stable | J31: =IF(AND(D31>0,H31<1),((D31/F31)^G31/FACT(G31)/(1-H31))/(SUMPRODUCT(--({0,1,2,3,4,5,6,7,8,9}<G31),(D31/F31)^{0,1,2,3,4,5,6,7,8,9}/FACT({0,1,2,3,4,5,6,7,8,9}))+((D31/F31)^G31/FACT(G31)/(1-H31)))/(G31*F31-D31),"—") -> 0.091111606 | K31: =IF(ISNUMBER(J31),(1+Assumptions!$B$22^2)/2*J31,"—") -> 0.061955892 | L31: ='Sim Data'!$F$26 -> 0.0857 | M31: ='Sim Data'!$H$26 -> 1.1129 | N31: =D31*L31 -> 1.1556645 | O31: =IF(MAX(M31,N31)<0.5,"both ≈ 0",IF(N31=0,"no new arrivals",M31/N31)) -> 0.96299575 | P31: =IF(D31=0,"",IF(H31>=1,"No steady state: the line grows by about "&TEXT((D31-G31*F31)*10,"0")&" in 10 min",IF(ISNUMBER(O31),IF(ABS(O31-1)<=0.2,"Steady: Little's Law holds",IF(O31>1,"Draining a line left from earlier","Line still building")),"Hardly any line"))) -> Steady: Little's Law holds
A32: Today (no screens) | B32: Central CT | C32: 12:10 | D32: ='Sim Data'!$E$27 -> 18.49 | E32: ='Sim Data'!$G$27 -> 0.1004 | F32: =IF(E32>0,1/E32,Assumptions!$B$21) -> 9.9601594 | G32: =Assumptions!$B$20 -> 2 | H32: =D32/(G32*F32) -> 0.928198 | I32: =IF(D32=0,"no arrivals",IF(H32<0.85,"stable",IF(H32<1,"near capacity","over capacity"))) -> near capacity | J32: =IF(AND(D32>0,H32<1),((D32/F32)^G32/FACT(G32)/(1-H32))/(SUMPRODUCT(--({0,1,2,3,4,5,6,7,8,9}<G32),(D32/F32)^{0,1,2,3,4,5,6,7,8,9}/FACT({0,1,2,3,4,5,6,7,8,9}))+((D32/F32)^G32/FACT(G32)/(1-H32)))/(G32*F32-D32),"—") -> 0.62477954 | K32: =IF(ISNUMBER(J32),(1+Assumptions!$B$22^2)/2*J32,"—") -> 0.42485009 | L32: ='Sim Data'!$F$27 -> 0.2595 | M32: ='Sim Data'!$H$27 -> 4.575 | N32: =D32*L32 -> 4.798155 | O32: =IF(MAX(M32,N32)<0.5,"both ≈ 0",IF(N32=0,"no new arrivals",M32/N32)) -> 0.9534915 | P32: =IF(D32=0,"",IF(H32>=1,"No steady state: the line grows by about "&TEXT((D32-G32*F32)*10,"0")&" in 10 min",IF(ISNUMBER(O32),IF(ABS(O32-1)<=0.2,"Steady: Little's Law holds",IF(O32>1,"Draining a line left from earlier","Line still building")),"Hardly any line"))) -> Steady: Little's Law holds
A33: Today (no screens) | B33: Central CT | C33: 12:20 | D33: ='Sim Data'!$E$28 -> 19.005 | E33: ='Sim Data'!$G$28 -> 0.1009 | F33: =IF(E33>0,1/E33,Assumptions!$B$21) -> 9.9108028 | G33: =Assumptions!$B$20 -> 2 | H33: =D33/(G33*F33) -> 0.95880225 | I33: =IF(D33=0,"no arrivals",IF(H33<0.85,"stable",IF(H33<1,"near capacity","over capacity"))) -> near capacity | J33: =IF(AND(D33>0,H33<1),((D33/F33)^G33/FACT(G33)/(1-H33))/(SUMPRODUCT(--({0,1,2,3,4,5,6,7,8,9}<G33),(D33/F33)^{0,1,2,3,4,5,6,7,8,9}/FACT({0,1,2,3,4,5,6,7,8,9}))+((D33/F33)^G33/FACT(G33)/(1-H33)))/(G33*F33-D33),"—") -> 1.149437 | K33: =IF(ISNUMBER(J33),(1+Assumptions!$B$22^2)/2*J33,"—") -> 0.78161714 | L33: ='Sim Data'!$F$28 -> 0.613 | M33: ='Sim Data'!$H$28 -> 11.2764 | N33: =D33*L33 -> 11.650065 | O33: =IF(MAX(M33,N33)<0.5,"both ≈ 0",IF(N33=0,"no new arrivals",M33/N33)) -> 0.96792593 | P33: =IF(D33=0,"",IF(H33>=1,"No steady state: the line grows by about "&TEXT((D33-G33*F33)*10,"0")&" in 10 min",IF(ISNUMBER(O33),IF(ABS(O33-1)<=0.2,"Steady: Little's Law holds",IF(O33>1,"Draining a line left from earlier","Line still building")),"Hardly any line"))) -> Steady: Little's Law holds
A34: Today (no screens) | B34: Central CT | C34: 12:30 | D34: ='Sim Data'!$E$29 -> 22.575 | E34: ='Sim Data'!$G$29 -> 0.1002 | F34: =IF(E34>0,1/E34,Assumptions!$B$21) -> 9.9800399 | G34: =Assumptions!$B$20 -> 2 | H34: =D34/(G34*F34) -> 1.1310075 | I34: =IF(D34=0,"no arrivals",IF(H34<0.85,"stable",IF(H34<1,"near capacity","over capacity"))) -> over capacity | J34: =IF(AND(D34>0,H34<1),((D34/F34)^G34/FACT(G34)/(1-H34))/(SUMPRODUCT(--({0,1,2,3,4,5,6,7,8,9}<G34),(D34/F34)^{0,1,2,3,4,5,6,7,8,9}/FACT({0,1,2,3,4,5,6,7,8,9}))+((D34/F34)^G34/FACT(G34)/(1-H34)))/(G34*F34-D34),"—") -> — | K34: =IF(ISNUMBER(J34),(1+Assumptions!$B$22^2)/2*J34,"—") -> — | L34: ='Sim Data'!$F$29 -> 1.3246 | M34: ='Sim Data'!$H$29 -> 25.1983 | N34: =D34*L34 -> 29.902845 | O34: =IF(MAX(M34,N34)<0.5,"both ≈ 0",IF(N34=0,"no new arrivals",M34/N34)) -> 0.84267233 | P34: =IF(D34=0,"",IF(H34>=1,"No steady state: the line grows by about "&TEXT((D34-G34*F34)*10,"0")&" in 10 min",IF(ISNUMBER(O34),IF(ABS(O34-1)<=0.2,"Steady: Little's Law holds",IF(O34>1,"Draining a line left from earlier","Line still building")),"Hardly any line"))) -> No steady state: the line grows by about 26 in 10 min
A35: Today (no screens) | B35: Central CT | C35: 12:40 | D35: ='Sim Data'!$E$30 -> 20.555 | E35: ='Sim Data'!$G$30 -> 0.0983 | F35: =IF(E35>0,1/E35,Assumptions!$B$21) -> 10.17294 | G35: =Assumptions!$B$20 -> 2 | H35: =D35/(G35*F35) -> 1.0102783 | I35: =IF(D35=0,"no arrivals",IF(H35<0.85,"stable",IF(H35<1,"near capacity","over capacity"))) -> over capacity | J35: =IF(AND(D35>0,H35<1),((D35/F35)^G35/FACT(G35)/(1-H35))/(SUMPRODUCT(--({0,1,2,3,4,5,6,7,8,9}<G35),(D35/F35)^{0,1,2,3,4,5,6,7,8,9}/FACT({0,1,2,3,4,5,6,7,8,9}))+((D35/F35)^G35/FACT(G35)/(1-H35)))/(G35*F35-D35),"—") -> — | K35: =IF(ISNUMBER(J35),(1+Assumptions!$B$22^2)/2*J35,"—") -> — | L35: ='Sim Data'!$F$30 -> 2.4614 | M35: ='Sim Data'!$H$30 -> 45.0696 | N35: =D35*L35 -> 50.594077 | O35: =IF(MAX(M35,N35)<0.5,"both ≈ 0",IF(N35=0,"no new arrivals",M35/N35)) -> 0.89080783 | P35: =IF(D35=0,"",IF(H35>=1,"No steady state: the line grows by about "&TEXT((D35-G35*F35)*10,"0")&" in 10 min",IF(ISNUMBER(O35),IF(ABS(O35-1)<=0.2,"Steady: Little's Law holds",IF(O35>1,"Draining a line left from earlier","Line still building")),"Hardly any line"))) -> No steady state: the line grows by about 2 in 10 min
A36: Today (no screens) | B36: Central CT | C36: 12:50 | D36: ='Sim Data'!$E$31 -> 17.265 | E36: ='Sim Data'!$G$31 -> 0.1002 | F36: =IF(E36>0,1/E36,Assumptions!$B$21) -> 9.9800399 | G36: =Assumptions!$B$20 -> 2 | H36: =D36/(G36*F36) -> 0.8649765 | I36: =IF(D36=0,"no arrivals",IF(H36<0.85,"stable",IF(H36<1,"near capacity","over capacity"))) -> near capacity | J36: =IF(AND(D36>0,H36<1),((D36/F36)^G36/FACT(G36)/(1-H36))/(SUMPRODUCT(--({0,1,2,3,4,5,6,7,8,9}<G36),(D36/F36)^{0,1,2,3,4,5,6,7,8,9}/FACT({0,1,2,3,4,5,6,7,8,9}))+((D36/F36)^G36/FACT(G36)/(1-H36)))/(G36*F36-D36),"—") -> 0.29771013 | K36: =IF(ISNUMBER(J36),(1+Assumptions!$B$22^2)/2*J36,"—") -> 0.20244289 | L36: ='Sim Data'!$F$31 -> 2.6137 | M36: ='Sim Data'!$H$31 -> 47.1154 | N36: =D36*L36 -> 45.125531 | O36: =IF(MAX(M36,N36)<0.5,"both ≈ 0",IF(N36=0,"no new arrivals",M36/N36)) -> 1.0440963 | P36: =IF(D36=0,"",IF(H36>=1,"No steady state: the line grows by about "&TEXT((D36-G36*F36)*10,"0")&" in 10 min",IF(ISNUMBER(O36),IF(ABS(O36-1)<=0.2,"Steady: Little's Law holds",IF(O36>1,"Draining a line left from earlier","Line still building")),"Hardly any line"))) -> Steady: Little's Law holds
A37: Today (no screens) | B37: Central CT | C37: 13:00 | D37: ='Sim Data'!$E$32 -> 21.335 | E37: ='Sim Data'!$G$32 -> 0.0998 | F37: =IF(E37>0,1/E37,Assumptions!$B$21) -> 10.02004 | G37: =Assumptions!$B$20 -> 2 | H37: =D37/(G37*F37) -> 1.0646165 | I37: =IF(D37=0,"no arrivals",IF(H37<0.85,"stable",IF(H37<1,"near capacity","over capacity"))) -> over capacity | J37: =IF(AND(D37>0,H37<1),((D37/F37)^G37/FACT(G37)/(1-H37))/(SUMPRODUCT(--({0,1,2,3,4,5,6,7,8,9}<G37),(D37/F37)^{0,1,2,3,4,5,6,7,8,9}/FACT({0,1,2,3,4,5,6,7,8,9}))+((D37/F37)^G37/FACT(G37)/(1-H37)))/(G37*F37-D37),"—") -> — | K37: =IF(ISNUMBER(J37),(1+Assumptions!$B$22^2)/2*J37,"—") -> — | L37: ='Sim Data'!$F$32 -> 2.0437 | M37: ='Sim Data'!$H$32 -> 38.4499 | N37: =D37*L37 -> 43.602339 | O37: =IF(MAX(M37,N37)<0.5,"both ≈ 0",IF(N37=0,"no new arrivals",M37/N37)) -> 0.88183112 | P37: =IF(D37=0,"",IF(H37>=1,"No steady state: the line grows by about "&TEXT((D37-G37*F37)*10,"0")&" in 10 min",IF(ISNUMBER(O37),IF(ABS(O37-1)<=0.2,"Steady: Little's Law holds",IF(O37>1,"Draining a line left from earlier","Line still building")),"Hardly any line"))) -> No steady state: the line grows by about 13 in 10 min
